Workbook

Sheet Setup
A1: FUTURE TALENT ACADEMY JAMSHORO — SETUP
A3: Academy Name | B3: Future Talent Academy Jamshoro
A5: Subject / Class | B5: Teacher Name | C5: Teacher Share | D5: Academy Share
A6: English | B6: Sir Sajjad Ali Birhmani | C6: 0.5 | D6: =1-C6 -> 0.5
A7: Computer | B7: Sir Nazeer Ahmed Jamali | C7: 0.5 | D7: =1-C7 -> 0.5
A8: Biology | B8: Sir Azhar Ali Chandio | C8: 0.5 | D8: =1-C8 -> 0.5
A9: Math | B9: Sir M. Faheem | C9: 0.5 | D9: =1-C9 -> 0.5
A10: Kids Coaching (Class 1) | B10: Miss Farzana | C10: 0.5 | D10: =1-C10 -> 0.5
A11: Kids Coaching (Class 2) | B11: Miss Fozia | C11: 0.5 | D11: =1-C11 -> 0.5
A13: How it works
A14: 1. Students: write each student ONCE. Under each subject, type that student's monthly fee. Leave blank if the student does not take that subject.
A15: Example: Ali takes Computer (2000) and Math (1500) only, so only those two cells are filled.
A16: 2. Month sheets (Oct 2026 …): type only the amount paid in each subject's 'Paid' column. Unpaid fees carry forward per subject.
A17: 3. Administration: write every expense (rent, bills, salaries …), investment (furniture, computers …) and any other income, with its month.
A18: 4. Each month sheet and the Profit & Loss sheet show: Academy share of fees + other income − expenses − investment = NET PROFIT.
A19: 5. Teacher shares are paid from collected fees only; expenses and investment are cut from the academy's share.

Sheet Students
A1: STUDENT LIST — ONE ROW PER STUDENT
A2: Type the monthly fee under each subject the student takes. Leave blank for subjects the student does not take. Add new students at the bottom; keep the order the same.
A3: STUDENT | E3: MONTHLY FEE PER SUBJECT (blank = not enrolled)
A4: Serial No | B4: Student Name | C4: Father Name | D4: Phone No | E4: =Setup!A6 -> English | F4: =Setup!A7 -> Computer | G4: =Setup!A8 -> Biology | H4: =Setup!A9 -> Math | I4: =Setup!A10 -> Kids Coaching (Class 1) | J4: =Setup!A11 -> Kids Coaching (Class 2) | K4: Total Monthly Fee
A5: 1 | B5: Ali (example) | C5: Muhammad Aslam | D5: 0300-0000000 | F5: 2000 | H5: 1500 | K5: =SUM(E5:J5) -> 3500
A6: 2 | K6: =SUM(E6:J6) -> 0
A7: 3 | K7: =SUM(E7:J7) -> 0
A8: 4 | K8: =SUM(E8:J8) -> 0
A9: 5 | K9: =SUM(E9:J9) -> 0
A10: 6 | K10: =SUM(E10:J10) -> 0
A11: 7 | K11: =SUM(E11:J11) -> 0
A12: 8 | K12: =SUM(E12:J12) -> 0
A13: 9 | K13: =SUM(E13:J13) -> 0
A14: 10 | K14: =SUM(E14:J14) -> 0
A15: 11 | K15: =SUM(E15:J15) -> 0
A16: 12 | K16: =SUM(E16:J16) -> 0
A17: 13 | K17: =SUM(E17:J17) -> 0
... A154: 150 | K154: =SUM(E154:J154) -> 0

Sheet Administration
A1: ADMINISTRATION — EXPENSES, INVESTMENT & OTHER INCOME
A2: Write every payment the academy makes or receives (other than student fees). Choose the Month and Type. Totals flow to each month sheet and the Profit & Loss sheet.
A4: Serial No | B4: Date | C4: Month | D4: Type | E4: Category | F4: Description | G4: Amount | H4: Notes
A5: 1 | B5: 46300 | C5: Oct 2026 | D5: Expense | E5: Rent | F5: Building rent (example) | G5: 10000
A6: 2 | B6: 46305 | C6: Oct 2026 | D6: Investment | E6: Furniture | F6: 10 chairs (example) | G6: 8000
A7: 3
A8: 4
A9: 5
A10: 6
A11: 7
A12: 8
A13: 9
A14: 10
A15: 11
A16: 12
A17: 13
A18: 14
... A304: 300

Sheet Profit & Loss
A1: =UPPER(Setup!B3) -> FUTURE TALENT ACADEMY JAMSHORO
A2: Profit & Loss • Year 2026-27 (Administration Summary)
A4: Month | B4: Fees Collected | C4: Teachers' Share | D4: Academy Share | E4: Other Income | F4: Expenses | G4: Investment | H4: NET PROFIT | I4: Pending Fees | J4: Students Enrolled
A5: October 2026 | B5: ='Oct 2026'!F12 -> 3000 | C5: ='Oct 2026'!G12 -> 1500 | D5: ='Oct 2026'!H12 -> 1500 | E5: ='Oct 2026'!N6 -> 0 | F5: ='Oct 2026'!N7 -> 10000 | G5: ='Oct 2026'!N8 -> 8000 | H5: ='Oct 2026'!N10 -> -16500 | I5: ='Oct 2026'!I12 -> 500 | J5: =COUNTIF('Oct 2026'!B16:B165,"?*") -> 1
A6: November 2026 | B6: ='Nov 2026'!F12 -> 0 | C6: ='Nov 2026'!G12 -> 0 | D6: ='Nov 2026'!H12 -> 0 | E6: ='Nov 2026'!N6 -> 0 | F6: ='Nov 2026'!N7 -> 0 | G6: ='Nov 2026'!N8 -> 0 | H6: ='Nov 2026'!N10 -> 0 | I6: ='Nov 2026'!I12 -> 4000 | J6: =COUNTIF('Nov 2026'!B16:B165,"?*") -> 1
A7: December 2026 | B7: ='Dec 2026'!F12 -> 0 | C7: ='Dec 2026'!G12 -> 0 | D7: ='Dec 2026'!H12 -> 0 | E7: ='Dec 2026'!N6 -> 0 | F7: ='Dec 2026'!N7 -> 0 | G7: ='Dec 2026'!N8 -> 0 | H7: ='Dec 2026'!N10 -> 0 | I7: ='Dec 2026'!I12 -> 7500 | J7: =COUNTIF('Dec 2026'!B16:B165,"?*") -> 1
A8: January 2027 | B8: ='Jan 2027'!F12 -> 0 | C8: ='Jan 2027'!G12 -> 0 | D8: ='Jan 2027'!H12 -> 0 | E8: ='Jan 2027'!N6 -> 0 | F8: ='Jan 2027'!N7 -> 0 | G8: ='Jan 2027'!N8 -> 0 | H8: ='Jan 2027'!N10 -> 0 | I8: ='Jan 2027'!I12 -> 11000 | J8: =COUNTIF('Jan 2027'!B16:B165,"?*") -> 1
A9: February 2027 | B9: ='Feb 2027'!F12 -> 0 | C9: ='Feb 2027'!G12 -> 0 | D9: ='Feb 2027'!H12 -> 0 | E9: ='Feb 2027'!N6 -> 0 | F9: ='Feb 2027'!N7 -> 0 | G9: ='Feb 2027'!N8 -> 0 | H9: ='Feb 2027'!N10 -> 0 | I9: ='Feb 2027'!I12 -> 14500 | J9: =COUNTIF('Feb 2027'!B16:B165,"?*") -> 1
A10: March 2027 | B10: ='Mar 2027'!F12 -> 0 | C10: ='Mar 2027'!G12 -> 0 | D10: ='Mar 2027'!H12 -> 0 | E10: ='Mar 2027'!N6 -> 0 | F10: ='Mar 2027'!N7 -> 0 | G10: ='Mar 2027'!N8 -> 0 | H10: ='Mar 2027'!N10 -> 0 | I10: ='Mar 2027'!I12 -> 18000 | J10: =COUNTIF('Mar 2027'!B16:B165,"?*") -> 1
A11: April 2027 | B11: ='Apr 2027'!F12 -> 0 | C11: ='Apr 2027'!G12 -> 0 | D11: ='Apr 2027'!H12 -> 0 | E11: ='Apr 2027'!N6 -> 0 | F11: ='Apr 2027'!N7 -> 0 | G11: ='Apr 2027'!N8 -> 0 | H11: ='Apr 2027'!N10 -> 0 | I11: ='Apr 2027'!I12 -> 21500 | J11: =COUNTIF('Apr 2027'!B16:B165,"?*") -> 1
A12: May 2027 | B12: ='May 2027'!F12 -> 0 | C12: ='May 2027'!G12 -> 0 | D12: ='May 2027'!H12 -> 0 | E12: ='May 2027'!N6 -> 0 | F12: ='May 2027'!N7 -> 0 | G12: ='May 2027'!N8 -> 0 | H12: ='May 2027'!N10 -> 0 | I12: ='May 2027'!I12 -> 25000 | J12: =COUNTIF('May 2027'!B16:B165,"?*") -> 1
A13: June 2027 | B13: ='Jun 2027'!F12 -> 0 | C13: ='Jun 2027'!G12 -> 0 | D13: ='Jun 2027'!H12 -> 0 | E13: ='Jun 2027'!N6 -> 0 | F13: ='Jun 2027'!N7 -> 0 | G13: ='Jun 2027'!N8 -> 0 | H13: ='Jun 2027'!N10 -> 0 | I13: ='Jun 2027'!I12 -> 28500 | J13: =COUNTIF('Jun 2027'!B16:B165,"?*") -> 1
A14: July 2027 | B14: ='Jul 2027'!F12 -> 0 | C14: ='Jul 2027'!G12 -> 0 | D14: ='Jul 2027'!H12 -> 0 | E14: ='Jul 2027'!N6 -> 0 | F14: ='Jul 2027'!N7 -> 0 | G14: ='Jul 2027'!N8 -> 0 | H14: ='Jul 2027'!N10 -> 0 | I14: ='Jul 2027'!I12 -> 32000 | J14: =COUNTIF('Jul 2027'!B16:B165,"?*") -> 1
A15: August 2027 | B15: ='Aug 2027'!F12 -> 0 | C15: ='Aug 2027'!G12 -> 0 | D15: ='Aug 2027'!H12 -> 0 | E15: ='Aug 2027'!N6 -> 0 | F15: ='Aug 2027'!N7 -> 0 | G15: ='Aug 2027'!N8 -> 0 | H15: ='Aug 2027'!N10 -> 0 | I15: ='Aug 2027'!I12 -> 35500 | J15: =COUNTIF('Aug 2027'!B16:B165,"?*") -> 1
A16: September 2027 | B16: ='Sep 2027'!F12 -> 0 | C16: ='Sep 2027'!G12 -> 0 | D16: ='Sep 2027'!H12 -> 0 | E16: ='Sep 2027'!N6 -> 0 | F16: ='Sep 2027'!N7 -> 0 | G16: ='Sep 2027'!N8 -> 0 | H16: ='Sep 2027'!N10 -> 0 | I16: ='Sep 2027'!I12 -> 39000 | J16: =COUNTIF('Sep 2027'!B16:B165,"?*") -> 1
A17: YEAR TOTAL | B17: =SUM(B5:B16) -> 3000 | C17: =SUM(C5:C16) -> 1500 | D17: =SUM(D5:D16) -> 1500 | E17: =SUM(E5:E16) -> 0 | F17: =SUM(F5:F16) -> 10000 | G17: =SUM(G5:G16) -> 8000 | H17: =SUM(H5:H16) -> -16500
A20: SUBJECT-WISE YEAR TOTAL
A21: Subject | B21: Teacher | C21: Fees Collected | D21: Teacher Share | E21: Academy Share | F21: Pending (latest month)
A22: =Setup!A6 -> English | B22: =Setup!B6 -> Sir Sajjad Ali Birhmani | C22: ='Oct 2026'!F6+'Nov 2026'!F6+'Dec 2026'!F6+'Jan 2027'!F6+'Feb 2027'!F6+'Mar 2027'!F6+'Apr 2027'!F6+'May 2027'!F6+'Jun 2027'!F6+'Jul 2027'!F6+'Aug 2027'!F6+'Sep 2027'!F6 -> 0 | D22: ='Oct 2026'!G6+'Nov 2026'!G6+'Dec 2026'!G6+'Jan 2027'!G6+'Feb 2027'!G6+'Mar 2027'!G6+'Apr 2027'!G6+'May 2027'!G6+'Jun 2027'!G6+'Jul 2027'!G6+'Aug 2027'!G6+'Sep 2027'!G6 -> 0 | E22: ='Oct 2026'!H6+'Nov 2026'!H6+'Dec 2026'!H6+'Jan 2027'!H6+'Feb 2027'!H6+'Mar 2027'!H6+'Apr 2027'!H6+'May 2027'!H6+'Jun 2027'!H6+'Jul 2027'!H6+'Aug 2027'!H6+'Sep 2027'!H6 -> 0 | F22: ='Sep 2027'!I6 -> 0
A23: =Setup!A7 -> Computer | B23: =Setup!B7 -> Sir Nazeer Ahmed Jamali | C23: ='Oct 2026'!F7+'Nov 2026'!F7+'Dec 2026'!F7+'Jan 2027'!F7+'Feb 2027'!F7+'Mar 2027'!F7+'Apr 2027'!F7+'May 2027'!F7+'Jun 2027'!F7+'Jul 2027'!F7+'Aug 2027'!F7+'Sep 2027'!F7 -> 2000 | D23: ='Oct 2026'!G7+'Nov 2026'!G7+'Dec 2026'!G7+'Jan 2027'!G7+'Feb 2027'!G7+'Mar 2027'!G7+'Apr 2027'!G7+'May 2027'!G7+'Jun 2027'!G7+'Jul 2027'!G7+'Aug 2027'!G7+'Sep 2027'!G7 -> 1000 | E23: ='Oct 2026'!H7+'Nov 2026'!H7+'Dec 2026'!H7+'Jan 2027'!H7+'Feb 2027'!H7+'Mar 2027'!H7+'Apr 2027'!H7+'May 2027'!H7+'Jun 2027'!H7+'Jul 2027'!H7+'Aug 2027'!H7+'Sep 2027'!H7 -> 1000 | F23: ='Sep 2027'!I7 -> 22000
A24: =Setup!A8 -> Biology | B24: =Setup!B8 -> Sir Azhar Ali Chandio | C24: ='Oct 2026'!F8+'Nov 2026'!F8+'Dec 2026'!F8+'Jan 2027'!F8+'Feb 2027'!F8+'Mar 2027'!F8+'Apr 2027'!F8+'May 2027'!F8+'Jun 2027'!F8+'Jul 2027'!F8+'Aug 2027'!F8+'Sep 2027'!F8 -> 0 | D24: ='Oct 2026'!G8+'Nov 2026'!G8+'Dec 2026'!G8+'Jan 2027'!G8+'Feb 2027'!G8+'Mar 2027'!G8+'Apr 2027'!G8+'May 2027'!G8+'Jun 2027'!G8+'Jul 2027'!G8+'Aug 2027'!G8+'Sep 2027'!G8 -> 0 | E24: ='Oct 2026'!H8+'Nov 2026'!H8+'Dec 2026'!H8+'Jan 2027'!H8+'Feb 2027'!H8+'Mar 2027'!H8+'Apr 2027'!H8+'May 2027'!H8+'Jun 2027'!H8+'Jul 2027'!H8+'Aug 2027'!H8+'Sep 2027'!H8 -> 0 | F24: ='Sep 2027'!I8 -> 0
A25: =Setup!A9 -> Math | B25: =Setup!B9 -> Sir M. Faheem | C25: ='Oct 2026'!F9+'Nov 2026'!F9+'Dec 2026'!F9+'Jan 2027'!F9+'Feb 2027'!F9+'Mar 2027'!F9+'Apr 2027'!F9+'May 2027'!F9+'Jun 2027'!F9+'Jul 2027'!F9+'Aug 2027'!F9+'Sep 2027'!F9 -> 1000 | D25: ='Oct 2026'!G9+'Nov 2026'!G9+'Dec 2026'!G9+'Jan 2027'!G9+'Feb 2027'!G9+'Mar 2027'!G9+'Apr 2027'!G9+'May 2027'!G9+'Jun 2027'!G9+'Jul 2027'!G9+'Aug 2027'!G9+'Sep 2027'!G9 -> 500 | E25: ='Oct 2026'!H9+'Nov 2026'!H9+'Dec 2026'!H9+'Jan 2027'!H9+'Feb 2027'!H9+'Mar 2027'!H9+'Apr 2027'!H9+'May 2027'!H9+'Jun 2027'!H9+'Jul 2027'!H9+'Aug 2027'!H9+'Sep 2027'!H9 -> 500 | F25: ='Sep 2027'!I9 -> 17000
A26: =Setup!A10 -> Kids Coaching (Class 1) | B26: =Setup!B10 -> Miss Farzana | C26: ='Oct 2026'!F10+'Nov 2026'!F10+'Dec 2026'!F10+'Jan 2027'!F10+'Feb 2027'!F10+'Mar 2027'!F10+'Apr 2027'!F10+'May 2027'!F10+'Jun 2027'!F10+'Jul 2027'!F10+'Aug 2027'!F10+'Sep 2027'!F10 -> 0 | D26: ='Oct 2026'!G10+'Nov 2026'!G10+'Dec 2026'!G10+'Jan 2027'!G10+'Feb 2027'!G10+'Mar 2027'!G10+'Apr 2027'!G10+'May 2027'!G10+'Jun 2027'!G10+'Jul 2027'!G10+'Aug 2027'!G10+'Sep 2027'!G10 -> 0 | E26: ='Oct 2026'!H10+'Nov 2026'!H10+'Dec 2026'!H10+'Jan 2027'!H10+'Feb 2027'!H10+'Mar 2027'!H10+'Apr 2027'!H10+'May 2027'!H10+'Jun 2027'!H10+'Jul 2027'!H10+'Aug 2027'!H10+'Sep 2027'!H10 -> 0 | F26: ='Sep 2027'!I10 -> 0
A27: =Setup!A11 -> Kids Coaching (Class 2) | B27: =Setup!B11 -> Miss Fozia | C27: ='Oct 2026'!F11+'Nov 2026'!F11+'Dec 2026'!F11+'Jan 2027'!F11+'Feb 2027'!F11+'Mar 2027'!F11+'Apr 2027'!F11+'May 2027'!F11+'Jun 2027'!F11+'Jul 2027'!F11+'Aug 2027'!F11+'Sep 2027'!F11 -> 0 | D27: ='Oct 2026'!G11+'Nov 2026'!G11+'Dec 2026'!G11+'Jan 2027'!G11+'Feb 2027'!G11+'Mar 2027'!G11+'Apr 2027'!G11+'May 2027'!G11+'Jun 2027'!G11+'Jul 2027'!G11+'Aug 2027'!G11+'Sep 2027'!G11 -> 0 | E27: ='Oct 2026'!H11+'Nov 2026'!H11+'Dec 2026'!H11+'Jan 2027'!H11+'Feb 2027'!H11+'Mar 2027'!H11+'Apr 2027'!H11+'May 2027'!H11+'Jun 2027'!H11+'Jul 2027'!H11+'Aug 2027'!H11+'Sep 2027'!H11 -> 0 | F27: ='Sep 2027'!I11 -> 0
A28: TOTAL | C28: =SUM(C22:C27) -> 3000 | D28: =SUM(D22:D27) -> 1500 | E28: =SUM(E22:E27) -> 1500 | F28: =SUM(F22:F27) -> 39000
A30: Pending (latest month) shows dues as of the last sheet (Sep 2027); a month you have not filled in yet still carries the dues forward.

Sheet Oct 2026
A1: =UPPER(Setup!B3) -> FUTURE TALENT ACADEMY JAMSHORO
A2: Monthly Fee Register & Profit • October 2026
B4: SUBJECT-WISE SUMMARY (Teacher & Academy) | K4: ADMINISTRATION — ACADEMY PROFIT
B5: Subject | C5: Teacher | E5: Fee Charged | F5: Collected | G5: Teacher Share | H5: Academy Share | I5: Pending | K5: Academy Share of Fees | N5: =H12 -> 1500 | P5: FEES COLLECTED | T5: TEACHERS' SHARE | X5: PENDING FEES
B6: =Setup!A6 -> English | C6: =Setup!B6 -> Sir Sajjad Ali Birhmani | E6: =D166 -> 0 | F6: =E166 -> 0 | G6: =F6*Setup!C6 -> 0 | H6: =F6-G6 -> 0 | I6: =F166 -> 0 | K6: + Other Income | N6: =SUMIFS(Administration!$G$5:$G$304,Administration!$C$5:$C$304,"Oct 2026",Administration!$D$5:$D$304,"Other Income") -> 0 | P6: =F12 -> 3000 | T6: =G12 -> 1500 | X6: =I12 -> 500
B7: =Setup!A7 -> Computer | C7: =Setup!B7 -> Sir Nazeer Ahmed Jamali | E7: =H166 -> 2000 | F7: =I166 -> 2000 | G7: =F7*Setup!C7 -> 1000 | H7: =F7-G7 -> 1000 | I7: =J166 -> 0 | K7: − Expenses | N7: =SUMIFS(Administration!$G$5:$G$304,Administration!$C$5:$C$304,"Oct 2026",Administration!$D$5:$D$304,"Expense") -> 10000
B8: =Setup!A8 -> Biology | C8: =Setup!B8 -> Sir Azhar Ali Chandio | E8: =L166 -> 0 | F8: =M166 -> 0 | G8: =F8*Setup!C8 -> 0 | H8: =F8-G8 -> 0 | I8: =N166 -> 0 | K8: − Investment | N8: =SUMIFS(Administration!$G$5:$G$304,Administration!$C$5:$C$304,"Oct 2026",Administration!$D$5:$D$304,"Investment") -> 8000
B9: =Setup!A9 -> Math | C9: =Setup!B9 -> Sir M. Faheem | E9: =P166 -> 1500 | F9: =Q166 -> 1000 | G9: =F9*Setup!C9 -> 500 | H9: =F9-G9 -> 500 | I9: =R166 -> 500 | P9: =COUNTIF(AC16:AC165,"Clear")&" students fully paid • "&(COUNTIF(AC16:AC165,"Due")+COUNTIF(AC16:AC165,"Partial"))&" students with dues" -> 0 students fully paid • 1 students with dues
B10: =Setup!A10 -> Kids Coaching (Class 1) | C10: =Setup!B10 -> Miss Farzana | E10: =T166 -> 0 | F10: =U166 -> 0 | G10: =F10*Setup!C10 -> 0 | H10: =F10-G10 -> 0 | I10: =V166 -> 0 | K10: NET PROFIT | N10: =N5+N6-N7-N8 -> -16500
B11: =Setup!A11 -> Kids Coaching (Class 2) | C11: =Setup!B11 -> Miss Fozia | E11: =X166 -> 0 | F11: =Y166 -> 0 | G11: =F11*Setup!C11 -> 0 | H11: =F11-G11 -> 0 | I11: =Z166 -> 0 | K11: Expenses & investment come from the Administration sheet.
B12: TOTAL | E12: =SUM(E6:E11) -> 3500 | F12: =SUM(F6:F11) -> 3000 | G12: =SUM(G6:G11) -> 1500 | H12: =SUM(H6:H11) -> 1500 | I12: =SUM(I6:I11) -> 500
A14: STUDENT | C14: =Setup!A6&" — "&Setup!B6 -> English — Sir Sajjad Ali Birhmani | G14: =Setup!A7&" — "&Setup!B7 -> Computer — Sir Nazeer Ahmed Jamali | K14: =Setup!A8&" — "&Setup!B8 -> Biology — Sir Azhar Ali Chandio | O14: =Setup!A9&" — "&Setup!B9 -> Math — Sir M. Faheem | S14: =Setup!A10&" — "&Setup!B10 -> Kids Coaching (Class 1) — Miss Farzana | W14: =Setup!A11&" — "&Setup!B11 -> Kids Coaching (Class 2) — Miss Fozia | AA14: ALL SUBJECTS
A15: Serial No | B15: Student Name | C15: Previous Due | D15: Monthly Fee | E15: Paid | F15: Balance | G15: Previous Due | H15: Monthly Fee | I15: Paid | J15: Balance | K15: Previous Due | L15: Monthly Fee | M15: Paid | N15: Balance | O15: Previous Due | P15: Monthly Fee | Q15: Paid | R15: Balance | S15: Previous Due | T15: Monthly Fee | U15: Paid | V15: Balance | W15: Previous Due | X15: Monthly Fee | Y15: Paid | Z15: Balance | AA15: Total Paid | AB15: Total Due Now | AC15: Status
A16: 1 | B16: =IF(Students!B5="","",Students!B5) -> Ali (example) | D16: =IF(B16="",0,N(Students!E5)) -> 0 | F16: =N(C16)+N(D16)-N(E16) -> 0 | H16: =IF(B16="",0,N(Students!F5)) -> 2000 | I16: 2000 | J16: =N(G16)+N(H16)-N(I16) -> 0 | L16: =IF(B16="",0,N(Students!G5)) -> 0 | N16: =N(K16)+N(L16)-N(M16) -> 0 | P16: =IF(B16="",0,N(Students!H5)) -> 1500 | Q16: 1000 | R16: =N(O16)+N(P16)-N(Q16) -> 500 | T16: =IF(B16="",0,N(Students!I5)) -> 0 | V16: =N(S16)+N(T16)-N(U16) -> 0 | X16: =IF(B16="",0,N(Students!J5)) -> 0 | Z16: =N(W16)+N(X16)-N(Y16) -> 0 | AA16: =N(E16)+N(I16)+N(M16)+N(Q16)+N(U16)+N(Y16) -> 3000 | AB16: =F16+J16+N16+R16+V16+Z16 -> 500 | AC16: =IF(B16="","",IF(AB16<=0,"Clear",IF(AA16>0,"Partial","Due"))) -> Partial
A17: 2 | B17: =IF(Students!B6="","",Students!B6) | D17: =IF(B17="",0,N(Students!E6)) -> 0 | F17: =N(C17)+N(D17)-N(E17) -> 0 | H17: =IF(B17="",0,N(Students!F6)) -> 0 | J17: =N(G17)+N(H17)-N(I17) -> 0 | L17: =IF(B17="",0,N(Students!G6)) -> 0 | N17: =N(K17)+N(L17)-N(M17) -> 0 | P17: =IF(B17="",0,N(Students!H6)) -> 0 | R17: =N(O17)+N(P17)-N(Q17) -> 0 | T17: =IF(B17="",0,N(Students!I6)) -> 0 | V17: =N(S17)+N(T17)-N(U17) -> 0 | X17: =IF(B17="",0,N(Students!J6)) -> 0 | Z17: =N(W17)+N(X17)-N(Y17) -> 0 | AA17: =N(E17)+N(I17)+N(M17)+N(Q17)+N(U17)+N(Y17) -> 0 | AB17: =F17+J17+N17+R17+V17+Z17 -> 0 | AC17: =IF(B17="","",IF(AB17<=0,"Clear",IF(AA17>0,"Partial","Due")))
A18: 3 | B18: =IF(Students!B7="","",Students!B7) | D18: =IF(B18="",0,N(Students!E7)) -> 0 | F18: =N(C18)+N(D18)-N(E18) -> 0 | H18: =IF(B18="",0,N(Students!F7)) -> 0 | J18: =N(G18)+N(H18)-N(I18) -> 0 | L18: =IF(B18="",0,N(Students!G7)) -> 0 | N18: =N(K18)+N(L18)-N(M18) -> 0 | P18: =IF(B18="",0,N(Students!H7)) -> 0 | R18: =N(O18)+N(P18)-N(Q18) -> 0 | T18: =IF(B18="",0,N(Students!I7)) -> 0 | V18: =N(S18)+N(T18)-N(U18) -> 0 | X18: =IF(B18="",0,N(Students!J7)) -> 0 | Z18: =N(W18)+N(X18)-N(Y18) -> 0 | AA18: =N(E18)+N(I18)+N(M18)+N(Q18)+N(U18)+N(Y18) -> 0 | AB18: =F18+J18+N18+R18+V18+Z18 -> 0 | AC18: =IF(B18="","",IF(AB18<=0,"Clear",IF(AA18>0,"Partial","Due")))
A19: 4 | B19: =IF(Students!B8="","",Students!B8) | D19: =IF(B19="",0,N(Students!E8)) -> 0 | F19: =N(C19)+N(D19)-N(E19) -> 0 | H19: =IF(B19="",0,N(Students!F8)) -> 0 | J19: =N(G19)+N(H19)-N(I19) -> 0 | L19: =IF(B19="",0,N(Students!G8)) -> 0 | N19: =N(K19)+N(L19)-N(M19) -> 0 | P19: =IF(B19="",0,N(Students!H8)) -> 0 | R19: =N(O19)+N(P19)-N(Q19) -> 0 | T19: =IF(B19="",0,N(Students!I8)) -> 0 | V19: =N(S19)+N(T19)-N(U19) -> 0 | X19: =IF(B19="",0,N(Students!J8)) -> 0 | Z19: =N(W19)+N(X19)-N(Y19) -> 0 | AA19: =N(E19)+N(I19)+N(M19)+N(Q19)+N(U19)+N(Y19) -> 0 | AB19: =F19+J19+N19+R19+V19+Z19 -> 0 | AC19: =IF(B19="","",IF(AB19<=0,"Clear",IF(AA19>0,"Partial","Due")))
A20: 5 | B20: =IF(Students!B9="","",Students!B9) | D20: =IF(B20="",0,N(Students!E9)) -> 0 | F20: =N(C20)+N(D20)-N(E20) -> 0 | H20: =IF(B20="",0,N(Students!F9)) -> 0 | J20: =N(G20)+N(H20)-N(I20) -> 0 | L20: =IF(B20="",0,N(Students!G9)) -> 0 | N20: =N(K20)+N(L20)-N(M20) -> 0 | P20: =IF(B20="",0,N(Students!H9)) -> 0 | R20: =N(O20)+N(P20)-N(Q20) -> 0 | T20: =IF(B20="",0,N(Students!I9)) -> 0 | V20: =N(S20)+N(T20)-N(U20) -> 0 | X20: =IF(B20="",0,N(Students!J9)) -> 0 | Z20: =N(W20)+N(X20)-N(Y20) -> 0 | AA20: =N(E20)+N(I20)+N(M20)+N(Q20)+N(U20)+N(Y20) -> 0 | AB20: =F20+J20+N20+R20+V20+Z20 -> 0 | AC20: =IF(B20="","",IF(AB20<=0,"Clear",IF(AA20>0,"Partial","Due")))
A21: 6 | B21: =IF(Students!B10="","",Students!B10) | D21: =IF(B21="",0,N(Students!E10)) -> 0 | F21: =N(C21)+N(D21)-N(E21) -> 0 | H21: =IF(B21="",0,N(Students!F10)) -> 0 | J21: =N(G21)+N(H21)-N(I21) -> 0 | L21: =IF(B21="",0,N(Students!G10)) -> 0 | N21: =N(K21)+N(L21)-N(M21) -> 0 | P21: =IF(B21="",0,N(Students!H10)) -> 0 | R21: =N(O21)+N(P21)-N(Q21) -> 0 | T21: =IF(B21="",0,N(Students!I10)) -> 0 | V21: =N(S21)+N(T21)-N(U21) -> 0 | X21: =IF(B21="",0,N(Students!J10)) -> 0 | Z21: =N(W21)+N(X21)-N(Y21) -> 0 | AA21: =N(E21)+N(I21)+N(M21)+N(Q21)+N(U21)+N(Y21) -> 0 | AB21: =F21+J21+N21+R21+V21+Z21 -> 0 | AC21: =IF(B21="","",IF(AB21<=0,"Clear",IF(AA21>0,"Partial","Due")))
A22: 7 | B22: =IF(Students!B11="","",Students!B11) | D22: =IF(B22="",0,N(Students!E11)) -> 0 | F22: =N(C22)+N(D22)-N(E22) -> 0 | H22: =IF(B22="",0,N(Students!F11)) -> 0 | J22: =N(G22)+N(H22)-N(I22) -> 0 | L22: =IF(B22="",0,N(Students!G11)) -> 0 | N22: =N(K22)+N(L22)-N(M22) -> 0 | P22: =IF(B22="",0,N(Students!H11)) -> 0 | R22: =N(O22)+N(P22)-N(Q22) -> 0 | T22: =IF(B22="",0,N(Students!I11)) -> 0 | V22: =N(S22)+N(T22)-N(U22) -> 0 | X22: =IF(B22="",0,N(Students!J11)) -> 0 | Z22: =N(W22)+N(X22)-N(Y22) -> 0 | AA22: =N(E22)+N(I22)+N(M22)+N(Q22)+N(U22)+N(Y22) -> 0 | AB22: =F22+J22+N22+R22+V22+Z22 -> 0 | AC22: =IF(B22="","",IF(AB22<=0,"Clear",IF(AA22>0,"Partial","Due")))
A23: 8 | B23: =IF(Students!B12="","",Students!B12) | D23: =IF(B23="",0,N(Students!E12)) -> 0 | F23: =N(C23)+N(D23)-N(E23) -> 0 | H23: =IF(B23="",0,N(Students!F12)) -> 0 | J23: =N(G23)+N(H23)-N(I23) -> 0 | L23: =IF(B23="",0,N(Students!G12)) -> 0 | N23: =N(K23)+N(L23)-N(M23) -> 0 | P23: =IF(B23="",0,N(Students!H12)) -> 0 | R23: =N(O23)+N(P23)-N(Q23) -> 0 | T23: =IF(B23="",0,N(Students!I12)) -> 0 | V23: =N(S23)+N(T23)-N(U23) -> 0 | X23: =IF(B23="",0,N(Students!J12)) -> 0 | Z23: =N(W23)+N(X23)-N(Y23) -> 0 | AA23: =N(E23)+N(I23)+N(M23)+N(Q23)+N(U23)+N(Y23) -> 0 | AB23: =F23+J23+N23+R23+V23+Z23 -> 0 | AC23: =IF(B23="","",IF(AB23<=0,"Clear",IF(AA23>0,"Partial","Due")))
A24: 9 | B24: =IF(Students!B13="","",Students!B13) | D24: =IF(B24="",0,N(Students!E13)) -> 0 | F24: =N(C24)+N(D24)-N(E24) -> 0 | H24: =IF(B24="",0,N(Students!F13)) -> 0 | J24: =N(G24)+N(H24)-N(I24) -> 0 | L24: =IF(B24="",0,N(Students!G13)) -> 0 | N24: =N(K24)+N(L24)-N(M24) -> 0 | P24: =IF(B24="",0,N(Students!H13)) -> 0 | R24: =N(O24)+N(P24)-N(Q24) -> 0 | T24: =IF(B24="",0,N(Students!I13)) -> 0 | V24: =N(S24)+N(T24)-N(U24) -> 0 | X24: =IF(B24="",0,N(Students!J13)) -> 0 | Z24: =N(W24)+N(X24)-N(Y24) -> 0 | AA24: =N(E24)+N(I24)+N(M24)+N(Q24)+N(U24)+N(Y24) -> 0 | AB24: =F24+J24+N24+R24+V24+Z24 -> 0 | AC24: =IF(B24="","",IF(AB24<=0,"Clear",IF(AA24>0,"Partial","Due")))
A25: 10 | B25: =IF(Students!B14="","",Students!B14) | D25: =IF(B25="",0,N(Students!E14)) -> 0 | F25: =N(C25)+N(D25)-N(E25) -> 0 | H25: =IF(B25="",0,N(Students!F14)) -> 0 | J25: =N(G25)+N(H25)-N(I25) -> 0 | L25: =IF(B25="",0,N(Students!G14)) -> 0 | N25: =N(K25)+N(L25)-N(M25) -> 0 | P25: =IF(B25="",0,N(Students!H14)) -> 0 | R25: =N(O25)+N(P25)-N(Q25) -> 0 | T25: =IF(B25="",0,N(Students!I14)) -> 0 | V25: =N(S25)+N(T25)-N(U25) -> 0 | X25: =IF(B25="",0,N(Students!J14)) -> 0 | Z25: =N(W25)+N(X25)-N(Y25) -> 0 | AA25: =N(E25)+N(I25)+N(M25)+N(Q25)+N(U25)+N(Y25) -> 0 | AB25: =F25+J25+N25+R25+V25+Z25 -> 0 | AC25: =IF(B25="","",IF(AB25<=0,"Clear",IF(AA25>0,"Partial","Due")))
A26: 11 | B26: =IF(Students!B15="","",Students!B15) | D26: =IF(B26="",0,N(Students!E15)) -> 0 | F26: =N(C26)+N(D26)-N(E26) -> 0 | H26: =IF(B26="",0,N(Students!F15)) -> 0 | J26: =N(G26)+N(H26)-N(I26) -> 0 | L26: =IF(B26="",0,N(Students!G15)) -> 0 | N26: =N(K26)+N(L26)-N(M26) -> 0 | P26: =IF(B26="",0,N(Students!H15)) -> 0 | R26: =N(O26)+N(P26)-N(Q26) -> 0 | T26: =IF(B26="",0,N(Students!I15)) -> 0 | V26: =N(S26)+N(T26)-N(U26) -> 0 | X26: =IF(B26="",0,N(Students!J15)) -> 0 | Z26: =N(W26)+N(X26)-N(Y26) -> 0 | AA26: =N(E26)+N(I26)+N(M26)+N(Q26)+N(U26)+N(Y26) -> 0 | AB26: =F26+J26+N26+R26+V26+Z26 -> 0 | AC26: =IF(B26="","",IF(AB26<=0,"Clear",IF(AA26>0,"Partial","Due")))
A27: 12 | B27: =IF(Students!B16="","",Students!B16) | D27: =IF(B27="",0,N(Students!E16)) -> 0 | F27: =N(C27)+N(D27)-N(E27) -> 0 | H27: =IF(B27="",0,N(Students!F16)) -> 0 | J27: =N(G27)+N(H27)-N(I27) -> 0 | L27: =IF(B27="",0,N(Students!G16)) -> 0 | N27: =N(K27)+N(L27)-N(M27) -> 0 | P27: =IF(B27="",0,N(Students!H16)) -> 0 | R27: =N(O27)+N(P27)-N(Q27) -> 0 | T27: =IF(B27="",0,N(Students!I16)) -> 0 | V27: =N(S27)+N(T27)-N(U27) -> 0 | X27: =IF(B27="",0,N(Students!J16)) -> 0 | Z27: =N(W27)+N(X27)-N(Y27) -> 0 | AA27: =N(E27)+N(I27)+N(M27)+N(Q27)+N(U27)+N(Y27) -> 0 | AB27: =F27+J27+N27+R27+V27+Z27 -> 0 | AC27: =IF(B27="","",IF(AB27<=0,"Clear",IF(AA27>0,"Partial","Due")))
A28: 13 | B28: =IF(Students!B17="","",Students!B17) | D28: =IF(B28="",0,N(Students!E17)) -> 0 | F28: =N(C28)+N(D28)-N(E28) -> 0 | H28: =IF(B28="",0,N(Students!F17)) -> 0 | J28: =N(G28)+N(H28)-N(I28) -> 0 | L28: =IF(B28="",0,N(Students!G17)) -> 0 | N28: =N(K28)+N(L28)-N(M28) -> 0 | P28: =IF(B28="",0,N(Students!H17)) -> 0 | R28: =N(O28)+N(P28)-N(Q28) -> 0 | T28: =IF(B28="",0,N(Students!I17)) -> 0 | V28: =N(S28)+N(T28)-N(U28) -> 0 | X28: =IF(B28="",0,N(Students!J17)) -> 0 | Z28: =N(W28)+N(X28)-N(Y28) -> 0 | AA28: =N(E28)+N(I28)+N(M28)+N(Q28)+N(U28)+N(Y28) -> 0 | AB28: =F28+J28+N28+R28+V28+Z28 -> 0 | AC28: =IF(B28="","",IF(AB28<=0,"Clear",IF(AA28>0,"Partial","Due")))
... A165: 150 | B165: =IF(Students!B154="","",Students!B154) | D165: =IF(B165="",0,N(Students!E154)) -> 0 | F165: =N(C165)+N(D165)-N(E165) -> 0 | H165: =IF(B165="",0,N(Students!F154)) -> 0 | J165: =N(G165)+N(H165)-N(I165) -> 0 | L165: =IF(B165="",0,N(Students!G154)) -> 0 | N165: =N(K165)+N(L165)-N(M165) -> 0 | P165: =IF(B165="",0,N(Students!H154)) -> 0 | R165: =N(O165)+N(P165)-N(Q165) -> 0 | T165: =IF(B165="",0,N(Students!I154)) -> 0 | V165: =N(S165)+N(T165)-N(U165) -> 0 | X165: =IF(B165="",0,N(Students!J154)) -> 0 | Z165: =N(W165)+N(X165)-N(Y165) -> 0 | AA165: =N(E165)+N(I165)+N(M165)+N(Q165)+N(U165)+N(Y165) -> 0 | AB165: =F165+J165+N165+R165+V165+Z165 -> 0 | AC165: =IF(B165="","",IF(AB165<=0,"Clear",IF(AA165>0,"Partial","Due")))
A166: TOTAL | C166: =SUM(C16:C165) -> 0 | D166: =SUM(D16:D165) -> 0 | E166: =SUM(E16:E165) -> 0 | F166: =SUM(F16:F165) -> 0 | G166: =SUM(G16:G165) -> 0 | H166: =SUM(H16:H165) -> 2000 | I166: =SUM(I16:I165) -> 2000 | J166: =SUM(J16:J165) -> 0 | ... AB166: =SUM(AB16:AB165) -> 500

Sheet Nov 2026
A1: =UPPER(Setup!B3) -> FUTURE TALENT ACADEMY JAMSHORO
A2: Monthly Fee Register & Profit • November 2026
B4: SUBJECT-WISE SUMMARY (Teacher & Academy) | K4: ADMINISTRATION — ACADEMY PROFIT
B5: Subject | C5: Teacher | E5: Fee Charged | F5: Collected | G5: Teacher Share | H5: Academy Share | I5: Pending | K5: Academy Share of Fees | N5: =H12 -> 0 | P5: FEES COLLECTED | T5: TEACHERS' SHARE | X5: PENDING FEES
B6: =Setup!A6 -> English | C6: =Setup!B6 -> Sir Sajjad Ali Birhmani | E6: =D166 -> 0 | F6: =E166 -> 0 | G6: =F6*Setup!C6 -> 0 | H6: =F6-G6 -> 0 | I6: =F166 -> 0 | K6: + Other Income | N6: =SUMIFS(Administration!$G$5:$G$304,Administration!$C$5:$C$304,"Nov 2026",Administration!$D$5:$D$304,"Other Income") -> 0 | P6: =F12 -> 0 | T6: =G12 -> 0 | X6: =I12 -> 4000
B7: =Setup!A7 -> Computer | C7: =Setup!B7 -> Sir Nazeer Ahmed Jamali | E7: =H166 -> 2000 | F7: =I166 -> 0 | G7: =F7*Setup!C7 -> 0 | H7: =F7-G7 -> 0 | I7: =J166 -> 2000 | K7: − Expenses | N7: =SUMIFS(Administration!$G$5:$G$304,Administration!$C$5:$C$304,"Nov 2026",Administration!$D$5:$D$304,"Expense") -> 0
B8: =Setup!A8 -> Biology | C8: =Setup!B8 -> Sir Azhar Ali Chandio | E8: =L166 -> 0 | F8: =M166 -> 0 | G8: =F8*Setup!C8 -> 0 | H8: =F8-G8 -> 0 | I8: =N166 -> 0 | K8: − Investment | N8: =SUMIFS(Administration!$G$5:$G$304,Administration!$C$5:$C$304,"Nov 2026",Administration!$D$5:$D$304,"Investment") -> 0
B9: =Setup!A9 -> Math | C9: =Setup!B9 -> Sir M. Faheem | E9: =P166 -> 1500 | F9: =Q166 -> 0 | G9: =F9*Setup!C9 -> 0 | H9: =F9-G9 -> 0 | I9: =R166 -> 2000 | P9: =COUNTIF(AC16:AC165,"Clear")&" students fully paid • "&(COUNTIF(AC16:AC165,"Due")+COUNTIF(AC16:AC165,"Partial"))&" students with dues" -> 0 students fully paid • 1 students with dues
B10: =Setup!A10 -> Kids Coaching (Class 1) | C10: =Setup!B10 -> Miss Farzana | E10: =T166 -> 0 | F10: =U166 -> 0 | G10: =F10*Setup!C10 -> 0 | H10: =F10-G10 -> 0 | I10: =V166 -> 0 | K10: NET PROFIT | N10: =N5+N6-N7-N8 -> 0
B11: =Setup!A11 -> Kids Coaching (Class 2) | C11: =Setup!B11 -> Miss Fozia | E11: =X166 -> 0 | F11: =Y166 -> 0 | G11: =F11*Setup!C11 -> 0 | H11: =F11-G11 -> 0 | I11: =Z166 -> 0 | K11: Expenses & investment come from the Administration sheet.
B12: TOTAL | E12: =SUM(E6:E11) -> 3500 | F12: =SUM(F6:F11) -> 0 | G12: =SUM(G6:G11) -> 0 | H12: =SUM(H6:H11) -> 0 | I12: =SUM(I6:I11) -> 4000
A14: STUDENT | C14: =Setup!A6&" — "&Setup!B6 -> English — Sir Sajjad Ali Birhmani | G14: =Setup!A7&" — "&Setup!B7 -> Computer — Sir Nazeer Ahmed Jamali | K14: =Setup!A8&" — "&Setup!B8 -> Biology — Sir Azhar Ali Chandio | O14: =Setup!A9&" — "&Setup!B9 -> Math — Sir M. Faheem | S14: =Setup!A10&" — "&Setup!B10 -> Kids Coaching (Class 1) — Miss Farzana | W14: =Setup!A11&" — "&Setup!B11 -> Kids Coaching (Class 2) — Miss Fozia | AA14: ALL SUBJECTS
A15: Serial No | B15: Student Name | C15: Previous Due | D15: Monthly Fee | E15: Paid | F15: Balance | G15: Previous Due | H15: Monthly Fee | I15: Paid | J15: Balance | K15: Previous Due | L15: Monthly Fee | M15: Paid | N15: Balance | O15: Previous Due | P15: Monthly Fee | Q15: Paid | R15: Balance | S15: Previous Due | T15: Monthly Fee | U15: Paid | V15: Balance | W15: Previous Due | X15: Monthly Fee | Y15: Paid | Z15: Balance | AA15: Total Paid | AB15: Total Due Now | AC15: Status
A16: 1 | B16: =IF(Students!B5="","",Students!B5) -> Ali (example) | C16: ='Oct 2026'!F16 -> 0 | D16: =IF(B16="",0,N(Students!E5)) -> 0 | F16: =N(C16)+N(D16)-N(E16) -> 0 | G16: ='Oct 2026'!J16 -> 0 | H16: =IF(B16="",0,N(Students!F5)) -> 2000 | J16: =N(G16)+N(H16)-N(I16) -> 2000 | K16: ='Oct 2026'!N16 -> 0 | L16: =IF(B16="",0,N(Students!G5)) -> 0 | N16: =N(K16)+N(L16)-N(M16) -> 0 | O16: ='Oct 2026'!R16 -> 500 | P16: =IF(B16="",0,N(Students!H5)) -> 1500 | R16: =N(O16)+N(P16)-N(Q16) -> 2000 | S16: ='Oct 2026'!V16 -> 0 | T16: =IF(B16="",0,N(Students!I5)) -> 0 | V16: =N(S16)+N(T16)-N(U16) -> 0 | W16: ='Oct 2026'!Z16 -> 0 | X16: =IF(B16="",0,N(Students!J5)) -> 0 | Z16: =N(W16)+N(X16)-N(Y16) -> 0 | AA16: =N(E16)+N(I16)+N(M16)+N(Q16)+N(U16)+N(Y16) -> 0 | AB16: =F16+J16+N16+R16+V16+Z16 -> 4000 | AC16: =IF(B16="","",IF(AB16<=0,"Clear",IF(AA16>0,"Partial","Due"))) -> Due
A17: 2 | B17: =IF(Students!B6="","",Students!B6) | C17: ='Oct 2026'!F17 -> 0 | D17: =IF(B17="",0,N(Students!E6)) -> 0 | F17: =N(C17)+N(D17)-N(E17) -> 0 | G17: ='Oct 2026'!J17 -> 0 | H17: =IF(B17="",0,N(Students!F6)) -> 0 | J17: =N(G17)+N(H17)-N(I17) -> 0 | K17: ='Oct 2026'!N17 -> 0 | L17: =IF(B17="",0,N(Students!G6)) -> 0 | N17: =N(K17)+N(L17)-N(M17) -> 0 | O17: ='Oct 2026'!R17 -> 0 | P17: =IF(B17="",0,N(Students!H6)) -> 0 | R17: =N(O17)+N(P17)-N(Q17) -> 0 | S17: ='Oct 2026'!V17 -> 0 | T17: =IF(B17="",0,N(Students!I6)) -> 0 | V17: =N(S17)+N(T17)-N(U17) -> 0 | W17: ='Oct 2026'!Z17 -> 0 | X17: =IF(B17="",0,N(Students!J6)) -> 0 | Z17: =N(W17)+N(X17)-N(Y17) -> 0 | AA17: =N(E17)+N(I17)+N(M17)+N(Q17)+N(U17)+N(Y17) -> 0 | AB17: =F17+J17+N17+R17+V17+Z17 -> 0 | AC17: =IF(B17="","",IF(AB17<=0,"Clear",IF(AA17>0,"Partial","Due")))
A18: 3 | B18: =IF(Students!B7="","",Students!B7) | C18: ='Oct 2026'!F18 -> 0 | D18: =IF(B18="",0,N(Students!E7)) -> 0 | F18: =N(C18)+N(D18)-N(E18) -> 0 | G18: ='Oct 2026'!J18 -> 0 | H18: =IF(B18="",0,N(Students!F7)) -> 0 | J18: =N(G18)+N(H18)-N(I18) -> 0 | K18: ='Oct 2026'!N18 -> 0 | L18: =IF(B18="",0,N(Students!G7)) -> 0 | N18: =N(K18)+N(L18)-N(M18) -> 0 | O18: ='Oct 2026'!R18 -> 0 | P18: =IF(B18="",0,N(Students!H7)) -> 0 | R18: =N(O18)+N(P18)-N(Q18) -> 0 | S18: ='Oct 2026'!V18 -> 0 | T18: =IF(B18="",0,N(Students!I7)) -> 0 | V18: =N(S18)+N(T18)-N(U18) -> 0 | W18: ='Oct 2026'!Z18 -> 0 | X18: =IF(B18="",0,N(Students!J7)) -> 0 | Z18: =N(W18)+N(X18)-N(Y18) -> 0 | AA18: =N(E18)+N(I18)+N(M18)+N(Q18)+N(U18)+N(Y18) -> 0 | AB18: =F18+J18+N18+R18+V18+Z18 -> 0 | AC18: =IF(B18="","",IF(AB18<=0,"Clear",IF(AA18>0,"Partial","Due")))
A19: 4 | B19: =IF(Students!B8="","",Students!B8) | C19: ='Oct 2026'!F19 -> 0 | D19: =IF(B19="",0,N(Students!E8)) -> 0 | F19: =N(C19)+N(D19)-N(E19) -> 0 | G19: ='Oct 2026'!J19 -> 0 | H19: =IF(B19="",0,N(Students!F8)) -> 0 | J19: =N(G19)+N(H19)-N(I19) -> 0 | K19: ='Oct 2026'!N19 -> 0 | L19: =IF(B19="",0,N(Students!G8)) -> 0 | N19: =N(K19)+N(L19)-N(M19) -> 0 | O19: ='Oct 2026'!R19 -> 0 | P19: =IF(B19="",0,N(Students!H8)) -> 0 | R19: =N(O19)+N(P19)-N(Q19) -> 0 | S19: ='Oct 2026'!V19 -> 0 | T19: =IF(B19="",0,N(Students!I8)) -> 0 | V19: =N(S19)+N(T19)-N(U19) -> 0 | W19: ='Oct 2026'!Z19 -> 0 | X19: =IF(B19="",0,N(Students!J8)) -> 0 | Z19: =N(W19)+N(X19)-N(Y19) -> 0 | AA19: =N(E19)+N(I19)+N(M19)+N(Q19)+N(U19)+N(Y19) -> 0 | AB19: =F19+J19+N19+R19+V19+Z19 -> 0 | AC19: =IF(B19="","",IF(AB19<=0,"Clear",IF(AA19>0,"Partial","Due")))
A20: 5 | B20: =IF(Students!B9="","",Students!B9) | C20: ='Oct 2026'!F20 -> 0 | D20: =IF(B20="",0,N(Students!E9)) -> 0 | F20: =N(C20)+N(D20)-N(E20) -> 0 | G20: ='Oct 2026'!J20 -> 0 | H20: =IF(B20="",0,N(Students!F9)) -> 0 | J20: =N(G20)+N(H20)-N(I20) -> 0 | K20: ='Oct 2026'!N20 -> 0 | L20: =IF(B20="",0,N(Students!G9)) -> 0 | N20: =N(K20)+N(L20)-N(M20) -> 0 | O20: ='Oct 2026'!R20 -> 0 | P20: =IF(B20="",0,N(Students!H9)) -> 0 | R20: =N(O20)+N(P20)-N(Q20) -> 0 | S20: ='Oct 2026'!V20 -> 0 | T20: =IF(B20="",0,N(Students!I9)) -> 0 | V20: =N(S20)+N(T20)-N(U20) -> 0 | W20: ='Oct 2026'!Z20 -> 0 | X20: =IF(B20="",0,N(Students!J9)) -> 0 | Z20: =N(W20)+N(X20)-N(Y20) -> 0 | AA20: =N(E20)+N(I20)+N(M20)+N(Q20)+N(U20)+N(Y20) -> 0 | AB20: =F20+J20+N20+R20+V20+Z20 -> 0 | AC20: =IF(B20="","",IF(AB20<=0,"Clear",IF(AA20>0,"Partial","Due")))
A21: 6 | B21: =IF(Students!B10="","",Students!B10) | C21: ='Oct 2026'!F21 -> 0 | D21: =IF(B21="",0,N(Students!E10)) -> 0 | F21: =N(C21)+N(D21)-N(E21) -> 0 | G21: ='Oct 2026'!J21 -> 0 | H21: =IF(B21="",0,N(Students!F10)) -> 0 | J21: =N(G21)+N(H21)-N(I21) -> 0 | K21: ='Oct 2026'!N21 -> 0 | L21: =IF(B21="",0,N(Students!G10)) -> 0 | N21: =N(K21)+N(L21)-N(M21) -> 0 | O21: ='Oct 2026'!R21 -> 0 | P21: =IF(B21="",0,N(Students!H10)) -> 0 | R21: =N(O21)+N(P21)-N(Q21) -> 0 | S21: ='Oct 2026'!V21 -> 0 | T21: =IF(B21="",0,N(Students!I10)) -> 0 | V21: =N(S21)+N(T21)-N(U21) -> 0 | W21: ='Oct 2026'!Z21 -> 0 | X21: =IF(B21="",0,N(Students!J10)) -> 0 | Z21: =N(W21)+N(X21)-N(Y21) -> 0 | AA21: =N(E21)+N(I21)+N(M21)+N(Q21)+N(U21)+N(Y21) -> 0 | AB21: =F21+J21+N21+R21+V21+Z21 -> 0 | AC21: =IF(B21="","",IF(AB21<=0,"Clear",IF(AA21>0,"Partial","Due")))
A22: 7 | B22: =IF(Students!B11="","",Students!B11) | C22: ='Oct 2026'!F22 -> 0 | D22: =IF(B22="",0,N(Students!E11)) -> 0 | F22: =N(C22)+N(D22)-N(E22) -> 0 | G22: ='Oct 2026'!J22 -> 0 | H22: =IF(B22="",0,N(Students!F11)) -> 0 | J22: =N(G22)+N(H22)-N(I22) -> 0 | K22: ='Oct 2026'!N22 -> 0 | L22: =IF(B22="",0,N(Students!G11)) -> 0 | N22: =N(K22)+N(L22)-N(M22) -> 0 | O22: ='Oct 2026'!R22 -> 0 | P22: =IF(B22="",0,N(Students!H11)) -> 0 | R22: =N(O22)+N(P22)-N(Q22) -> 0 | S22: ='Oct 2026'!V22 -> 0 | T22: =IF(B22="",0,N(Students!I11)) -> 0 | V22: =N(S22)+N(T22)-N(U22) -> 0 | W22: ='Oct 2026'!Z22 -> 0 | X22: =IF(B22="",0,N(Students!J11)) -> 0 | Z22: =N(W22)+N(X22)-N(Y22) -> 0 | AA22: =N(E22)+N(I22)+N(M22)+N(Q22)+N(U22)+N(Y22) -> 0 | AB22: =F22+J22+N22+R22+V22+Z22 -> 0 | AC22: =IF(B22="","",IF(AB22<=0,"Clear",IF(AA22>0,"Partial","Due")))
A23: 8 | B23: =IF(Students!B12="","",Students!B12) | C23: ='Oct 2026'!F23 -> 0 | D23: =IF(B23="",0,N(Students!E12)) -> 0 | F23: =N(C23)+N(D23)-N(E23) -> 0 | G23: ='Oct 2026'!J23 -> 0 | H23: =IF(B23="",0,N(Students!F12)) -> 0 | J23: =N(G23)+N(H23)-N(I23) -> 0 | K23: ='Oct 2026'!N23 -> 0 | L23: =IF(B23="",0,N(Students!G12)) -> 0 | N23: =N(K23)+N(L23)-N(M23) -> 0 | O23: ='Oct 2026'!R23 -> 0 | P23: =IF(B23="",0,N(Students!H12)) -> 0 | R23: =N(O23)+N(P23)-N(Q23) -> 0 | S23: ='Oct 2026'!V23 -> 0 | T23: =IF(B23="",0,N(Students!I12)) -> 0 | V23: =N(S23)+N(T23)-N(U23) -> 0 | W23: ='Oct 2026'!Z23 -> 0 | X23: =IF(B23="",0,N(Students!J12)) -> 0 | Z23: =N(W23)+N(X23)-N(Y23) -> 0 | AA23: =N(E23)+N(I23)+N(M23)+N(Q23)+N(U23)+N(Y23) -> 0 | AB23: =F23+J23+N23+R23+V23+Z23 -> 0 | AC23: =IF(B23="","",IF(AB23<=0,"Clear",IF(AA23>0,"Partial","Due")))
A24: 9 | B24: =IF(Students!B13="","",Students!B13) | C24: ='Oct 2026'!F24 -> 0 | D24: =IF(B24="",0,N(Students!E13)) -> 0 | F24: =N(C24)+N(D24)-N(E24) -> 0 | G24: ='Oct 2026'!J24 -> 0 | H24: =IF(B24="",0,N(Students!F13)) -> 0 | J24: =N(G24)+N(H24)-N(I24) -> 0 | K24: ='Oct 2026'!N24 -> 0 | L24: =IF(B24="",0,N(Students!G13)) -> 0 | N24: =N(K24)+N(L24)-N(M24) -> 0 | O24: ='Oct 2026'!R24 -> 0 | P24: =IF(B24="",0,N(Students!H13)) -> 0 | R24: =N(O24)+N(P24)-N(Q24) -> 0 | S24: ='Oct 2026'!V24 -> 0 | T24: =IF(B24="",0,N(Students!I13)) -> 0 | V24: =N(S24)+N(T24)-N(U24) -> 0 | W24: ='Oct 2026'!Z24 -> 0 | X24: =IF(B24="",0,N(Students!J13)) -> 0 | Z24: =N(W24)+N(X24)-N(Y24) -> 0 | AA24: =N(E24)+N(I24)+N(M24)+N(Q24)+N(U24)+N(Y24) -> 0 | AB24: =F24+J24+N24+R24+V24+Z24 -> 0 | AC24: =IF(B24="","",IF(AB24<=0,"Clear",IF(AA24>0,"Partial","Due")))
A25: 10 | B25: =IF(Students!B14="","",Students!B14) | C25: ='Oct 2026'!F25 -> 0 | D25: =IF(B25="",0,N(Students!E14)) -> 0 | F25: =N(C25)+N(D25)-N(E25) -> 0 | G25: ='Oct 2026'!J25 -> 0 | H25: =IF(B25="",0,N(Students!F14)) -> 0 | J25: =N(G25)+N(H25)-N(I25) -> 0 | K25: ='Oct 2026'!N25 -> 0 | L25: =IF(B25="",0,N(Students!G14)) -> 0 | N25: =N(K25)+N(L25)-N(M25) -> 0 | O25: ='Oct 2026'!R25 -> 0 | P25: =IF(B25="",0,N(Students!H14)) -> 0 | R25: =N(O25)+N(P25)-N(Q25) -> 0 | S25: ='Oct 2026'!V25 -> 0 | T25: =IF(B25="",0,N(Students!I14)) -> 0 | V25: =N(S25)+N(T25)-N(U25) -> 0 | W25: ='Oct 2026'!Z25 -> 0 | X25: =IF(B25="",0,N(Students!J14)) -> 0 | Z25: =N(W25)+N(X25)-N(Y25) -> 0 | AA25: =N(E25)+N(I25)+N(M25)+N(Q25)+N(U25)+N(Y25) -> 0 | AB25: =F25+J25+N25+R25+V25+Z25 -> 0 | AC25: =IF(B25="","",IF(AB25<=0,"Clear",IF(AA25>0,"Partial","Due")))
A26: 11 | B26: =IF(Students!B15="","",Students!B15) | C26: ='Oct 2026'!F26 -> 0 | D26: =IF(B26="",0,N(Students!E15)) -> 0 | F26: =N(C26)+N(D26)-N(E26) -> 0 | G26: ='Oct 2026'!J26 -> 0 | H26: =IF(B26="",0,N(Students!F15)) -> 0 | J26: =N(G26)+N(H26)-N(I26) -> 0 | K26: ='Oct 2026'!N26 -> 0 | L26: =IF(B26="",0,N(Students!G15)) -> 0 | N26: =N(K26)+N(L26)-N(M26) -> 0 | O26: ='Oct 2026'!R26 -> 0 | P26: =IF(B26="",0,N(Students!H15)) -> 0 | R26: =N(O26)+N(P26)-N(Q26) -> 0 | S26: ='Oct 2026'!V26 -> 0 | T26: =IF(B26="",0,N(Students!I15)) -> 0 | V26: =N(S26)+N(T26)-N(U26) -> 0 | W26: ='Oct 2026'!Z26 -> 0 | X26: =IF(B26="",0,N(Students!J15)) -> 0 | Z26: =N(W26)+N(X26)-N(Y26) -> 0 | AA26: =N(E26)+N(I26)+N(M26)+N(Q26)+N(U26)+N(Y26) -> 0 | AB26: =F26+J26+N26+R26+V26+Z26 -> 0 | AC26: =IF(B26="","",IF(AB26<=0,"Clear",IF(AA26>0,"Partial","Due")))
A27: 12 | B27: =IF(Students!B16="","",Students!B16) | C27: ='Oct 2026'!F27 -> 0 | D27: =IF(B27="",0,N(Students!E16)) -> 0 | F27: =N(C27)+N(D27)-N(E27) -> 0 | G27: ='Oct 2026'!J27 -> 0 | H27: =IF(B27="",0,N(Students!F16)) -> 0 | J27: =N(G27)+N(H27)-N(I27) -> 0 | K27: ='Oct 2026'!N27 -> 0 | L27: =IF(B27="",0,N(Students!G16)) -> 0 | N27: =N(K27)+N(L27)-N(M27) -> 0 | O27: ='Oct 2026'!R27 -> 0 | P27: =IF(B27="",0,N(Students!H16)) -> 0 | R27: =N(O27)+N(P27)-N(Q27) -> 0 | S27: ='Oct 2026'!V27 -> 0 | T27: =IF(B27="",0,N(Students!I16)) -> 0 | V27: =N(S27)+N(T27)-N(U27) -> 0 | W27: ='Oct 2026'!Z27 -> 0 | X27: =IF(B27="",0,N(Students!J16)) -> 0 | Z27: =N(W27)+N(X27)-N(Y27) -> 0 | AA27: =N(E27)+N(I27)+N(M27)+N(Q27)+N(U27)+N(Y27) -> 0 | AB27: =F27+J27+N27+R27+V27+Z27 -> 0 | AC27: =IF(B27="","",IF(AB27<=0,"Clear",IF(AA27>0,"Partial","Due")))
... A165: 150 | B165: =IF(Students!B154="","",Students!B154) | C165: ='Oct 2026'!F165 -> 0 | D165: =IF(B165="",0,N(Students!E154)) -> 0 | F165: =N(C165)+N(D165)-N(E165) -> 0 | G165: ='Oct 2026'!J165 -> 0 | H165: =IF(B165="",0,N(Students!F154)) -> 0 | J165: =N(G165)+N(H165)-N(I165) -> 0 | K165: ='Oct 2026'!N165 -> 0 | L165: =IF(B165="",0,N(Students!G154)) -> 0 | N165: =N(K165)+N(L165)-N(M165) -> 0 | O165: ='Oct 2026'!R165 -> 0 | P165: =IF(B165="",0,N(Students!H154)) -> 0 | R165: =N(O165)+N(P165)-N(Q165) -> 0 | S165: ='Oct 2026'!V165 -> 0 | T165: =IF(B165="",0,N(Students!I154)) -> 0 | V165: =N(S165)+N(T165)-N(U165) -> 0 | W165: ='Oct 2026'!Z165 -> 0 | X165: =IF(B165="",0,N(Students!J154)) -> 0 | Z165: =N(W165)+N(X165)-N(Y165) -> 0 | AA165: =N(E165)+N(I165)+N(M165)+N(Q165)+N(U165)+N(Y165) -> 0 | AB165: =F165+J165+N165+R165+V165+Z165 -> 0 | AC165: =IF(B165="","",IF(AB165<=0,"Clear",IF(AA165>0,"Partial","Due")))
A166: TOTAL | C166: =SUM(C16:C165) -> 0 | D166: =SUM(D16:D165) -> 0 | E166: =SUM(E16:E165) -> 0 | F166: =SUM(F16:F165) -> 0 | G166: =SUM(G16:G165) -> 0 | H166: =SUM(H16:H165) -> 2000 | I166: =SUM(I16:I165) -> 0 | J166: =SUM(J16:J165) -> 2000 | ... AB166: =SUM(AB16:AB165) -> 4000

Sheet Dec 2026
A1: =UPPER(Setup!B3) -> FUTURE TALENT ACADEMY JAMSHORO
A2: Monthly Fee Register & Profit • December 2026
B4: SUBJECT-WISE SUMMARY (Teacher & Academy) | K4: ADMINISTRATION — ACADEMY PROFIT
B5: Subject | C5: Teacher | E5: Fee Charged | F5: Collected | G5: Teacher Share | H5: Academy Share | I5: Pending | K5: Academy Share of Fees | N5: =H12 -> 0 | P5: FEES COLLECTED | T5: TEACHERS' SHARE | X5: PENDING FEES
B6: =Setup!A6 -> English | C6: =Setup!B6 -> Sir Sajjad Ali Birhmani | E6: =D166 -> 0 | F6: =E166 -> 0 | G6: =F6*Setup!C6 -> 0 | H6: =F6-G6 -> 0 | I6: =F166 -> 0 | K6: + Other Income | N6: =SUMIFS(Administration!$G$5:$G$304,Administration!$C$5:$C$304,"Dec 2026",Administration!$D$5:$D$304,"Other Income") -> 0 | P6: =F12 -> 0 | T6: =G12 -> 0 | X6: =I12 -> 7500
B7: =Setup!A7 -> Computer | C7: =Setup!B7 -> Sir Nazeer Ahmed Jamali | E7: =H166 -> 2000 | F7: =I166 -> 0 | G7: =F7*Setup!C7 -> 0 | H7: =F7-G7 -> 0 | I7: =J166 -> 4000 | K7: − Expenses | N7: =SUMIFS(Administration!$G$5:$G$304,Administration!$C$5:$C$304,"Dec 2026",Administration!$D$5:$D$304,"Expense") -> 0
B8: =Setup!A8 -> Biology | C8: =Setup!B8 -> Sir Azhar Ali Chandio | E8: =L166 -> 0 | F8: =M166 -> 0 | G8: =F8*Setup!C8 -> 0 | H8: =F8-G8 -> 0 | I8: =N166 -> 0 | K8: − Investment | N8: =SUMIFS(Administration!$G$5:$G$304,Administration!$C$5:$C$304,"Dec 2026",Administration!$D$5:$D$304,"Investment") -> 0
B9: =Setup!A9 -> Math | C9: =Setup!B9 -> Sir M. Faheem | E9: =P166 -> 1500 | F9: =Q166 -> 0 | G9: =F9*Setup!C9 -> 0 | H9: =F9-G9 -> 0 | I9: =R166 -> 3500 | P9: =COUNTIF(AC16:AC165,"Clear")&" students fully paid • "&(COUNTIF(AC16:AC165,"Due")+COUNTIF(AC16:AC165,"Partial"))&" students with dues" -> 0 students fully paid • 1 students with dues
B10: =Setup!A10 -> Kids Coaching (Class 1) | C10: =Setup!B10 -> Miss Farzana | E10: =T166 -> 0 | F10: =U166 -> 0 | G10: =F10*Setup!C10 -> 0 | H10: =F10-G10 -> 0 | I10: =V166 -> 0 | K10: NET PROFIT | N10: =N5+N6-N7-N8 -> 0
B11: =Setup!A11 -> Kids Coaching (Class 2) | C11: =Setup!B11 -> Miss Fozia | E11: =X166 -> 0 | F11: =Y166 -> 0 | G11: =F11*Setup!C11 -> 0 | H11: =F11-G11 -> 0 | I11: =Z166 -> 0 | K11: Expenses & investment come from the Administration sheet.
B12: TOTAL | E12: =SUM(E6:E11) -> 3500 | F12: =SUM(F6:F11) -> 0 | G12: =SUM(G6:G11) -> 0 | H12: =SUM(H6:H11) -> 0 | I12: =SUM(I6:I11) -> 7500
A14: STUDENT | C14: =Setup!A6&" — "&Setup!B6 -> English — Sir Sajjad Ali Birhmani | G14: =Setup!A7&" — "&Setup!B7 -> Computer — Sir Nazeer Ahmed Jamali | K14: =Setup!A8&" — "&Setup!B8 -> Biology — Sir Azhar Ali Chandio | O14: =Setup!A9&" — "&Setup!B9 -> Math — Sir M. Faheem | S14: =Setup!A10&" — "&Setup!B10 -> Kids Coaching (Class 1) — Miss Farzana | W14: =Setup!A11&" — "&Setup!B11 -> Kids Coaching (Class 2) — Miss Fozia | AA14: ALL SUBJECTS
A15: Serial No | B15: Student Name | C15: Previous Due | D15: Monthly Fee | E15: Paid | F15: Balance | G15: Previous Due | H15: Monthly Fee | I15: Paid | J15: Balance | K15: Previous Due | L15: Monthly Fee | M15: Paid | N15: Balance | O15: Previous Due | P15: Monthly Fee | Q15: Paid | R15: Balance | S15: Previous Due | T15: Monthly Fee | U15: Paid | V15: Balance | W15: Previous Due | X15: Monthly Fee | Y15: Paid | Z15: Balance | AA15: Total Paid | AB15: Total Due Now | AC15: Status
A16: 1 | B16: =IF(Students!B5="","",Students!B5) -> Ali (example) | C16: ='Nov 2026'!F16 -> 0 | D16: =IF(B16="",0,N(Students!E5)) -> 0 | F16: =N(C16)+N(D16)-N(E16) -> 0 | G16: ='Nov 2026'!J16 -> 2000 | H16: =IF(B16="",0,N(Students!F5)) -> 2000 | J16: =N(G16)+N(H16)-N(I16) -> 4000 | K16: ='Nov 2026'!N16 -> 0 | L16: =IF(B16="",0,N(Students!G5)) -> 0 | N16: =N(K16)+N(L16)-N(M16) -> 0 | O16: ='Nov 2026'!R16 -> 2000 | P16: =IF(B16="",0,N(Students!H5)) -> 1500 | R16: =N(O16)+N(P16)-N(Q16) -> 3500 | S16: ='Nov 2026'!V16 -> 0 | T16: =IF(B16="",0,N(Students!I5)) -> 0 | V16: =N(S16)+N(T16)-N(U16) -> 0 | W16: ='Nov 2026'!Z16 -> 0 | X16: =IF(B16="",0,N(Students!J5)) -> 0 | Z16: =N(W16)+N(X16)-N(Y16) -> 0 | AA16: =N(E16)+N(I16)+N(M16)+N(Q16)+N(U16)+N(Y16) -> 0 | AB16: =F16+J16+N16+R16+V16+Z16 -> 7500 | AC16: =IF(B16="","",IF(AB16<=0,"Clear",IF(AA16>0,"Partial","Due"))) -> Due
A17: 2 | B17: =IF(Students!B6="","",Students!B6) | C17: ='Nov 2026'!F17 -> 0 | D17: =IF(B17="",0,N(Students!E6)) -> 0 | F17: =N(C17)+N(D17)-N(E17) -> 0 | G17: ='Nov 2026'!J17 -> 0 | H17: =IF(B17="",0,N(Students!F6)) -> 0 | J17: =N(G17)+N(H17)-N(I17) -> 0 | K17: ='Nov 2026'!N17 -> 0 | L17: =IF(B17="",0,N(Students!G6)) -> 0 | N17: =N(K17)+N(L17)-N(M17) -> 0 | O17: ='Nov 2026'!R17 -> 0 | P17: =IF(B17="",0,N(Students!H6)) -> 0 | R17: =N(O17)+N(P17)-N(Q17) -> 0 | S17: ='Nov 2026'!V17 -> 0 | T17: =IF(B17="",0,N(Students!I6)) -> 0 | V17: =N(S17)+N(T17)-N(U17) -> 0 | W17: ='Nov 2026'!Z17 -> 0 | X17: =IF(B17="",0,N(Students!J6)) -> 0 | Z17: =N(W17)+N(X17)-N(Y17) -> 0 | AA17: =N(E17)+N(I17)+N(M17)+N(Q17)+N(U17)+N(Y17) -> 0 | AB17: =F17+J17+N17+R17+V17+Z17 -> 0 | AC17: =IF(B17="","",IF(AB17<=0,"Clear",IF(AA17>0,"Partial","Due")))
A18: 3 | B18: =IF(Students!B7="","",Students!B7) | C18: ='Nov 2026'!F18 -> 0 | D18: =IF(B18="",0,N(Students!E7)) -> 0 | F18: =N(C18)+N(D18)-N(E18) -> 0 | G18: ='Nov 2026'!J18 -> 0 | H18: =IF(B18="",0,N(Students!F7)) -> 0 | J18: =N(G18)+N(H18)-N(I18) -> 0 | K18: ='Nov 2026'!N18 -> 0 | L18: =IF(B18="",0,N(Students!G7)) -> 0 | N18: =N(K18)+N(L18)-N(M18) -> 0 | O18: ='Nov 2026'!R18 -> 0 | P18: =IF(B18="",0,N(Students!H7)) -> 0 | R18: =N(O18)+N(P18)-N(Q18) -> 0 | S18: ='Nov 2026'!V18 -> 0 | T18: =IF(B18="",0,N(Students!I7)) -> 0 | V18: =N(S18)+N(T18)-N(U18) -> 0 | W18: ='Nov 2026'!Z18 -> 0 | X18: =IF(B18="",0,N(Students!J7)) -> 0 | Z18: =N(W18)+N(X18)-N(Y18) -> 0 | AA18: =N(E18)+N(I18)+N(M18)+N(Q18)+N(U18)+N(Y18) -> 0 | AB18: =F18+J18+N18+R18+V18+Z18 -> 0 | AC18: =IF(B18="","",IF(AB18<=0,"Clear",IF(AA18>0,"Partial","Due")))
A19: 4 | B19: =IF(Students!B8="","",Students!B8) | C19: ='Nov 2026'!F19 -> 0 | D19: =IF(B19="",0,N(Students!E8)) -> 0 | F19: =N(C19)+N(D19)-N(E19) -> 0 | G19: ='Nov 2026'!J19 -> 0 | H19: =IF(B19="",0,N(Students!F8)) -> 0 | J19: =N(G19)+N(H19)-N(I19) -> 0 | K19: ='Nov 2026'!N19 -> 0 | L19: =IF(B19="",0,N(Students!G8)) -> 0 | N19: =N(K19)+N(L19)-N(M19) -> 0 | O19: ='Nov 2026'!R19 -> 0 | P19: =IF(B19="",0,N(Students!H8)) -> 0 | R19: =N(O19)+N(P19)-N(Q19) -> 0 | S19: ='Nov 2026'!V19 -> 0 | T19: =IF(B19="",0,N(Students!I8)) -> 0 | V19: =N(S19)+N(T19)-N(U19) -> 0 | W19: ='Nov 2026'!Z19 -> 0 | X19: =IF(B19="",0,N(Students!J8)) -> 0 | Z19: =N(W19)+N(X19)-N(Y19) -> 0 | AA19: =N(E19)+N(I19)+N(M19)+N(Q19)+N(U19)+N(Y19) -> 0 | AB19: =F19+J19+N19+R19+V19+Z19 -> 0 | AC19: =IF(B19="","",IF(AB19<=0,"Clear",IF(AA19>0,"Partial","Due")))
A20: 5 | B20: =IF(Students!B9="","",Students!B9) | C20: ='Nov 2026'!F20 -> 0 | D20: =IF(B20="",0,N(Students!E9)) -> 0 | F20: =N(C20)+N(D20)-N(E20) -> 0 | G20: ='Nov 2026'!J20 -> 0 | H20: =IF(B20="",0,N(Students!F9)) -> 0 | J20: =N(G20)+N(H20)-N(I20) -> 0 | K20: ='Nov 2026'!N20 -> 0 | L20: =IF(B20="",0,N(Students!G9)) -> 0 | N20: =N(K20)+N(L20)-N(M20) -> 0 | O20: ='Nov 2026'!R20 -> 0 | P20: =IF(B20="",0,N(Students!H9)) -> 0 | R20: =N(O20)+N(P20)-N(Q20) -> 0 | S20: ='Nov 2026'!V20 -> 0 | T20: =IF(B20="",0,N(Students!I9)) -> 0 | V20: =N(S20)+N(T20)-N(U20) -> 0 | W20: ='Nov 2026'!Z20 -> 0 | X20: =IF(B20="",0,N(Students!J9)) -> 0 | Z20: =N(W20)+N(X20)-N(Y20) -> 0 | AA20: =N(E20)+N(I20)+N(M20)+N(Q20)+N(U20)+N(Y20) -> 0 | AB20: =F20+J20+N20+R20+V20+Z20 -> 0 | AC20: =IF(B20="","",IF(AB20<=0,"Clear",IF(AA20>0,"Partial","Due")))
A21: 6 | B21: =IF(Students!B10="","",Students!B10) | C21: ='Nov 2026'!F21 -> 0 | D21: =IF(B21="",0,N(Students!E10)) -> 0 | F21: =N(C21)+N(D21)-N(E21) -> 0 | G21: ='Nov 2026'!J21 -> 0 | H21: =IF(B21="",0,N(Students!F10)) -> 0 | J21: =N(G21)+N(H21)-N(I21) -> 0 | K21: ='Nov 2026'!N21 -> 0 | L21: =IF(B21="",0,N(Students!G10)) -> 0 | N21: =N(K21)+N(L21)-N(M21) -> 0 | O21: ='Nov 2026'!R21 -> 0 | P21: =IF(B21="",0,N(Students!H10)) -> 0 | R21: =N(O21)+N(P21)-N(Q21) -> 0 | S21: ='Nov 2026'!V21 -> 0 | T21: =IF(B21="",0,N(Students!I10)) -> 0 | V21: =N(S21)+N(T21)-N(U21) -> 0 | W21: ='Nov 2026'!Z21 -> 0 | X21: =IF(B21="",0,N(Students!J10)) -> 0 | Z21: =N(W21)+N(X21)-N(Y21) -> 0 | AA21: =N(E21)+N(I21)+N(M21)+N(Q21)+N(U21)+N(Y21) -> 0 | AB21: =F21+J21+N21+R21+V21+Z21 -> 0 | AC21: =IF(B21="","",IF(AB21<=0,"Clear",IF(AA21>0,"Partial","Due")))
A22: 7 | B22: =IF(Students!B11="","",Students!B11) | C22: ='Nov 2026'!F22 -> 0 | D22: =IF(B22="",0,N(Students!E11)) -> 0 | F22: =N(C22)+N(D22)-N(E22) -> 0 | G22: ='Nov 2026'!J22 -> 0 | H22: =IF(B22="",0,N(Students!F11)) -> 0 | J22: =N(G22)+N(H22)-N(I22) -> 0 | K22: ='Nov 2026'!N22 -> 0 | L22: =IF(B22="",0,N(Students!G11)) -> 0 | N22: =N(K22)+N(L22)-N(M22) -> 0 | O22: ='Nov 2026'!R22 -> 0 | P22: =IF(B22="",0,N(Students!H11)) -> 0 | R22: =N(O22)+N(P22)-N(Q22) -> 0 | S22: ='Nov 2026'!V22 -> 0 | T22: =IF(B22="",0,N(Students!I11)) -> 0 | V22: =N(S22)+N(T22)-N(U22) -> 0 | W22: ='Nov 2026'!Z22 -> 0 | X22: =IF(B22="",0,N(Students!J11)) -> 0 | Z22: =N(W22)+N(X22)-N(Y22) -> 0 | AA22: =N(E22)+N(I22)+N(M22)+N(Q22)+N(U22)+N(Y22) -> 0 | AB22: =F22+J22+N22+R22+V22+Z22 -> 0 | AC22: =IF(B22="","",IF(AB22<=0,"Clear",IF(AA22>0,"Partial","Due")))
A23: 8 | B23: =IF(Students!B12="","",Students!B12) | C23: ='Nov 2026'!F23 -> 0 | D23: =IF(B23="",0,N(Students!E12)) -> 0 | F23: =N(C23)+N(D23)-N(E23) -> 0 | G23: ='Nov 2026'!J23 -> 0 | H23: =IF(B23="",0,N(Students!F12)) -> 0 | J23: =N(G23)+N(H23)-N(I23) -> 0 | K23: ='Nov 2026'!N23 -> 0 | L23: =IF(B23="",0,N(Students!G12)) -> 0 | N23: =N(K23)+N(L23)-N(M23) -> 0 | O23: ='Nov 2026'!R23 -> 0 | P23: =IF(B23="",0,N(Students!H12)) -> 0 | R23: =N(O23)+N(P23)-N(Q23) -> 0 | S23: ='Nov 2026'!V23 -> 0 | T23: =IF(B23="",0,N(Students!I12)) -> 0 | V23: =N(S23)+N(T23)-N(U23) -> 0 | W23: ='Nov 2026'!Z23 -> 0 | X23: =IF(B23="",0,N(Students!J12)) -> 0 | Z23: =N(W23)+N(X23)-N(Y23) -> 0 | AA23: =N(E23)+N(I23)+N(M23)+N(Q23)+N(U23)+N(Y23) -> 0 | AB23: =F23+J23+N23+R23+V23+Z23 -> 0 | AC23: =IF(B23="","",IF(AB23<=0,"Clear",IF(AA23>0,"Partial","Due")))
A24: 9 | B24: =IF(Students!B13="","",Students!B13) | C24: ='Nov 2026'!F24 -> 0 | D24: =IF(B24="",0,N(Students!E13)) -> 0 | F24: =N(C24)+N(D24)-N(E24) -> 0 | G24: ='Nov 2026'!J24 -> 0 | H24: =IF(B24="",0,N(Students!F13)) -> 0 | J24: =N(G24)+N(H24)-N(I24) -> 0 | K24: ='Nov 2026'!N24 -> 0 | L24: =IF(B24="",0,N(Students!G13)) -> 0 | N24: =N(K24)+N(L24)-N(M24) -> 0 | O24: ='Nov 2026'!R24 -> 0 | P24: =IF(B24="",0,N(Students!H13)) -> 0 | R24: =N(O24)+N(P24)-N(Q24) -> 0 | S24: ='Nov 2026'!V24 -> 0 | T24: =IF(B24="",0,N(Students!I13)) -> 0 | V24: =N(S24)+N(T24)-N(U24) -> 0 | W24: ='Nov 2026'!Z24 -> 0 | X24: =IF(B24="",0,N(Students!J13)) -> 0 | Z24: =N(W24)+N(X24)-N(Y24) -> 0 | AA24: =N(E24)+N(I24)+N(M24)+N(Q24)+N(U24)+N(Y24) -> 0 | AB24: =F24+J24+N24+R24+V24+Z24 -> 0 | AC24: =IF(B24="","",IF(AB24<=0,"Clear",IF(AA24>0,"Partial","Due")))
A25: 10 | B25: =IF(Students!B14="","",Students!B14) | C25: ='Nov 2026'!F25 -> 0 | D25: =IF(B25="",0,N(Students!E14)) -> 0 | F25: =N(C25)+N(D25)-N(E25) -> 0 | G25: ='Nov 2026'!J25 -> 0 | H25: =IF(B25="",0,N(Students!F14)) -> 0 | J25: =N(G25)+N(H25)-N(I25) -> 0 | K25: ='Nov 2026'!N25 -> 0 | L25: =IF(B25="",0,N(Students!G14)) -> 0 | N25: =N(K25)+N(L25)-N(M25) -> 0 | O25: ='Nov 2026'!R25 -> 0 | P25: =IF(B25="",0,N(Students!H14)) -> 0 | R25: =N(O25)+N(P25)-N(Q25) -> 0 | S25: ='Nov 2026'!V25 -> 0 | T25: =IF(B25="",0,N(Students!I14)) -> 0 | V25: =N(S25)+N(T25)-N(U25) -> 0 | W25: ='Nov 2026'!Z25 -> 0 | X25: =IF(B25="",0,N(Students!J14)) -> 0 | Z25: =N(W25)+N(X25)-N(Y25) -> 0 | AA25: =N(E25)+N(I25)+N(M25)+N(Q25)+N(U25)+N(Y25) -> 0 | AB25: =F25+J25+N25+R25+V25+Z25 -> 0 | AC25: =IF(B25="","",IF(AB25<=0,"Clear",IF(AA25>0,"Partial","Due")))
A26: 11 | B26: =IF(Students!B15="","",Students!B15) | C26: ='Nov 2026'!F26 -> 0 | D26: =IF(B26="",0,N(Students!E15)) -> 0 | F26: =N(C26)+N(D26)-N(E26) -> 0 | G26: ='Nov 2026'!J26 -> 0 | H26: =IF(B26="",0,N(Students!F15)) -> 0 | J26: =N(G26)+N(H26)-N(I26) -> 0 | K26: ='Nov 2026'!N26 -> 0 | L26: =IF(B26="",0,N(Students!G15)) -> 0 | N26: =N(K26)+N(L26)-N(M26) -> 0 | O26: ='Nov 2026'!R26 -> 0 | P26: =IF(B26="",0,N(Students!H15)) -> 0 | R26: =N(O26)+N(P26)-N(Q26) -> 0 | S26: ='Nov 2026'!V26 -> 0 | T26: =IF(B26="",0,N(Students!I15)) -> 0 | V26: =N(S26)+N(T26)-N(U26) -> 0 | W26: ='Nov 2026'!Z26 -> 0 | X26: =IF(B26="",0,N(Students!J15)) -> 0 | Z26: =N(W26)+N(X26)-N(Y26) -> 0 | AA26: =N(E26)+N(I26)+N(M26)+N(Q26)+N(U26)+N(Y26) -> 0 | AB26: =F26+J26+N26+R26+V26+Z26 -> 0 | AC26: =IF(B26="","",IF(AB26<=0,"Clear",IF(AA26>0,"Partial","Due")))
A27: 12 | B27: =IF(Students!B16="","",Students!B16) | C27: ='Nov 2026'!F27 -> 0 | D27: =IF(B27="",0,N(Students!E16)) -> 0 | F27: =N(C27)+N(D27)-N(E27) -> 0 | G27: ='Nov 2026'!J27 -> 0 | H27: =IF(B27="",0,N(Students!F16)) -> 0 | J27: =N(G27)+N(H27)-N(I27) -> 0 | K27: ='Nov 2026'!N27 -> 0 | L27: =IF(B27="",0,N(Students!G16)) -> 0 | N27: =N(K27)+N(L27)-N(M27) -> 0 | O27: ='Nov 2026'!R27 -> 0 | P27: =IF(B27="",0,N(Students!H16)) -> 0 | R27: =N(O27)+N(P27)-N(Q27) -> 0 | S27: ='Nov 2026'!V27 -> 0 | T27: =IF(B27="",0,N(Students!I16)) -> 0 | V27: =N(S27)+N(T27)-N(U27) -> 0 | W27: ='Nov 2026'!Z27 -> 0 | X27: =IF(B27="",0,N(Students!J16)) -> 0 | Z27: =N(W27)+N(X27)-N(Y27) -> 0 | AA27: =N(E27)+N(I27)+N(M27)+N(Q27)+N(U27)+N(Y27) -> 0 | AB27: =F27+J27+N27+R27+V27+Z27 -> 0 | AC27: =IF(B27="","",IF(AB27<=0,"Clear",IF(AA27>0,"Partial","Due")))
... A165: 150 | B165: =IF(Students!B154="","",Students!B154) | C165: ='Nov 2026'!F165 -> 0 | D165: =IF(B165="",0,N(Students!E154)) -> 0 | F165: =N(C165)+N(D165)-N(E165) -> 0 | G165: ='Nov 2026'!J165 -> 0 | H165: =IF(B165="",0,N(Students!F154)) -> 0 | J165: =N(G165)+N(H165)-N(I165) -> 0 | K165: ='Nov 2026'!N165 -> 0 | L165: =IF(B165="",0,N(Students!G154)) -> 0 | N165: =N(K165)+N(L165)-N(M165) -> 0 | O165: ='Nov 2026'!R165 -> 0 | P165: =IF(B165="",0,N(Students!H154)) -> 0 | R165: =N(O165)+N(P165)-N(Q165) -> 0 | S165: ='Nov 2026'!V165 -> 0 | T165: =IF(B165="",0,N(Students!I154)) -> 0 | V165: =N(S165)+N(T165)-N(U165) -> 0 | W165: ='Nov 2026'!Z165 -> 0 | X165: =IF(B165="",0,N(Students!J154)) -> 0 | Z165: =N(W165)+N(X165)-N(Y165) -> 0 | AA165: =N(E165)+N(I165)+N(M165)+N(Q165)+N(U165)+N(Y165) -> 0 | AB165: =F165+J165+N165+R165+V165+Z165 -> 0 | AC165: =IF(B165="","",IF(AB165<=0,"Clear",IF(AA165>0,"Partial","Due")))
A166: TOTAL | C166: =SUM(C16:C165) -> 0 | D166: =SUM(D16:D165) -> 0 | E166: =SUM(E16:E165) -> 0 | F166: =SUM(F16:F165) -> 0 | G166: =SUM(G16:G165) -> 2000 | H166: =SUM(H16:H165) -> 2000 | I166: =SUM(I16:I165) -> 0 | J166: =SUM(J16:J165) -> 4000 | ... AB166: =SUM(AB16:AB165) -> 7500

Sheet Jan 2027
A1: =UPPER(Setup!B3) -> FUTURE TALENT ACADEMY JAMSHORO
A2: Monthly Fee Register & Profit • January 2027
B4: SUBJECT-WISE SUMMARY (Teacher & Academy) | K4: ADMINISTRATION — ACADEMY PROFIT
B5: Subject | C5: Teacher | E5: Fee Charged | F5: Collected | G5: Teacher Share | H5: Academy Share | I5: Pending | K5: Academy Share of Fees | N5: =H12 -> 0 | P5: FEES COLLECTED | T5: TEACHERS' SHARE | X5: PENDING FEES
B6: =Setup!A6 -> English | C6: =Setup!B6 -> Sir Sajjad Ali Birhmani | E6: =D166 -> 0 | F6: =E166 -> 0 | G6: =F6*Setup!C6 -> 0 | H6: =F6-G6 -> 0 | I6: =F166 -> 0 | K6: + Other Income | N6: =SUMIFS(Administration!$G$5:$G$304,Administration!$C$5:$C$304,"Jan 2027",Administration!$D$5:$D$304,"Other Income") -> 0 | P6: =F12 -> 0 | T6: =G12 -> 0 | X6: =I12 -> 11000
B7: =Setup!A7 -> Computer | C7: =Setup!B7 -> Sir Nazeer Ahmed Jamali | E7: =H166 -> 2000 | F7: =I166 -> 0 | G7: =F7*Setup!C7 -> 0 | H7: =F7-G7 -> 0 | I7: =J166 -> 6000 | K7: − Expenses | N7: =SUMIFS(Administration!$G$5:$G$304,Administration!$C$5:$C$304,"Jan 2027",Administration!$D$5:$D$304,"Expense") -> 0
B8: =Setup!A8 -> Biology | C8: =Setup!B8 -> Sir Azhar Ali Chandio | E8: =L166 -> 0 | F8: =M166 -> 0 | G8: =F8*Setup!C8 -> 0 | H8: =F8-G8 -> 0 | I8: =N166 -> 0 | K8: − Investment | N8: =SUMIFS(Administration!$G$5:$G$304,Administration!$C$5:$C$304,"Jan 2027",Administration!$D$5:$D$304,"Investment") -> 0
B9: =Setup!A9 -> Math | C9: =Setup!B9 -> Sir M. Faheem | E9: =P166 -> 1500 | F9: =Q166 -> 0 | G9: =F9*Setup!C9 -> 0 | H9: =F9-G9 -> 0 | I9: =R166 -> 5000 | P9: =COUNTIF(AC16:AC165,"Clear")&" students fully paid • "&(COUNTIF(AC16:AC165,"Due")+COUNTIF(AC16:AC165,"Partial"))&" students with dues" -> 0 students fully paid • 1 students with dues
B10: =Setup!A10 -> Kids Coaching (Class 1) | C10: =Setup!B10 -> Miss Farzana | E10: =T166 -> 0 | F10: =U166 -> 0 | G10: =F10*Setup!C10 -> 0 | H10: =F10-G10 -> 0 | I10: =V166 -> 0 | K10: NET PROFIT | N10: =N5+N6-N7-N8 -> 0
B11: =Setup!A11 -> Kids Coaching (Class 2) | C11: =Setup!B11 -> Miss Fozia | E11: =X166 -> 0 | F11: =Y166 -> 0 | G11: =F11*Setup!C11 -> 0 | H11: =F11-G11 -> 0 | I11: =Z166 -> 0 | K11: Expenses & investment come from the Administration sheet.
B12: TOTAL | E12: =SUM(E6:E11) -> 3500 | F12: =SUM(F6:F11) -> 0 | G12: =SUM(G6:G11) -> 0 | H12: =SUM(H6:H11) -> 0 | I12: =SUM(I6:I11) -> 11000
A14: STUDENT | C14: =Setup!A6&" — "&Setup!B6 -> English — Sir Sajjad Ali Birhmani | G14: =Setup!A7&" — "&Setup!B7 -> Computer — Sir Nazeer Ahmed Jamali | K14: =Setup!A8&" — "&Setup!B8 -> Biology — Sir Azhar Ali Chandio | O14: =Setup!A9&" — "&Setup!B9 -> Math — Sir M. Faheem | S14: =Setup!A10&" — "&Setup!B10 -> Kids Coaching (Class 1) — Miss Farzana | W14: =Setup!A11&" — "&Setup!B11 -> Kids Coaching (Class 2) — Miss Fozia | AA14: ALL SUBJECTS
A15: Serial No | B15: Student Name | C15: Previous Due | D15: Monthly Fee | E15: Paid | F15: Balance | G15: Previous Due | H15: Monthly Fee | I15: Paid | J15: Balance | K15: Previous Due | L15: Monthly Fee | M15: Paid | N15: Balance | O15: Previous Due | P15: Monthly Fee | Q15: Paid | R15: Balance | S15: Previous Due | T15: Monthly Fee | U15: Paid | V15: Balance | W15: Previous Due | X15: Monthly Fee | Y15: Paid | Z15: Balance | AA15: Total Paid | AB15: Total Due Now | AC15: Status
A16: 1 | B16: =IF(Students!B5="","",Students!B5) -> Ali (example) | C16: ='Dec 2026'!F16 -> 0 | D16: =IF(B16="",0,N(Students!E5)) -> 0 | F16: =N(C16)+N(D16)-N(E16) -> 0 | G16: ='Dec 2026'!J16 -> 4000 | H16: =IF(B16="",0,N(Students!F5)) -> 2000 | J16: =N(G16)+N(H16)-N(I16) -> 6000 | K16: ='Dec 2026'!N16 -> 0 | L16: =IF(B16="",0,N(Students!G5)) -> 0 | N16: =N(K16)+N(L16)-N(M16) -> 0 | O16: ='Dec 2026'!R16 -> 3500 | P16: =IF(B16="",0,N(Students!H5)) -> 1500 | R16: =N(O16)+N(P16)-N(Q16) -> 5000 | S16: ='Dec 2026'!V16 -> 0 | T16: =IF(B16="",0,N(Students!I5)) -> 0 | V16: =N(S16)+N(T16)-N(U16) -> 0 | W16: ='Dec 2026'!Z16 -> 0 | X16: =IF(B16="",0,N(Students!J5)) -> 0 | Z16: =N(W16)+N(X16)-N(Y16) -> 0 | AA16: =N(E16)+N(I16)+N(M16)+N(Q16)+N(U16)+N(Y16) -> 0 | AB16: =F16+J16+N16+R16+V16+Z16 -> 11000 | AC16: =IF(B16="","",IF(AB16<=0,"Clear",IF(AA16>0,"Partial","Due"))) -> Due
A17: 2 | B17: =IF(Students!B6="","",Students!B6) | C17: ='Dec 2026'!F17 -> 0 | D17: =IF(B17="",0,N(Students!E6)) -> 0 | F17: =N(C17)+N(D17)-N(E17) -> 0 | G17: ='Dec 2026'!J17 -> 0 | H17: =IF(B17="",0,N(Students!F6)) -> 0 | J17: =N(G17)+N(H17)-N(I17) -> 0 | K17: ='Dec 2026'!N17 -> 0 | L17: =IF(B17="",0,N(Students!G6)) -> 0 | N17: =N(K17)+N(L17)-N(M17) -> 0 | O17: ='Dec 2026'!R17 -> 0 | P17: =IF(B17="",0,N(Students!H6)) -> 0 | R17: =N(O17)+N(P17)-N(Q17) -> 0 | S17: ='Dec 2026'!V17 -> 0 | T17: =IF(B17="",0,N(Students!I6)) -> 0 | V17: =N(S17)+N(T17)-N(U17) -> 0 | W17: ='Dec 2026'!Z17 -> 0 | X17: =IF(B17="",0,N(Students!J6)) -> 0 | Z17: =N(W17)+N(X17)-N(Y17) -> 0 | AA17: =N(E17)+N(I17)+N(M17)+N(Q17)+N(U17)+N(Y17) -> 0 | AB17: =F17+J17+N17+R17+V17+Z17 -> 0 | AC17: =IF(B17="","",IF(AB17<=0,"Clear",IF(AA17>0,"Partial","Due")))
A18: 3 | B18: =IF(Students!B7="","",Students!B7) | C18: ='Dec 2026'!F18 -> 0 | D18: =IF(B18="",0,N(Students!E7)) -> 0 | F18: =N(C18)+N(D18)-N(E18) -> 0 | G18: ='Dec 2026'!J18 -> 0 | H18: =IF(B18="",0,N(Students!F7)) -> 0 | J18: =N(G18)+N(H18)-N(I18) -> 0 | K18: ='Dec 2026'!N18 -> 0 | L18: =IF(B18="",0,N(Students!G7)) -> 0 | N18: =N(K18)+N(L18)-N(M18) -> 0 | O18: ='Dec 2026'!R18 -> 0 | P18: =IF(B18="",0,N(Students!H7)) -> 0 | R18: =N(O18)+N(P18)-N(Q18) -> 0 | S18: ='Dec 2026'!V18 -> 0 | T18: =IF(B18="",0,N(Students!I7)) -> 0 | V18: =N(S18)+N(T18)-N(U18) -> 0 | W18: ='Dec 2026'!Z18 -> 0 | X18: =IF(B18="",0,N(Students!J7)) -> 0 | Z18: =N(W18)+N(X18)-N(Y18) -> 0 | AA18: =N(E18)+N(I18)+N(M18)+N(Q18)+N(U18)+N(Y18) -> 0 | AB18: =F18+J18+N18+R18+V18+Z18 -> 0 | AC18: =IF(B18="","",IF(AB18<=0,"Clear",IF(AA18>0,"Partial","Due")))
