Workbook

Sheet Students
A1: FUTURE TALENT ACADEMY JAMSHORO — STUDENT LISTS
A2: Write the names once here. Every month's marksheet picks them up automatically. Keep the order the same; add new students at the bottom.
A4: ENGLISH CLASS — Sir Sajjad Ali Birhmani | E4: COMPUTER CLASS — Sir Nazeer Ahmed Jamali
A5: S.No | B5: Student Name | C5: Father Name | E5: S.No | F5: Student Name | G5: Father Name
A6: 1 | B6: Ali Ahmed (example) | C6: Ahmed Khan | E6: 1 | F6: Sara Bibi (example) | G6: Abdul Rehman
A7: 2 | E7: 2
A8: 3 | E8: 3
A9: 4 | E9: 4
A10: 5 | E10: 5
A11: 6 | E11: 6
A12: 7 | E12: 7
A13: 8 | E13: 8
A14: 9 | E14: 9
A15: 10 | E15: 10
A16: 11 | E16: 11
A17: 12 | E17: 12
A18: 13 | E18: 13
... A55: 50 | E55: 50

Sheet Award Summary
A1: 🏆 MONTHLY AWARD WINNERS — TOP 3
A2: Fills in automatically from each month's marksheet.
A4: Month | B4: Class | C4: 🥇 1st | D4: 🥈 2nd | E4: 🥉 3rd
A5: October 2026 | B5: English | C5: =MID(IF('Eng Oct 2026'!A8=1,", "&'Eng Oct 2026'!B8,"")&IF('Eng Oct 2026'!A9=1,", "&'Eng Oct 2026'!B9,"")&IF('Eng Oct 2026'!A10=1,", "&'Eng Oct 2026'!B10,"")&IF('Eng Oct 2026'!A11=1,", "&'Eng Oct 2026'!B11,""),3,999) | D5: =MID(IF('Eng Oct 2026'!A8=2,", "&'Eng Oct 2026'!B8,"")&IF('Eng Oct 2026'!A9=2,", "&'Eng Oct 2026'!B9,"")&IF('Eng Oct 2026'!A10=2,", "&'Eng Oct 2026'!B10,"")&IF('Eng Oct 2026'!A11=2,", "&'Eng Oct 2026'!B11,""),3,999) | E5: =MID(IF('Eng Oct 2026'!A8=3,", "&'Eng Oct 2026'!B8,"")&IF('Eng Oct 2026'!A9=3,", "&'Eng Oct 2026'!B9,"")&IF('Eng Oct 2026'!A10=3,", "&'Eng Oct 2026'!B10,"")&IF('Eng Oct 2026'!A11=3,", "&'Eng Oct 2026'!B11,""),3,999)
A6: October 2026 | B6: Computer | C6: =MID(IF('Com Oct 2026'!A8=1,", "&'Com Oct 2026'!B8,"")&IF('Com Oct 2026'!A9=1,", "&'Com Oct 2026'!B9,"")&IF('Com Oct 2026'!A10=1,", "&'Com Oct 2026'!B10,"")&IF('Com Oct 2026'!A11=1,", "&'Com Oct 2026'!B11,""),3,999) | D6: =MID(IF('Com Oct 2026'!A8=2,", "&'Com Oct 2026'!B8,"")&IF('Com Oct 2026'!A9=2,", "&'Com Oct 2026'!B9,"")&IF('Com Oct 2026'!A10=2,", "&'Com Oct 2026'!B10,"")&IF('Com Oct 2026'!A11=2,", "&'Com Oct 2026'!B11,""),3,999) | E6: =MID(IF('Com Oct 2026'!A8=3,", "&'Com Oct 2026'!B8,"")&IF('Com Oct 2026'!A9=3,", "&'Com Oct 2026'!B9,"")&IF('Com Oct 2026'!A10=3,", "&'Com Oct 2026'!B10,"")&IF('Com Oct 2026'!A11=3,", "&'Com Oct 2026'!B11,""),3,999)
A7: November 2026 | B7: English | C7: =MID(IF('Eng Nov 2026'!A8=1,", "&'Eng Nov 2026'!B8,"")&IF('Eng Nov 2026'!A9=1,", "&'Eng Nov 2026'!B9,"")&IF('Eng Nov 2026'!A10=1,", "&'Eng Nov 2026'!B10,"")&IF('Eng Nov 2026'!A11=1,", "&'Eng Nov 2026'!B11,""),3,999) | D7: =MID(IF('Eng Nov 2026'!A8=2,", "&'Eng Nov 2026'!B8,"")&IF('Eng Nov 2026'!A9=2,", "&'Eng Nov 2026'!B9,"")&IF('Eng Nov 2026'!A10=2,", "&'Eng Nov 2026'!B10,"")&IF('Eng Nov 2026'!A11=2,", "&'Eng Nov 2026'!B11,""),3,999) | E7: =MID(IF('Eng Nov 2026'!A8=3,", "&'Eng Nov 2026'!B8,"")&IF('Eng Nov 2026'!A9=3,", "&'Eng Nov 2026'!B9,"")&IF('Eng Nov 2026'!A10=3,", "&'Eng Nov 2026'!B10,"")&IF('Eng Nov 2026'!A11=3,", "&'Eng Nov 2026'!B11,""),3,999)
A8: November 2026 | B8: Computer | C8: =MID(IF('Com Nov 2026'!A8=1,", "&'Com Nov 2026'!B8,"")&IF('Com Nov 2026'!A9=1,", "&'Com Nov 2026'!B9,"")&IF('Com Nov 2026'!A10=1,", "&'Com Nov 2026'!B10,"")&IF('Com Nov 2026'!A11=1,", "&'Com Nov 2026'!B11,""),3,999) | D8: =MID(IF('Com Nov 2026'!A8=2,", "&'Com Nov 2026'!B8,"")&IF('Com Nov 2026'!A9=2,", "&'Com Nov 2026'!B9,"")&IF('Com Nov 2026'!A10=2,", "&'Com Nov 2026'!B10,"")&IF('Com Nov 2026'!A11=2,", "&'Com Nov 2026'!B11,""),3,999) | E8: =MID(IF('Com Nov 2026'!A8=3,", "&'Com Nov 2026'!B8,"")&IF('Com Nov 2026'!A9=3,", "&'Com Nov 2026'!B9,"")&IF('Com Nov 2026'!A10=3,", "&'Com Nov 2026'!B10,"")&IF('Com Nov 2026'!A11=3,", "&'Com Nov 2026'!B11,""),3,999)
A9: December 2026 | B9: English | C9: =MID(IF('Eng Dec 2026'!A8=1,", "&'Eng Dec 2026'!B8,"")&IF('Eng Dec 2026'!A9=1,", "&'Eng Dec 2026'!B9,"")&IF('Eng Dec 2026'!A10=1,", "&'Eng Dec 2026'!B10,"")&IF('Eng Dec 2026'!A11=1,", "&'Eng Dec 2026'!B11,""),3,999) | D9: =MID(IF('Eng Dec 2026'!A8=2,", "&'Eng Dec 2026'!B8,"")&IF('Eng Dec 2026'!A9=2,", "&'Eng Dec 2026'!B9,"")&IF('Eng Dec 2026'!A10=2,", "&'Eng Dec 2026'!B10,"")&IF('Eng Dec 2026'!A11=2,", "&'Eng Dec 2026'!B11,""),3,999) | E9: =MID(IF('Eng Dec 2026'!A8=3,", "&'Eng Dec 2026'!B8,"")&IF('Eng Dec 2026'!A9=3,", "&'Eng Dec 2026'!B9,"")&IF('Eng Dec 2026'!A10=3,", "&'Eng Dec 2026'!B10,"")&IF('Eng Dec 2026'!A11=3,", "&'Eng Dec 2026'!B11,""),3,999)
A10: December 2026 | B10: Computer | C10: =MID(IF('Com Dec 2026'!A8=1,", "&'Com Dec 2026'!B8,"")&IF('Com Dec 2026'!A9=1,", "&'Com Dec 2026'!B9,"")&IF('Com Dec 2026'!A10=1,", "&'Com Dec 2026'!B10,"")&IF('Com Dec 2026'!A11=1,", "&'Com Dec 2026'!B11,""),3,999) | D10: =MID(IF('Com Dec 2026'!A8=2,", "&'Com Dec 2026'!B8,"")&IF('Com Dec 2026'!A9=2,", "&'Com Dec 2026'!B9,"")&IF('Com Dec 2026'!A10=2,", "&'Com Dec 2026'!B10,"")&IF('Com Dec 2026'!A11=2,", "&'Com Dec 2026'!B11,""),3,999) | E10: =MID(IF('Com Dec 2026'!A8=3,", "&'Com Dec 2026'!B8,"")&IF('Com Dec 2026'!A9=3,", "&'Com Dec 2026'!B9,"")&IF('Com Dec 2026'!A10=3,", "&'Com Dec 2026'!B10,"")&IF('Com Dec 2026'!A11=3,", "&'Com Dec 2026'!B11,""),3,999)
A11: January 2027 | B11: English | C11: =MID(IF('Eng Jan 2027'!A8=1,", "&'Eng Jan 2027'!B8,"")&IF('Eng Jan 2027'!A9=1,", "&'Eng Jan 2027'!B9,"")&IF('Eng Jan 2027'!A10=1,", "&'Eng Jan 2027'!B10,"")&IF('Eng Jan 2027'!A11=1,", "&'Eng Jan 2027'!B11,""),3,999) | D11: =MID(IF('Eng Jan 2027'!A8=2,", "&'Eng Jan 2027'!B8,"")&IF('Eng Jan 2027'!A9=2,", "&'Eng Jan 2027'!B9,"")&IF('Eng Jan 2027'!A10=2,", "&'Eng Jan 2027'!B10,"")&IF('Eng Jan 2027'!A11=2,", "&'Eng Jan 2027'!B11,""),3,999) | E11: =MID(IF('Eng Jan 2027'!A8=3,", "&'Eng Jan 2027'!B8,"")&IF('Eng Jan 2027'!A9=3,", "&'Eng Jan 2027'!B9,"")&IF('Eng Jan 2027'!A10=3,", "&'Eng Jan 2027'!B10,"")&IF('Eng Jan 2027'!A11=3,", "&'Eng Jan 2027'!B11,""),3,999)
A12: January 2027 | B12: Computer | C12: =MID(IF('Com Jan 2027'!A8=1,", "&'Com Jan 2027'!B8,"")&IF('Com Jan 2027'!A9=1,", "&'Com Jan 2027'!B9,"")&IF('Com Jan 2027'!A10=1,", "&'Com Jan 2027'!B10,"")&IF('Com Jan 2027'!A11=1,", "&'Com Jan 2027'!B11,""),3,999) | D12: =MID(IF('Com Jan 2027'!A8=2,", "&'Com Jan 2027'!B8,"")&IF('Com Jan 2027'!A9=2,", "&'Com Jan 2027'!B9,"")&IF('Com Jan 2027'!A10=2,", "&'Com Jan 2027'!B10,"")&IF('Com Jan 2027'!A11=2,", "&'Com Jan 2027'!B11,""),3,999) | E12: =MID(IF('Com Jan 2027'!A8=3,", "&'Com Jan 2027'!B8,"")&IF('Com Jan 2027'!A9=3,", "&'Com Jan 2027'!B9,"")&IF('Com Jan 2027'!A10=3,", "&'Com Jan 2027'!B10,"")&IF('Com Jan 2027'!A11=3,", "&'Com Jan 2027'!B11,""),3,999)
A13: February 2027 | B13: English | C13: =MID(IF('Eng Feb 2027'!A8=1,", "&'Eng Feb 2027'!B8,"")&IF('Eng Feb 2027'!A9=1,", "&'Eng Feb 2027'!B9,"")&IF('Eng Feb 2027'!A10=1,", "&'Eng Feb 2027'!B10,"")&IF('Eng Feb 2027'!A11=1,", "&'Eng Feb 2027'!B11,""),3,999) | D13: =MID(IF('Eng Feb 2027'!A8=2,", "&'Eng Feb 2027'!B8,"")&IF('Eng Feb 2027'!A9=2,", "&'Eng Feb 2027'!B9,"")&IF('Eng Feb 2027'!A10=2,", "&'Eng Feb 2027'!B10,"")&IF('Eng Feb 2027'!A11=2,", "&'Eng Feb 2027'!B11,""),3,999) | E13: =MID(IF('Eng Feb 2027'!A8=3,", "&'Eng Feb 2027'!B8,"")&IF('Eng Feb 2027'!A9=3,", "&'Eng Feb 2027'!B9,"")&IF('Eng Feb 2027'!A10=3,", "&'Eng Feb 2027'!B10,"")&IF('Eng Feb 2027'!A11=3,", "&'Eng Feb 2027'!B11,""),3,999)
A14: February 2027 | B14: Computer | C14: =MID(IF('Com Feb 2027'!A8=1,", "&'Com Feb 2027'!B8,"")&IF('Com Feb 2027'!A9=1,", "&'Com Feb 2027'!B9,"")&IF('Com Feb 2027'!A10=1,", "&'Com Feb 2027'!B10,"")&IF('Com Feb 2027'!A11=1,", "&'Com Feb 2027'!B11,""),3,999) | D14: =MID(IF('Com Feb 2027'!A8=2,", "&'Com Feb 2027'!B8,"")&IF('Com Feb 2027'!A9=2,", "&'Com Feb 2027'!B9,"")&IF('Com Feb 2027'!A10=2,", "&'Com Feb 2027'!B10,"")&IF('Com Feb 2027'!A11=2,", "&'Com Feb 2027'!B11,""),3,999) | E14: =MID(IF('Com Feb 2027'!A8=3,", "&'Com Feb 2027'!B8,"")&IF('Com Feb 2027'!A9=3,", "&'Com Feb 2027'!B9,"")&IF('Com Feb 2027'!A10=3,", "&'Com Feb 2027'!B10,"")&IF('Com Feb 2027'!A11=3,", "&'Com Feb 2027'!B11,""),3,999)
A15: March 2027 | B15: English | C15: =MID(IF('Eng Mar 2027'!A8=1,", "&'Eng Mar 2027'!B8,"")&IF('Eng Mar 2027'!A9=1,", "&'Eng Mar 2027'!B9,"")&IF('Eng Mar 2027'!A10=1,", "&'Eng Mar 2027'!B10,"")&IF('Eng Mar 2027'!A11=1,", "&'Eng Mar 2027'!B11,""),3,999) | D15: =MID(IF('Eng Mar 2027'!A8=2,", "&'Eng Mar 2027'!B8,"")&IF('Eng Mar 2027'!A9=2,", "&'Eng Mar 2027'!B9,"")&IF('Eng Mar 2027'!A10=2,", "&'Eng Mar 2027'!B10,"")&IF('Eng Mar 2027'!A11=2,", "&'Eng Mar 2027'!B11,""),3,999) | E15: =MID(IF('Eng Mar 2027'!A8=3,", "&'Eng Mar 2027'!B8,"")&IF('Eng Mar 2027'!A9=3,", "&'Eng Mar 2027'!B9,"")&IF('Eng Mar 2027'!A10=3,", "&'Eng Mar 2027'!B10,"")&IF('Eng Mar 2027'!A11=3,", "&'Eng Mar 2027'!B11,""),3,999)
A16: March 2027 | B16: Computer | C16: =MID(IF('Com Mar 2027'!A8=1,", "&'Com Mar 2027'!B8,"")&IF('Com Mar 2027'!A9=1,", "&'Com Mar 2027'!B9,"")&IF('Com Mar 2027'!A10=1,", "&'Com Mar 2027'!B10,"")&IF('Com Mar 2027'!A11=1,", "&'Com Mar 2027'!B11,""),3,999) | D16: =MID(IF('Com Mar 2027'!A8=2,", "&'Com Mar 2027'!B8,"")&IF('Com Mar 2027'!A9=2,", "&'Com Mar 2027'!B9,"")&IF('Com Mar 2027'!A10=2,", "&'Com Mar 2027'!B10,"")&IF('Com Mar 2027'!A11=2,", "&'Com Mar 2027'!B11,""),3,999) | E16: =MID(IF('Com Mar 2027'!A8=3,", "&'Com Mar 2027'!B8,"")&IF('Com Mar 2027'!A9=3,", "&'Com Mar 2027'!B9,"")&IF('Com Mar 2027'!A10=3,", "&'Com Mar 2027'!B10,"")&IF('Com Mar 2027'!A11=3,", "&'Com Mar 2027'!B11,""),3,999)
A17: April 2027 | B17: English | C17: =MID(IF('Eng Apr 2027'!A8=1,", "&'Eng Apr 2027'!B8,"")&IF('Eng Apr 2027'!A9=1,", "&'Eng Apr 2027'!B9,"")&IF('Eng Apr 2027'!A10=1,", "&'Eng Apr 2027'!B10,"")&IF('Eng Apr 2027'!A11=1,", "&'Eng Apr 2027'!B11,""),3,999) | D17: =MID(IF('Eng Apr 2027'!A8=2,", "&'Eng Apr 2027'!B8,"")&IF('Eng Apr 2027'!A9=2,", "&'Eng Apr 2027'!B9,"")&IF('Eng Apr 2027'!A10=2,", "&'Eng Apr 2027'!B10,"")&IF('Eng Apr 2027'!A11=2,", "&'Eng Apr 2027'!B11,""),3,999) | E17: =MID(IF('Eng Apr 2027'!A8=3,", "&'Eng Apr 2027'!B8,"")&IF('Eng Apr 2027'!A9=3,", "&'Eng Apr 2027'!B9,"")&IF('Eng Apr 2027'!A10=3,", "&'Eng Apr 2027'!B10,"")&IF('Eng Apr 2027'!A11=3,", "&'Eng Apr 2027'!B11,""),3,999)
A18: April 2027 | B18: Computer | C18: =MID(IF('Com Apr 2027'!A8=1,", "&'Com Apr 2027'!B8,"")&IF('Com Apr 2027'!A9=1,", "&'Com Apr 2027'!B9,"")&IF('Com Apr 2027'!A10=1,", "&'Com Apr 2027'!B10,"")&IF('Com Apr 2027'!A11=1,", "&'Com Apr 2027'!B11,""),3,999) | D18: =MID(IF('Com Apr 2027'!A8=2,", "&'Com Apr 2027'!B8,"")&IF('Com Apr 2027'!A9=2,", "&'Com Apr 2027'!B9,"")&IF('Com Apr 2027'!A10=2,", "&'Com Apr 2027'!B10,"")&IF('Com Apr 2027'!A11=2,", "&'Com Apr 2027'!B11,""),3,999) | E18: =MID(IF('Com Apr 2027'!A8=3,", "&'Com Apr 2027'!B8,"")&IF('Com Apr 2027'!A9=3,", "&'Com Apr 2027'!B9,"")&IF('Com Apr 2027'!A10=3,", "&'Com Apr 2027'!B10,"")&IF('Com Apr 2027'!A11=3,", "&'Com Apr 2027'!B11,""),3,999)
A19: May 2027 | B19: English | C19: =MID(IF('Eng May 2027'!A8=1,", "&'Eng May 2027'!B8,"")&IF('Eng May 2027'!A9=1,", "&'Eng May 2027'!B9,"")&IF('Eng May 2027'!A10=1,", "&'Eng May 2027'!B10,"")&IF('Eng May 2027'!A11=1,", "&'Eng May 2027'!B11,""),3,999) | D19: =MID(IF('Eng May 2027'!A8=2,", "&'Eng May 2027'!B8,"")&IF('Eng May 2027'!A9=2,", "&'Eng May 2027'!B9,"")&IF('Eng May 2027'!A10=2,", "&'Eng May 2027'!B10,"")&IF('Eng May 2027'!A11=2,", "&'Eng May 2027'!B11,""),3,999) | E19: =MID(IF('Eng May 2027'!A8=3,", "&'Eng May 2027'!B8,"")&IF('Eng May 2027'!A9=3,", "&'Eng May 2027'!B9,"")&IF('Eng May 2027'!A10=3,", "&'Eng May 2027'!B10,"")&IF('Eng May 2027'!A11=3,", "&'Eng May 2027'!B11,""),3,999)
A20: May 2027 | B20: Computer | C20: =MID(IF('Com May 2027'!A8=1,", "&'Com May 2027'!B8,"")&IF('Com May 2027'!A9=1,", "&'Com May 2027'!B9,"")&IF('Com May 2027'!A10=1,", "&'Com May 2027'!B10,"")&IF('Com May 2027'!A11=1,", "&'Com May 2027'!B11,""),3,999) | D20: =MID(IF('Com May 2027'!A8=2,", "&'Com May 2027'!B8,"")&IF('Com May 2027'!A9=2,", "&'Com May 2027'!B9,"")&IF('Com May 2027'!A10=2,", "&'Com May 2027'!B10,"")&IF('Com May 2027'!A11=2,", "&'Com May 2027'!B11,""),3,999) | E20: =MID(IF('Com May 2027'!A8=3,", "&'Com May 2027'!B8,"")&IF('Com May 2027'!A9=3,", "&'Com May 2027'!B9,"")&IF('Com May 2027'!A10=3,", "&'Com May 2027'!B10,"")&IF('Com May 2027'!A11=3,", "&'Com May 2027'!B11,""),3,999)
A21: June 2027 | B21: English | C21: =MID(IF('Eng Jun 2027'!A8=1,", "&'Eng Jun 2027'!B8,"")&IF('Eng Jun 2027'!A9=1,", "&'Eng Jun 2027'!B9,"")&IF('Eng Jun 2027'!A10=1,", "&'Eng Jun 2027'!B10,"")&IF('Eng Jun 2027'!A11=1,", "&'Eng Jun 2027'!B11,""),3,999) | D21: =MID(IF('Eng Jun 2027'!A8=2,", "&'Eng Jun 2027'!B8,"")&IF('Eng Jun 2027'!A9=2,", "&'Eng Jun 2027'!B9,"")&IF('Eng Jun 2027'!A10=2,", "&'Eng Jun 2027'!B10,"")&IF('Eng Jun 2027'!A11=2,", "&'Eng Jun 2027'!B11,""),3,999) | E21: =MID(IF('Eng Jun 2027'!A8=3,", "&'Eng Jun 2027'!B8,"")&IF('Eng Jun 2027'!A9=3,", "&'Eng Jun 2027'!B9,"")&IF('Eng Jun 2027'!A10=3,", "&'Eng Jun 2027'!B10,"")&IF('Eng Jun 2027'!A11=3,", "&'Eng Jun 2027'!B11,""),3,999)
A22: June 2027 | B22: Computer | C22: =MID(IF('Com Jun 2027'!A8=1,", "&'Com Jun 2027'!B8,"")&IF('Com Jun 2027'!A9=1,", "&'Com Jun 2027'!B9,"")&IF('Com Jun 2027'!A10=1,", "&'Com Jun 2027'!B10,"")&IF('Com Jun 2027'!A11=1,", "&'Com Jun 2027'!B11,""),3,999) | D22: =MID(IF('Com Jun 2027'!A8=2,", "&'Com Jun 2027'!B8,"")&IF('Com Jun 2027'!A9=2,", "&'Com Jun 2027'!B9,"")&IF('Com Jun 2027'!A10=2,", "&'Com Jun 2027'!B10,"")&IF('Com Jun 2027'!A11=2,", "&'Com Jun 2027'!B11,""),3,999) | E22: =MID(IF('Com Jun 2027'!A8=3,", "&'Com Jun 2027'!B8,"")&IF('Com Jun 2027'!A9=3,", "&'Com Jun 2027'!B9,"")&IF('Com Jun 2027'!A10=3,", "&'Com Jun 2027'!B10,"")&IF('Com Jun 2027'!A11=3,", "&'Com Jun 2027'!B11,""),3,999)
A23: July 2027 | B23: English | C23: =MID(IF('Eng Jul 2027'!A8=1,", "&'Eng Jul 2027'!B8,"")&IF('Eng Jul 2027'!A9=1,", "&'Eng Jul 2027'!B9,"")&IF('Eng Jul 2027'!A10=1,", "&'Eng Jul 2027'!B10,"")&IF('Eng Jul 2027'!A11=1,", "&'Eng Jul 2027'!B11,""),3,999) | D23: =MID(IF('Eng Jul 2027'!A8=2,", "&'Eng Jul 2027'!B8,"")&IF('Eng Jul 2027'!A9=2,", "&'Eng Jul 2027'!B9,"")&IF('Eng Jul 2027'!A10=2,", "&'Eng Jul 2027'!B10,"")&IF('Eng Jul 2027'!A11=2,", "&'Eng Jul 2027'!B11,""),3,999) | E23: =MID(IF('Eng Jul 2027'!A8=3,", "&'Eng Jul 2027'!B8,"")&IF('Eng Jul 2027'!A9=3,", "&'Eng Jul 2027'!B9,"")&IF('Eng Jul 2027'!A10=3,", "&'Eng Jul 2027'!B10,"")&IF('Eng Jul 2027'!A11=3,", "&'Eng Jul 2027'!B11,""),3,999)
A24: July 2027 | B24: Computer | C24: =MID(IF('Com Jul 2027'!A8=1,", "&'Com Jul 2027'!B8,"")&IF('Com Jul 2027'!A9=1,", "&'Com Jul 2027'!B9,"")&IF('Com Jul 2027'!A10=1,", "&'Com Jul 2027'!B10,"")&IF('Com Jul 2027'!A11=1,", "&'Com Jul 2027'!B11,""),3,999) | D24: =MID(IF('Com Jul 2027'!A8=2,", "&'Com Jul 2027'!B8,"")&IF('Com Jul 2027'!A9=2,", "&'Com Jul 2027'!B9,"")&IF('Com Jul 2027'!A10=2,", "&'Com Jul 2027'!B10,"")&IF('Com Jul 2027'!A11=2,", "&'Com Jul 2027'!B11,""),3,999) | E24: =MID(IF('Com Jul 2027'!A8=3,", "&'Com Jul 2027'!B8,"")&IF('Com Jul 2027'!A9=3,", "&'Com Jul 2027'!B9,"")&IF('Com Jul 2027'!A10=3,", "&'Com Jul 2027'!B10,"")&IF('Com Jul 2027'!A11=3,", "&'Com Jul 2027'!B11,""),3,999)
A25: August 2027 | B25: English | C25: =MID(IF('Eng Aug 2027'!A8=1,", "&'Eng Aug 2027'!B8,"")&IF('Eng Aug 2027'!A9=1,", "&'Eng Aug 2027'!B9,"")&IF('Eng Aug 2027'!A10=1,", "&'Eng Aug 2027'!B10,"")&IF('Eng Aug 2027'!A11=1,", "&'Eng Aug 2027'!B11,""),3,999) | D25: =MID(IF('Eng Aug 2027'!A8=2,", "&'Eng Aug 2027'!B8,"")&IF('Eng Aug 2027'!A9=2,", "&'Eng Aug 2027'!B9,"")&IF('Eng Aug 2027'!A10=2,", "&'Eng Aug 2027'!B10,"")&IF('Eng Aug 2027'!A11=2,", "&'Eng Aug 2027'!B11,""),3,999) | E25: =MID(IF('Eng Aug 2027'!A8=3,", "&'Eng Aug 2027'!B8,"")&IF('Eng Aug 2027'!A9=3,", "&'Eng Aug 2027'!B9,"")&IF('Eng Aug 2027'!A10=3,", "&'Eng Aug 2027'!B10,"")&IF('Eng Aug 2027'!A11=3,", "&'Eng Aug 2027'!B11,""),3,999)
A26: August 2027 | B26: Computer | C26: =MID(IF('Com Aug 2027'!A8=1,", "&'Com Aug 2027'!B8,"")&IF('Com Aug 2027'!A9=1,", "&'Com Aug 2027'!B9,"")&IF('Com Aug 2027'!A10=1,", "&'Com Aug 2027'!B10,"")&IF('Com Aug 2027'!A11=1,", "&'Com Aug 2027'!B11,""),3,999) | D26: =MID(IF('Com Aug 2027'!A8=2,", "&'Com Aug 2027'!B8,"")&IF('Com Aug 2027'!A9=2,", "&'Com Aug 2027'!B9,"")&IF('Com Aug 2027'!A10=2,", "&'Com Aug 2027'!B10,"")&IF('Com Aug 2027'!A11=2,", "&'Com Aug 2027'!B11,""),3,999) | E26: =MID(IF('Com Aug 2027'!A8=3,", "&'Com Aug 2027'!B8,"")&IF('Com Aug 2027'!A9=3,", "&'Com Aug 2027'!B9,"")&IF('Com Aug 2027'!A10=3,", "&'Com Aug 2027'!B10,"")&IF('Com Aug 2027'!A11=3,", "&'Com Aug 2027'!B11,""),3,999)
A27: September 2027 | B27: English | C27: =MID(IF('Eng Sep 2027'!A8=1,", "&'Eng Sep 2027'!B8,"")&IF('Eng Sep 2027'!A9=1,", "&'Eng Sep 2027'!B9,"")&IF('Eng Sep 2027'!A10=1,", "&'Eng Sep 2027'!B10,"")&IF('Eng Sep 2027'!A11=1,", "&'Eng Sep 2027'!B11,""),3,999) | D27: =MID(IF('Eng Sep 2027'!A8=2,", "&'Eng Sep 2027'!B8,"")&IF('Eng Sep 2027'!A9=2,", "&'Eng Sep 2027'!B9,"")&IF('Eng Sep 2027'!A10=2,", "&'Eng Sep 2027'!B10,"")&IF('Eng Sep 2027'!A11=2,", "&'Eng Sep 2027'!B11,""),3,999) | E27: =MID(IF('Eng Sep 2027'!A8=3,", "&'Eng Sep 2027'!B8,"")&IF('Eng Sep 2027'!A9=3,", "&'Eng Sep 2027'!B9,"")&IF('Eng Sep 2027'!A10=3,", "&'Eng Sep 2027'!B10,"")&IF('Eng Sep 2027'!A11=3,", "&'Eng Sep 2027'!B11,""),3,999)
A28: September 2027 | B28: Computer | C28: =MID(IF('Com Sep 2027'!A8=1,", "&'Com Sep 2027'!B8,"")&IF('Com Sep 2027'!A9=1,", "&'Com Sep 2027'!B9,"")&IF('Com Sep 2027'!A10=1,", "&'Com Sep 2027'!B10,"")&IF('Com Sep 2027'!A11=1,", "&'Com Sep 2027'!B11,""),3,999) | D28: =MID(IF('Com Sep 2027'!A8=2,", "&'Com Sep 2027'!B8,"")&IF('Com Sep 2027'!A9=2,", "&'Com Sep 2027'!B9,"")&IF('Com Sep 2027'!A10=2,", "&'Com Sep 2027'!B10,"")&IF('Com Sep 2027'!A11=2,", "&'Com Sep 2027'!B11,""),3,999) | E28: =MID(IF('Com Sep 2027'!A8=3,", "&'Com Sep 2027'!B8,"")&IF('Com Sep 2027'!A9=3,", "&'Com Sep 2027'!B9,"")&IF('Com Sep 2027'!A10=3,", "&'Com Sep 2027'!B10,"")&IF('Com Sep 2027'!A11=3,", "&'Com Sep 2027'!B11,""),3,999)

Sheet Eng Oct 2026
A1: FUTURE TALENT ACADEMY JAMSHORO
A2: English Class — Monthly Marksheet — October 2026
D3: Test 1 | E3: Test 2 | F3: Test 3 | G3: Out of
A4: Teacher: Sir Sajjad Ali Birhmani | C4: Total marks of each test → | D4: 50 | E4: 50 | F4: 50 | G4: =SUM(D4:F4) -> 150
A6: 🏆 TOP 3 — AWARD WINNERS
A7: Pos. | B7: Student Name | F7: Percentage | H7: Grade | J7: Award
A8: =IF(IFERROR(INDEX($K$13:$K$62,MATCH(1,$M$13:$M$62,0))<=3,FALSE()),INDEX($K$13:$K$62,MATCH(1,$M$13:$M$62,0)),"") | B8: =IF(IFERROR(INDEX($K$13:$K$62,MATCH(1,$M$13:$M$62,0))<=3,FALSE()),INDEX($B$13:$B$62,MATCH(1,$M$13:$M$62,0)),"") | F8: =IF(IFERROR(INDEX($K$13:$K$62,MATCH(1,$M$13:$M$62,0))<=3,FALSE()),INDEX($I$13:$I$62,MATCH(1,$M$13:$M$62,0)),"") | H8: =IF(IFERROR(INDEX($K$13:$K$62,MATCH(1,$M$13:$M$62,0))<=3,FALSE()),INDEX($J$13:$J$62,MATCH(1,$M$13:$M$62,0)),"") | J8: =IF(IFERROR(INDEX($K$13:$K$62,MATCH(1,$M$13:$M$62,0))<=3,FALSE()),INDEX($L$13:$L$62,MATCH(1,$M$13:$M$62,0)),"")
A9: =IF(IFERROR(INDEX($K$13:$K$62,MATCH(2,$M$13:$M$62,0))<=3,FALSE()),INDEX($K$13:$K$62,MATCH(2,$M$13:$M$62,0)),"") | B9: =IF(IFERROR(INDEX($K$13:$K$62,MATCH(2,$M$13:$M$62,0))<=3,FALSE()),INDEX($B$13:$B$62,MATCH(2,$M$13:$M$62,0)),"") | F9: =IF(IFERROR(INDEX($K$13:$K$62,MATCH(2,$M$13:$M$62,0))<=3,FALSE()),INDEX($I$13:$I$62,MATCH(2,$M$13:$M$62,0)),"") | H9: =IF(IFERROR(INDEX($K$13:$K$62,MATCH(2,$M$13:$M$62,0))<=3,FALSE()),INDEX($J$13:$J$62,MATCH(2,$M$13:$M$62,0)),"") | J9: =IF(IFERROR(INDEX($K$13:$K$62,MATCH(2,$M$13:$M$62,0))<=3,FALSE()),INDEX($L$13:$L$62,MATCH(2,$M$13:$M$62,0)),"")
A10: =IF(IFERROR(INDEX($K$13:$K$62,MATCH(3,$M$13:$M$62,0))<=3,FALSE()),INDEX($K$13:$K$62,MATCH(3,$M$13:$M$62,0)),"") | B10: =IF(IFERROR(INDEX($K$13:$K$62,MATCH(3,$M$13:$M$62,0))<=3,FALSE()),INDEX($B$13:$B$62,MATCH(3,$M$13:$M$62,0)),"") | F10: =IF(IFERROR(INDEX($K$13:$K$62,MATCH(3,$M$13:$M$62,0))<=3,FALSE()),INDEX($I$13:$I$62,MATCH(3,$M$13:$M$62,0)),"") | H10: =IF(IFERROR(INDEX($K$13:$K$62,MATCH(3,$M$13:$M$62,0))<=3,FALSE()),INDEX($J$13:$J$62,MATCH(3,$M$13:$M$62,0)),"") | J10: =IF(IFERROR(INDEX($K$13:$K$62,MATCH(3,$M$13:$M$62,0))<=3,FALSE()),INDEX($L$13:$L$62,MATCH(3,$M$13:$M$62,0)),"")
A11: =IF(IFERROR(INDEX($K$13:$K$62,MATCH(4,$M$13:$M$62,0))<=3,FALSE()),INDEX($K$13:$K$62,MATCH(4,$M$13:$M$62,0)),"") | B11: =IF(IFERROR(INDEX($K$13:$K$62,MATCH(4,$M$13:$M$62,0))<=3,FALSE()),INDEX($B$13:$B$62,MATCH(4,$M$13:$M$62,0)),"") | F11: =IF(IFERROR(INDEX($K$13:$K$62,MATCH(4,$M$13:$M$62,0))<=3,FALSE()),INDEX($I$13:$I$62,MATCH(4,$M$13:$M$62,0)),"") | H11: =IF(IFERROR(INDEX($K$13:$K$62,MATCH(4,$M$13:$M$62,0))<=3,FALSE()),INDEX($J$13:$J$62,MATCH(4,$M$13:$M$62,0)),"") | J11: =IF(IFERROR(INDEX($K$13:$K$62,MATCH(4,$M$13:$M$62,0))<=3,FALSE()),INDEX($L$13:$L$62,MATCH(4,$M$13:$M$62,0)),"")
A12: S.No | B12: Student Name | C12: Father Name | D12: Test 1 | E12: Test 2 | F12: Test 3 | G12: Total | H12: Out of | I12: Percentage | J12: Grade | K12: Position | L12: Award | M12: Order
A13: 1 | B13: =IF(Students!B6="","",Students!B6) -> Ali Ahmed (example) | C13: =IF(Students!C6="","",Students!C6) -> Ahmed Khan | G13: =IF(OR(B13="",COUNTA(D13:F13)=0),"",SUM(D13:F13)) | H13: =IF(G13="","",$G$4) | I13: =IF(G13="","",G13/H13) | J13: =IF(I13="","",IF(I13>=0.9,"A+",IF(I13>=0.8,"A",IF(I13>=0.7,"B",IF(I13>=0.6,"C",IF(I13>=0.5,"D","F")))))) | K13: =IF(I13="","",RANK(I13,$I$13:$I$62,0)) | L13: =IF(K13="","",IF(K13=1,"🥇 1st Award",IF(K13=2,"🥈 2nd Award",IF(K13=3,"🥉 3rd Award","")))) | M13: =IF(K13="","",K13+COUNTIF($I$13:I13,I13)-1)
A14: 2 | B14: =IF(Students!B7="","",Students!B7) | C14: =IF(Students!C7="","",Students!C7) | G14: =IF(OR(B14="",COUNTA(D14:F14)=0),"",SUM(D14:F14)) | H14: =IF(G14="","",$G$4) | I14: =IF(G14="","",G14/H14) | J14: =IF(I14="","",IF(I14>=0.9,"A+",IF(I14>=0.8,"A",IF(I14>=0.7,"B",IF(I14>=0.6,"C",IF(I14>=0.5,"D","F")))))) | K14: =IF(I14="","",RANK(I14,$I$13:$I$62,0)) | L14: =IF(K14="","",IF(K14=1,"🥇 1st Award",IF(K14=2,"🥈 2nd Award",IF(K14=3,"🥉 3rd Award","")))) | M14: =IF(K14="","",K14+COUNTIF($I$13:I14,I14)-1)
A15: 3 | B15: =IF(Students!B8="","",Students!B8) | C15: =IF(Students!C8="","",Students!C8) | G15: =IF(OR(B15="",COUNTA(D15:F15)=0),"",SUM(D15:F15)) | H15: =IF(G15="","",$G$4) | I15: =IF(G15="","",G15/H15) | J15: =IF(I15="","",IF(I15>=0.9,"A+",IF(I15>=0.8,"A",IF(I15>=0.7,"B",IF(I15>=0.6,"C",IF(I15>=0.5,"D","F")))))) | K15: =IF(I15="","",RANK(I15,$I$13:$I$62,0)) | L15: =IF(K15="","",IF(K15=1,"🥇 1st Award",IF(K15=2,"🥈 2nd Award",IF(K15=3,"🥉 3rd Award","")))) | M15: =IF(K15="","",K15+COUNTIF($I$13:I15,I15)-1)
A16: 4 | B16: =IF(Students!B9="","",Students!B9) | C16: =IF(Students!C9="","",Students!C9) | G16: =IF(OR(B16="",COUNTA(D16:F16)=0),"",SUM(D16:F16)) | H16: =IF(G16="","",$G$4) | I16: =IF(G16="","",G16/H16) | J16: =IF(I16="","",IF(I16>=0.9,"A+",IF(I16>=0.8,"A",IF(I16>=0.7,"B",IF(I16>=0.6,"C",IF(I16>=0.5,"D","F")))))) | K16: =IF(I16="","",RANK(I16,$I$13:$I$62,0)) | L16: =IF(K16="","",IF(K16=1,"🥇 1st Award",IF(K16=2,"🥈 2nd Award",IF(K16=3,"🥉 3rd Award","")))) | M16: =IF(K16="","",K16+COUNTIF($I$13:I16,I16)-1)
A17: 5 | B17: =IF(Students!B10="","",Students!B10) | C17: =IF(Students!C10="","",Students!C10) | G17: =IF(OR(B17="",COUNTA(D17:F17)=0),"",SUM(D17:F17)) | H17: =IF(G17="","",$G$4) | I17: =IF(G17="","",G17/H17) | J17: =IF(I17="","",IF(I17>=0.9,"A+",IF(I17>=0.8,"A",IF(I17>=0.7,"B",IF(I17>=0.6,"C",IF(I17>=0.5,"D","F")))))) | K17: =IF(I17="","",RANK(I17,$I$13:$I$62,0)) | L17: =IF(K17="","",IF(K17=1,"🥇 1st Award",IF(K17=2,"🥈 2nd Award",IF(K17=3,"🥉 3rd Award","")))) | M17: =IF(K17="","",K17+COUNTIF($I$13:I17,I17)-1)
A18: 6 | B18: =IF(Students!B11="","",Students!B11) | C18: =IF(Students!C11="","",Students!C11) | G18: =IF(OR(B18="",COUNTA(D18:F18)=0),"",SUM(D18:F18)) | H18: =IF(G18="","",$G$4) | I18: =IF(G18="","",G18/H18) | J18: =IF(I18="","",IF(I18>=0.9,"A+",IF(I18>=0.8,"A",IF(I18>=0.7,"B",IF(I18>=0.6,"C",IF(I18>=0.5,"D","F")))))) | K18: =IF(I18="","",RANK(I18,$I$13:$I$62,0)) | L18: =IF(K18="","",IF(K18=1,"🥇 1st Award",IF(K18=2,"🥈 2nd Award",IF(K18=3,"🥉 3rd Award","")))) | M18: =IF(K18="","",K18+COUNTIF($I$13:I18,I18)-1)
A19: 7 | B19: =IF(Students!B12="","",Students!B12) | C19: =IF(Students!C12="","",Students!C12) | G19: =IF(OR(B19="",COUNTA(D19:F19)=0),"",SUM(D19:F19)) | H19: =IF(G19="","",$G$4) | I19: =IF(G19="","",G19/H19) | J19: =IF(I19="","",IF(I19>=0.9,"A+",IF(I19>=0.8,"A",IF(I19>=0.7,"B",IF(I19>=0.6,"C",IF(I19>=0.5,"D","F")))))) | K19: =IF(I19="","",RANK(I19,$I$13:$I$62,0)) | L19: =IF(K19="","",IF(K19=1,"🥇 1st Award",IF(K19=2,"🥈 2nd Award",IF(K19=3,"🥉 3rd Award","")))) | M19: =IF(K19="","",K19+COUNTIF($I$13:I19,I19)-1)
A20: 8 | B20: =IF(Students!B13="","",Students!B13) | C20: =IF(Students!C13="","",Students!C13) | G20: =IF(OR(B20="",COUNTA(D20:F20)=0),"",SUM(D20:F20)) | H20: =IF(G20="","",$G$4) | I20: =IF(G20="","",G20/H20) | J20: =IF(I20="","",IF(I20>=0.9,"A+",IF(I20>=0.8,"A",IF(I20>=0.7,"B",IF(I20>=0.6,"C",IF(I20>=0.5,"D","F")))))) | K20: =IF(I20="","",RANK(I20,$I$13:$I$62,0)) | L20: =IF(K20="","",IF(K20=1,"🥇 1st Award",IF(K20=2,"🥈 2nd Award",IF(K20=3,"🥉 3rd Award","")))) | M20: =IF(K20="","",K20+COUNTIF($I$13:I20,I20)-1)
A21: 9 | B21: =IF(Students!B14="","",Students!B14) | C21: =IF(Students!C14="","",Students!C14) | G21: =IF(OR(B21="",COUNTA(D21:F21)=0),"",SUM(D21:F21)) | H21: =IF(G21="","",$G$4) | I21: =IF(G21="","",G21/H21) | J21: =IF(I21="","",IF(I21>=0.9,"A+",IF(I21>=0.8,"A",IF(I21>=0.7,"B",IF(I21>=0.6,"C",IF(I21>=0.5,"D","F")))))) | K21: =IF(I21="","",RANK(I21,$I$13:$I$62,0)) | L21: =IF(K21="","",IF(K21=1,"🥇 1st Award",IF(K21=2,"🥈 2nd Award",IF(K21=3,"🥉 3rd Award","")))) | M21: =IF(K21="","",K21+COUNTIF($I$13:I21,I21)-1)
A22: 10 | B22: =IF(Students!B15="","",Students!B15) | C22: =IF(Students!C15="","",Students!C15) | G22: =IF(OR(B22="",COUNTA(D22:F22)=0),"",SUM(D22:F22)) | H22: =IF(G22="","",$G$4) | I22: =IF(G22="","",G22/H22) | J22: =IF(I22="","",IF(I22>=0.9,"A+",IF(I22>=0.8,"A",IF(I22>=0.7,"B",IF(I22>=0.6,"C",IF(I22>=0.5,"D","F")))))) | K22: =IF(I22="","",RANK(I22,$I$13:$I$62,0)) | L22: =IF(K22="","",IF(K22=1,"🥇 1st Award",IF(K22=2,"🥈 2nd Award",IF(K22=3,"🥉 3rd Award","")))) | M22: =IF(K22="","",K22+COUNTIF($I$13:I22,I22)-1)
A23: 11 | B23: =IF(Students!B16="","",Students!B16) | C23: =IF(Students!C16="","",Students!C16) | G23: =IF(OR(B23="",COUNTA(D23:F23)=0),"",SUM(D23:F23)) | H23: =IF(G23="","",$G$4) | I23: =IF(G23="","",G23/H23) | J23: =IF(I23="","",IF(I23>=0.9,"A+",IF(I23>=0.8,"A",IF(I23>=0.7,"B",IF(I23>=0.6,"C",IF(I23>=0.5,"D","F")))))) | K23: =IF(I23="","",RANK(I23,$I$13:$I$62,0)) | L23: =IF(K23="","",IF(K23=1,"🥇 1st Award",IF(K23=2,"🥈 2nd Award",IF(K23=3,"🥉 3rd Award","")))) | M23: =IF(K23="","",K23+COUNTIF($I$13:I23,I23)-1)
A24: 12 | B24: =IF(Students!B17="","",Students!B17) | C24: =IF(Students!C17="","",Students!C17) | G24: =IF(OR(B24="",COUNTA(D24:F24)=0),"",SUM(D24:F24)) | H24: =IF(G24="","",$G$4) | I24: =IF(G24="","",G24/H24) | J24: =IF(I24="","",IF(I24>=0.9,"A+",IF(I24>=0.8,"A",IF(I24>=0.7,"B",IF(I24>=0.6,"C",IF(I24>=0.5,"D","F")))))) | K24: =IF(I24="","",RANK(I24,$I$13:$I$62,0)) | L24: =IF(K24="","",IF(K24=1,"🥇 1st Award",IF(K24=2,"🥈 2nd Award",IF(K24=3,"🥉 3rd Award","")))) | M24: =IF(K24="","",K24+COUNTIF($I$13:I24,I24)-1)
... A62: 50 | B62: =IF(Students!B55="","",Students!B55) | C62: =IF(Students!C55="","",Students!C55) | G62: =IF(OR(B62="",COUNTA(D62:F62)=0),"",SUM(D62:F62)) | H62: =IF(G62="","",$G$4) | I62: =IF(G62="","",G62/H62) | J62: =IF(I62="","",IF(I62>=0.9,"A+",IF(I62>=0.8,"A",IF(I62>=0.7,"B",IF(I62>=0.6,"C",IF(I62>=0.5,"D","F")))))) | K62: =IF(I62="","",RANK(I62,$I$13:$I$62,0)) | L62: =IF(K62="","",IF(K62=1,"🥇 1st Award",IF(K62=2,"🥈 2nd Award",IF(K62=3,"🥉 3rd Award","")))) | M62: =IF(K62="","",K62+COUNTIF($I$13:I62,I62)-1)

Sheet Com Oct 2026
A1: FUTURE TALENT ACADEMY JAMSHORO
A2: Computer Class — Monthly Marksheet — October 2026
D3: Test 1 | E3: Test 2 | F3: Test 3 | G3: Out of
A4: Teacher: Sir Nazeer Ahmed Jamali | C4: Total marks of each test → | D4: 50 | E4: 50 | F4: 50 | G4: =SUM(D4:F4) -> 150
A6: 🏆 TOP 3 — AWARD WINNERS
A7: Pos. | B7: Student Name | F7: Percentage | H7: Grade | J7: Award
A8: =IF(IFERROR(INDEX($K$13:$K$62,MATCH(1,$M$13:$M$62,0))<=3,FALSE()),INDEX($K$13:$K$62,MATCH(1,$M$13:$M$62,0)),"") | B8: =IF(IFERROR(INDEX($K$13:$K$62,MATCH(1,$M$13:$M$62,0))<=3,FALSE()),INDEX($B$13:$B$62,MATCH(1,$M$13:$M$62,0)),"") | F8: =IF(IFERROR(INDEX($K$13:$K$62,MATCH(1,$M$13:$M$62,0))<=3,FALSE()),INDEX($I$13:$I$62,MATCH(1,$M$13:$M$62,0)),"") | H8: =IF(IFERROR(INDEX($K$13:$K$62,MATCH(1,$M$13:$M$62,0))<=3,FALSE()),INDEX($J$13:$J$62,MATCH(1,$M$13:$M$62,0)),"") | J8: =IF(IFERROR(INDEX($K$13:$K$62,MATCH(1,$M$13:$M$62,0))<=3,FALSE()),INDEX($L$13:$L$62,MATCH(1,$M$13:$M$62,0)),"")
A9: =IF(IFERROR(INDEX($K$13:$K$62,MATCH(2,$M$13:$M$62,0))<=3,FALSE()),INDEX($K$13:$K$62,MATCH(2,$M$13:$M$62,0)),"") | B9: =IF(IFERROR(INDEX($K$13:$K$62,MATCH(2,$M$13:$M$62,0))<=3,FALSE()),INDEX($B$13:$B$62,MATCH(2,$M$13:$M$62,0)),"") | F9: =IF(IFERROR(INDEX($K$13:$K$62,MATCH(2,$M$13:$M$62,0))<=3,FALSE()),INDEX($I$13:$I$62,MATCH(2,$M$13:$M$62,0)),"") | H9: =IF(IFERROR(INDEX($K$13:$K$62,MATCH(2,$M$13:$M$62,0))<=3,FALSE()),INDEX($J$13:$J$62,MATCH(2,$M$13:$M$62,0)),"") | J9: =IF(IFERROR(INDEX($K$13:$K$62,MATCH(2,$M$13:$M$62,0))<=3,FALSE()),INDEX($L$13:$L$62,MATCH(2,$M$13:$M$62,0)),"")
A10: =IF(IFERROR(INDEX($K$13:$K$62,MATCH(3,$M$13:$M$62,0))<=3,FALSE()),INDEX($K$13:$K$62,MATCH(3,$M$13:$M$62,0)),"") | B10: =IF(IFERROR(INDEX($K$13:$K$62,MATCH(3,$M$13:$M$62,0))<=3,FALSE()),INDEX($B$13:$B$62,MATCH(3,$M$13:$M$62,0)),"") | F10: =IF(IFERROR(INDEX($K$13:$K$62,MATCH(3,$M$13:$M$62,0))<=3,FALSE()),INDEX($I$13:$I$62,MATCH(3,$M$13:$M$62,0)),"") | H10: =IF(IFERROR(INDEX($K$13:$K$62,MATCH(3,$M$13:$M$62,0))<=3,FALSE()),INDEX($J$13:$J$62,MATCH(3,$M$13:$M$62,0)),"") | J10: =IF(IFERROR(INDEX($K$13:$K$62,MATCH(3,$M$13:$M$62,0))<=3,FALSE()),INDEX($L$13:$L$62,MATCH(3,$M$13:$M$62,0)),"")
A11: =IF(IFERROR(INDEX($K$13:$K$62,MATCH(4,$M$13:$M$62,0))<=3,FALSE()),INDEX($K$13:$K$62,MATCH(4,$M$13:$M$62,0)),"") | B11: =IF(IFERROR(INDEX($K$13:$K$62,MATCH(4,$M$13:$M$62,0))<=3,FALSE()),INDEX($B$13:$B$62,MATCH(4,$M$13:$M$62,0)),"") | F11: =IF(IFERROR(INDEX($K$13:$K$62,MATCH(4,$M$13:$M$62,0))<=3,FALSE()),INDEX($I$13:$I$62,MATCH(4,$M$13:$M$62,0)),"") | H11: =IF(IFERROR(INDEX($K$13:$K$62,MATCH(4,$M$13:$M$62,0))<=3,FALSE()),INDEX($J$13:$J$62,MATCH(4,$M$13:$M$62,0)),"") | J11: =IF(IFERROR(INDEX($K$13:$K$62,MATCH(4,$M$13:$M$62,0))<=3,FALSE()),INDEX($L$13:$L$62,MATCH(4,$M$13:$M$62,0)),"")
A12: S.No | B12: Student Name | C12: Father Name | D12: Test 1 | E12: Test 2 | F12: Test 3 | G12: Total | H12: Out of | I12: Percentage | J12: Grade | K12: Position | L12: Award | M12: Order
A13: 1 | B13: =IF(Students!F6="","",Students!F6) -> Sara Bibi (example) | C13: =IF(Students!G6="","",Students!G6) -> Abdul Rehman | G13: =IF(OR(B13="",COUNTA(D13:F13)=0),"",SUM(D13:F13)) | H13: =IF(G13="","",$G$4) | I13: =IF(G13="","",G13/H13) | J13: =IF(I13="","",IF(I13>=0.9,"A+",IF(I13>=0.8,"A",IF(I13>=0.7,"B",IF(I13>=0.6,"C",IF(I13>=0.5,"D","F")))))) | K13: =IF(I13="","",RANK(I13,$I$13:$I$62,0)) | L13: =IF(K13="","",IF(K13=1,"🥇 1st Award",IF(K13=2,"🥈 2nd Award",IF(K13=3,"🥉 3rd Award","")))) | M13: =IF(K13="","",K13+COUNTIF($I$13:I13,I13)-1)
A14: 2 | B14: =IF(Students!F7="","",Students!F7) | C14: =IF(Students!G7="","",Students!G7) | G14: =IF(OR(B14="",COUNTA(D14:F14)=0),"",SUM(D14:F14)) | H14: =IF(G14="","",$G$4) | I14: =IF(G14="","",G14/H14) | J14: =IF(I14="","",IF(I14>=0.9,"A+",IF(I14>=0.8,"A",IF(I14>=0.7,"B",IF(I14>=0.6,"C",IF(I14>=0.5,"D","F")))))) | K14: =IF(I14="","",RANK(I14,$I$13:$I$62,0)) | L14: =IF(K14="","",IF(K14=1,"🥇 1st Award",IF(K14=2,"🥈 2nd Award",IF(K14=3,"🥉 3rd Award","")))) | M14: =IF(K14="","",K14+COUNTIF($I$13:I14,I14)-1)
A15: 3 | B15: =IF(Students!F8="","",Students!F8) | C15: =IF(Students!G8="","",Students!G8) | G15: =IF(OR(B15="",COUNTA(D15:F15)=0),"",SUM(D15:F15)) | H15: =IF(G15="","",$G$4) | I15: =IF(G15="","",G15/H15) | J15: =IF(I15="","",IF(I15>=0.9,"A+",IF(I15>=0.8,"A",IF(I15>=0.7,"B",IF(I15>=0.6,"C",IF(I15>=0.5,"D","F")))))) | K15: =IF(I15="","",RANK(I15,$I$13:$I$62,0)) | L15: =IF(K15="","",IF(K15=1,"🥇 1st Award",IF(K15=2,"🥈 2nd Award",IF(K15=3,"🥉 3rd Award","")))) | M15: =IF(K15="","",K15+COUNTIF($I$13:I15,I15)-1)
A16: 4 | B16: =IF(Students!F9="","",Students!F9) | C16: =IF(Students!G9="","",Students!G9) | G16: =IF(OR(B16="",COUNTA(D16:F16)=0),"",SUM(D16:F16)) | H16: =IF(G16="","",$G$4) | I16: =IF(G16="","",G16/H16) | J16: =IF(I16="","",IF(I16>=0.9,"A+",IF(I16>=0.8,"A",IF(I16>=0.7,"B",IF(I16>=0.6,"C",IF(I16>=0.5,"D","F")))))) | K16: =IF(I16="","",RANK(I16,$I$13:$I$62,0)) | L16: =IF(K16="","",IF(K16=1,"🥇 1st Award",IF(K16=2,"🥈 2nd Award",IF(K16=3,"🥉 3rd Award","")))) | M16: =IF(K16="","",K16+COUNTIF($I$13:I16,I16)-1)
A17: 5 | B17: =IF(Students!F10="","",Students!F10) | C17: =IF(Students!G10="","",Students!G10) | G17: =IF(OR(B17="",COUNTA(D17:F17)=0),"",SUM(D17:F17)) | H17: =IF(G17="","",$G$4) | I17: =IF(G17="","",G17/H17) | J17: =IF(I17="","",IF(I17>=0.9,"A+",IF(I17>=0.8,"A",IF(I17>=0.7,"B",IF(I17>=0.6,"C",IF(I17>=0.5,"D","F")))))) | K17: =IF(I17="","",RANK(I17,$I$13:$I$62,0)) | L17: =IF(K17="","",IF(K17=1,"🥇 1st Award",IF(K17=2,"🥈 2nd Award",IF(K17=3,"🥉 3rd Award","")))) | M17: =IF(K17="","",K17+COUNTIF($I$13:I17,I17)-1)
A18: 6 | B18: =IF(Students!F11="","",Students!F11) | C18: =IF(Students!G11="","",Students!G11) | G18: =IF(OR(B18="",COUNTA(D18:F18)=0),"",SUM(D18:F18)) | H18: =IF(G18="","",$G$4) | I18: =IF(G18="","",G18/H18) | J18: =IF(I18="","",IF(I18>=0.9,"A+",IF(I18>=0.8,"A",IF(I18>=0.7,"B",IF(I18>=0.6,"C",IF(I18>=0.5,"D","F")))))) | K18: =IF(I18="","",RANK(I18,$I$13:$I$62,0)) | L18: =IF(K18="","",IF(K18=1,"🥇 1st Award",IF(K18=2,"🥈 2nd Award",IF(K18=3,"🥉 3rd Award","")))) | M18: =IF(K18="","",K18+COUNTIF($I$13:I18,I18)-1)
A19: 7 | B19: =IF(Students!F12="","",Students!F12) | C19: =IF(Students!G12="","",Students!G12) | G19: =IF(OR(B19="",COUNTA(D19:F19)=0),"",SUM(D19:F19)) | H19: =IF(G19="","",$G$4) | I19: =IF(G19="","",G19/H19) | J19: =IF(I19="","",IF(I19>=0.9,"A+",IF(I19>=0.8,"A",IF(I19>=0.7,"B",IF(I19>=0.6,"C",IF(I19>=0.5,"D","F")))))) | K19: =IF(I19="","",RANK(I19,$I$13:$I$62,0)) | L19: =IF(K19="","",IF(K19=1,"🥇 1st Award",IF(K19=2,"🥈 2nd Award",IF(K19=3,"🥉 3rd Award","")))) | M19: =IF(K19="","",K19+COUNTIF($I$13:I19,I19)-1)
A20: 8 | B20: =IF(Students!F13="","",Students!F13) | C20: =IF(Students!G13="","",Students!G13) | G20: =IF(OR(B20="",COUNTA(D20:F20)=0),"",SUM(D20:F20)) | H20: =IF(G20="","",$G$4) | I20: =IF(G20="","",G20/H20) | J20: =IF(I20="","",IF(I20>=0.9,"A+",IF(I20>=0.8,"A",IF(I20>=0.7,"B",IF(I20>=0.6,"C",IF(I20>=0.5,"D","F")))))) | K20: =IF(I20="","",RANK(I20,$I$13:$I$62,0)) | L20: =IF(K20="","",IF(K20=1,"🥇 1st Award",IF(K20=2,"🥈 2nd Award",IF(K20=3,"🥉 3rd Award","")))) | M20: =IF(K20="","",K20+COUNTIF($I$13:I20,I20)-1)
A21: 9 | B21: =IF(Students!F14="","",Students!F14) | C21: =IF(Students!G14="","",Students!G14) | G21: =IF(OR(B21="",COUNTA(D21:F21)=0),"",SUM(D21:F21)) | H21: =IF(G21="","",$G$4) | I21: =IF(G21="","",G21/H21) | J21: =IF(I21="","",IF(I21>=0.9,"A+",IF(I21>=0.8,"A",IF(I21>=0.7,"B",IF(I21>=0.6,"C",IF(I21>=0.5,"D","F")))))) | K21: =IF(I21="","",RANK(I21,$I$13:$I$62,0)) | L21: =IF(K21="","",IF(K21=1,"🥇 1st Award",IF(K21=2,"🥈 2nd Award",IF(K21=3,"🥉 3rd Award","")))) | M21: =IF(K21="","",K21+COUNTIF($I$13:I21,I21)-1)
A22: 10 | B22: =IF(Students!F15="","",Students!F15) | C22: =IF(Students!G15="","",Students!G15) | G22: =IF(OR(B22="",COUNTA(D22:F22)=0),"",SUM(D22:F22)) | H22: =IF(G22="","",$G$4) | I22: =IF(G22="","",G22/H22) | J22: =IF(I22="","",IF(I22>=0.9,"A+",IF(I22>=0.8,"A",IF(I22>=0.7,"B",IF(I22>=0.6,"C",IF(I22>=0.5,"D","F")))))) | K22: =IF(I22="","",RANK(I22,$I$13:$I$62,0)) | L22: =IF(K22="","",IF(K22=1,"🥇 1st Award",IF(K22=2,"🥈 2nd Award",IF(K22=3,"🥉 3rd Award","")))) | M22: =IF(K22="","",K22+COUNTIF($I$13:I22,I22)-1)
A23: 11 | B23: =IF(Students!F16="","",Students!F16) | C23: =IF(Students!G16="","",Students!G16) | G23: =IF(OR(B23="",COUNTA(D23:F23)=0),"",SUM(D23:F23)) | H23: =IF(G23="","",$G$4) | I23: =IF(G23="","",G23/H23) | J23: =IF(I23="","",IF(I23>=0.9,"A+",IF(I23>=0.8,"A",IF(I23>=0.7,"B",IF(I23>=0.6,"C",IF(I23>=0.5,"D","F")))))) | K23: =IF(I23="","",RANK(I23,$I$13:$I$62,0)) | L23: =IF(K23="","",IF(K23=1,"🥇 1st Award",IF(K23=2,"🥈 2nd Award",IF(K23=3,"🥉 3rd Award","")))) | M23: =IF(K23="","",K23+COUNTIF($I$13:I23,I23)-1)
A24: 12 | B24: =IF(Students!F17="","",Students!F17) | C24: =IF(Students!G17="","",Students!G17) | G24: =IF(OR(B24="",COUNTA(D24:F24)=0),"",SUM(D24:F24)) | H24: =IF(G24="","",$G$4) | I24: =IF(G24="","",G24/H24) | J24: =IF(I24="","",IF(I24>=0.9,"A+",IF(I24>=0.8,"A",IF(I24>=0.7,"B",IF(I24>=0.6,"C",IF(I24>=0.5,"D","F")))))) | K24: =IF(I24="","",RANK(I24,$I$13:$I$62,0)) | L24: =IF(K24="","",IF(K24=1,"🥇 1st Award",IF(K24=2,"🥈 2nd Award",IF(K24=3,"🥉 3rd Award","")))) | M24: =IF(K24="","",K24+COUNTIF($I$13:I24,I24)-1)
... A62: 50 | B62: =IF(Students!F55="","",Students!F55) | C62: =IF(Students!G55="","",Students!G55) | G62: =IF(OR(B62="",COUNTA(D62:F62)=0),"",SUM(D62:F62)) | H62: =IF(G62="","",$G$4) | I62: =IF(G62="","",G62/H62) | J62: =IF(I62="","",IF(I62>=0.9,"A+",IF(I62>=0.8,"A",IF(I62>=0.7,"B",IF(I62>=0.6,"C",IF(I62>=0.5,"D","F")))))) | K62: =IF(I62="","",RANK(I62,$I$13:$I$62,0)) | L62: =IF(K62="","",IF(K62=1,"🥇 1st Award",IF(K62=2,"🥈 2nd Award",IF(K62=3,"🥉 3rd Award","")))) | M62: =IF(K62="","",K62+COUNTIF($I$13:I62,I62)-1)

Sheet Eng Nov 2026
A1: FUTURE TALENT ACADEMY JAMSHORO
A2: English Class — Monthly Marksheet — November 2026
D3: Test 1 | E3: Test 2 | F3: Test 3 | G3: Out of
A4: Teacher: Sir Sajjad Ali Birhmani | C4: Total marks of each test → | D4: 50 | E4: 50 | F4: 50 | G4: =SUM(D4:F4) -> 150
A6: 🏆 TOP 3 — AWARD WINNERS
A7: Pos. | B7: Student Name | F7: Percentage | H7: Grade | J7: Award
A8: =IF(IFERROR(INDEX($K$13:$K$62,MATCH(1,$M$13:$M$62,0))<=3,FALSE()),INDEX($K$13:$K$62,MATCH(1,$M$13:$M$62,0)),"") | B8: =IF(IFERROR(INDEX($K$13:$K$62,MATCH(1,$M$13:$M$62,0))<=3,FALSE()),INDEX($B$13:$B$62,MATCH(1,$M$13:$M$62,0)),"") | F8: =IF(IFERROR(INDEX($K$13:$K$62,MATCH(1,$M$13:$M$62,0))<=3,FALSE()),INDEX($I$13:$I$62,MATCH(1,$M$13:$M$62,0)),"") | H8: =IF(IFERROR(INDEX($K$13:$K$62,MATCH(1,$M$13:$M$62,0))<=3,FALSE()),INDEX($J$13:$J$62,MATCH(1,$M$13:$M$62,0)),"") | J8: =IF(IFERROR(INDEX($K$13:$K$62,MATCH(1,$M$13:$M$62,0))<=3,FALSE()),INDEX($L$13:$L$62,MATCH(1,$M$13:$M$62,0)),"")
A9: =IF(IFERROR(INDEX($K$13:$K$62,MATCH(2,$M$13:$M$62,0))<=3,FALSE()),INDEX($K$13:$K$62,MATCH(2,$M$13:$M$62,0)),"") | B9: =IF(IFERROR(INDEX($K$13:$K$62,MATCH(2,$M$13:$M$62,0))<=3,FALSE()),INDEX($B$13:$B$62,MATCH(2,$M$13:$M$62,0)),"") | F9: =IF(IFERROR(INDEX($K$13:$K$62,MATCH(2,$M$13:$M$62,0))<=3,FALSE()),INDEX($I$13:$I$62,MATCH(2,$M$13:$M$62,0)),"") | H9: =IF(IFERROR(INDEX($K$13:$K$62,MATCH(2,$M$13:$M$62,0))<=3,FALSE()),INDEX($J$13:$J$62,MATCH(2,$M$13:$M$62,0)),"") | J9: =IF(IFERROR(INDEX($K$13:$K$62,MATCH(2,$M$13:$M$62,0))<=3,FALSE()),INDEX($L$13:$L$62,MATCH(2,$M$13:$M$62,0)),"")
A10: =IF(IFERROR(INDEX($K$13:$K$62,MATCH(3,$M$13:$M$62,0))<=3,FALSE()),INDEX($K$13:$K$62,MATCH(3,$M$13:$M$62,0)),"") | B10: =IF(IFERROR(INDEX($K$13:$K$62,MATCH(3,$M$13:$M$62,0))<=3,FALSE()),INDEX($B$13:$B$62,MATCH(3,$M$13:$M$62,0)),"") | F10: =IF(IFERROR(INDEX($K$13:$K$62,MATCH(3,$M$13:$M$62,0))<=3,FALSE()),INDEX($I$13:$I$62,MATCH(3,$M$13:$M$62,0)),"") | H10: =IF(IFERROR(INDEX($K$13:$K$62,MATCH(3,$M$13:$M$62,0))<=3,FALSE()),INDEX($J$13:$J$62,MATCH(3,$M$13:$M$62,0)),"") | J10: =IF(IFERROR(INDEX($K$13:$K$62,MATCH(3,$M$13:$M$62,0))<=3,FALSE()),INDEX($L$13:$L$62,MATCH(3,$M$13:$M$62,0)),"")
A11: =IF(IFERROR(INDEX($K$13:$K$62,MATCH(4,$M$13:$M$62,0))<=3,FALSE()),INDEX($K$13:$K$62,MATCH(4,$M$13:$M$62,0)),"") | B11: =IF(IFERROR(INDEX($K$13:$K$62,MATCH(4,$M$13:$M$62,0))<=3,FALSE()),INDEX($B$13:$B$62,MATCH(4,$M$13:$M$62,0)),"") | F11: =IF(IFERROR(INDEX($K$13:$K$62,MATCH(4,$M$13:$M$62,0))<=3,FALSE()),INDEX($I$13:$I$62,MATCH(4,$M$13:$M$62,0)),"") | H11: =IF(IFERROR(INDEX($K$13:$K$62,MATCH(4,$M$13:$M$62,0))<=3,FALSE()),INDEX($J$13:$J$62,MATCH(4,$M$13:$M$62,0)),"") | J11: =IF(IFERROR(INDEX($K$13:$K$62,MATCH(4,$M$13:$M$62,0))<=3,FALSE()),INDEX($L$13:$L$62,MATCH(4,$M$13:$M$62,0)),"")
A12: S.No | B12: Student Name | C12: Father Name | D12: Test 1 | E12: Test 2 | F12: Test 3 | G12: Total | H12: Out of | I12: Percentage | J12: Grade | K12: Position | L12: Award | M12: Order
A13: 1 | B13: =IF(Students!B6="","",Students!B6) -> Ali Ahmed (example) | C13: =IF(Students!C6="","",Students!C6) -> Ahmed Khan | G13: =IF(OR(B13="",COUNTA(D13:F13)=0),"",SUM(D13:F13)) | H13: =IF(G13="","",$G$4) | I13: =IF(G13="","",G13/H13) | J13: =IF(I13="","",IF(I13>=0.9,"A+",IF(I13>=0.8,"A",IF(I13>=0.7,"B",IF(I13>=0.6,"C",IF(I13>=0.5,"D","F")))))) | K13: =IF(I13="","",RANK(I13,$I$13:$I$62,0)) | L13: =IF(K13="","",IF(K13=1,"🥇 1st Award",IF(K13=2,"🥈 2nd Award",IF(K13=3,"🥉 3rd Award","")))) | M13: =IF(K13="","",K13+COUNTIF($I$13:I13,I13)-1)
A14: 2 | B14: =IF(Students!B7="","",Students!B7) | C14: =IF(Students!C7="","",Students!C7) | G14: =IF(OR(B14="",COUNTA(D14:F14)=0),"",SUM(D14:F14)) | H14: =IF(G14="","",$G$4) | I14: =IF(G14="","",G14/H14) | J14: =IF(I14="","",IF(I14>=0.9,"A+",IF(I14>=0.8,"A",IF(I14>=0.7,"B",IF(I14>=0.6,"C",IF(I14>=0.5,"D","F")))))) | K14: =IF(I14="","",RANK(I14,$I$13:$I$62,0)) | L14: =IF(K14="","",IF(K14=1,"🥇 1st Award",IF(K14=2,"🥈 2nd Award",IF(K14=3,"🥉 3rd Award","")))) | M14: =IF(K14="","",K14+COUNTIF($I$13:I14,I14)-1)
A15: 3 | B15: =IF(Students!B8="","",Students!B8) | C15: =IF(Students!C8="","",Students!C8) | G15: =IF(OR(B15="",COUNTA(D15:F15)=0),"",SUM(D15:F15)) | H15: =IF(G15="","",$G$4) | I15: =IF(G15="","",G15/H15) | J15: =IF(I15="","",IF(I15>=0.9,"A+",IF(I15>=0.8,"A",IF(I15>=0.7,"B",IF(I15>=0.6,"C",IF(I15>=0.5,"D","F")))))) | K15: =IF(I15="","",RANK(I15,$I$13:$I$62,0)) | L15: =IF(K15="","",IF(K15=1,"🥇 1st Award",IF(K15=2,"🥈 2nd Award",IF(K15=3,"🥉 3rd Award","")))) | M15: =IF(K15="","",K15+COUNTIF($I$13:I15,I15)-1)
A16: 4 | B16: =IF(Students!B9="","",Students!B9) | C16: =IF(Students!C9="","",Students!C9) | G16: =IF(OR(B16="",COUNTA(D16:F16)=0),"",SUM(D16:F16)) | H16: =IF(G16="","",$G$4) | I16: =IF(G16="","",G16/H16) | J16: =IF(I16="","",IF(I16>=0.9,"A+",IF(I16>=0.8,"A",IF(I16>=0.7,"B",IF(I16>=0.6,"C",IF(I16>=0.5,"D","F")))))) | K16: =IF(I16="","",RANK(I16,$I$13:$I$62,0)) | L16: =IF(K16="","",IF(K16=1,"🥇 1st Award",IF(K16=2,"🥈 2nd Award",IF(K16=3,"🥉 3rd Award","")))) | M16: =IF(K16="","",K16+COUNTIF($I$13:I16,I16)-1)
A17: 5 | B17: =IF(Students!B10="","",Students!B10) | C17: =IF(Students!C10="","",Students!C10) | G17: =IF(OR(B17="",COUNTA(D17:F17)=0),"",SUM(D17:F17)) | H17: =IF(G17="","",$G$4) | I17: =IF(G17="","",G17/H17) | J17: =IF(I17="","",IF(I17>=0.9,"A+",IF(I17>=0.8,"A",IF(I17>=0.7,"B",IF(I17>=0.6,"C",IF(I17>=0.5,"D","F")))))) | K17: =IF(I17="","",RANK(I17,$I$13:$I$62,0)) | L17: =IF(K17="","",IF(K17=1,"🥇 1st Award",IF(K17=2,"🥈 2nd Award",IF(K17=3,"🥉 3rd Award","")))) | M17: =IF(K17="","",K17+COUNTIF($I$13:I17,I17)-1)
A18: 6 | B18: =IF(Students!B11="","",Students!B11) | C18: =IF(Students!C11="","",Students!C11) | G18: =IF(OR(B18="",COUNTA(D18:F18)=0),"",SUM(D18:F18)) | H18: =IF(G18="","",$G$4) | I18: =IF(G18="","",G18/H18) | J18: =IF(I18="","",IF(I18>=0.9,"A+",IF(I18>=0.8,"A",IF(I18>=0.7,"B",IF(I18>=0.6,"C",IF(I18>=0.5,"D","F")))))) | K18: =IF(I18="","",RANK(I18,$I$13:$I$62,0)) | L18: =IF(K18="","",IF(K18=1,"🥇 1st Award",IF(K18=2,"🥈 2nd Award",IF(K18=3,"🥉 3rd Award","")))) | M18: =IF(K18="","",K18+COUNTIF($I$13:I18,I18)-1)
A19: 7 | B19: =IF(Students!B12="","",Students!B12) | C19: =IF(Students!C12="","",Students!C12) | G19: =IF(OR(B19="",COUNTA(D19:F19)=0),"",SUM(D19:F19)) | H19: =IF(G19="","",$G$4) | I19: =IF(G19="","",G19/H19) | J19: =IF(I19="","",IF(I19>=0.9,"A+",IF(I19>=0.8,"A",IF(I19>=0.7,"B",IF(I19>=0.6,"C",IF(I19>=0.5,"D","F")))))) | K19: =IF(I19="","",RANK(I19,$I$13:$I$62,0)) | L19: =IF(K19="","",IF(K19=1,"🥇 1st Award",IF(K19=2,"🥈 2nd Award",IF(K19=3,"🥉 3rd Award","")))) | M19: =IF(K19="","",K19+COUNTIF($I$13:I19,I19)-1)
A20: 8 | B20: =IF(Students!B13="","",Students!B13) | C20: =IF(Students!C13="","",Students!C13) | G20: =IF(OR(B20="",COUNTA(D20:F20)=0),"",SUM(D20:F20)) | H20: =IF(G20="","",$G$4) | I20: =IF(G20="","",G20/H20) | J20: =IF(I20="","",IF(I20>=0.9,"A+",IF(I20>=0.8,"A",IF(I20>=0.7,"B",IF(I20>=0.6,"C",IF(I20>=0.5,"D","F")))))) | K20: =IF(I20="","",RANK(I20,$I$13:$I$62,0)) | L20: =IF(K20="","",IF(K20=1,"🥇 1st Award",IF(K20=2,"🥈 2nd Award",IF(K20=3,"🥉 3rd Award","")))) | M20: =IF(K20="","",K20+COUNTIF($I$13:I20,I20)-1)
A21: 9 | B21: =IF(Students!B14="","",Students!B14) | C21: =IF(Students!C14="","",Students!C14) | G21: =IF(OR(B21="",COUNTA(D21:F21)=0),"",SUM(D21:F21)) | H21: =IF(G21="","",$G$4) | I21: =IF(G21="","",G21/H21) | J21: =IF(I21="","",IF(I21>=0.9,"A+",IF(I21>=0.8,"A",IF(I21>=0.7,"B",IF(I21>=0.6,"C",IF(I21>=0.5,"D","F")))))) | K21: =IF(I21="","",RANK(I21,$I$13:$I$62,0)) | L21: =IF(K21="","",IF(K21=1,"🥇 1st Award",IF(K21=2,"🥈 2nd Award",IF(K21=3,"🥉 3rd Award","")))) | M21: =IF(K21="","",K21+COUNTIF($I$13:I21,I21)-1)
A22: 10 | B22: =IF(Students!B15="","",Students!B15) | C22: =IF(Students!C15="","",Students!C15) | G22: =IF(OR(B22="",COUNTA(D22:F22)=0),"",SUM(D22:F22)) | H22: =IF(G22="","",$G$4) | I22: =IF(G22="","",G22/H22) | J22: =IF(I22="","",IF(I22>=0.9,"A+",IF(I22>=0.8,"A",IF(I22>=0.7,"B",IF(I22>=0.6,"C",IF(I22>=0.5,"D","F")))))) | K22: =IF(I22="","",RANK(I22,$I$13:$I$62,0)) | L22: =IF(K22="","",IF(K22=1,"🥇 1st Award",IF(K22=2,"🥈 2nd Award",IF(K22=3,"🥉 3rd Award","")))) | M22: =IF(K22="","",K22+COUNTIF($I$13:I22,I22)-1)
A23: 11 | B23: =IF(Students!B16="","",Students!B16) | C23: =IF(Students!C16="","",Students!C16) | G23: =IF(OR(B23="",COUNTA(D23:F23)=0),"",SUM(D23:F23)) | H23: =IF(G23="","",$G$4) | I23: =IF(G23="","",G23/H23) | J23: =IF(I23="","",IF(I23>=0.9,"A+",IF(I23>=0.8,"A",IF(I23>=0.7,"B",IF(I23>=0.6,"C",IF(I23>=0.5,"D","F")))))) | K23: =IF(I23="","",RANK(I23,$I$13:$I$62,0)) | L23: =IF(K23="","",IF(K23=1,"🥇 1st Award",IF(K23=2,"🥈 2nd Award",IF(K23=3,"🥉 3rd Award","")))) | M23: =IF(K23="","",K23+COUNTIF($I$13:I23,I23)-1)
A24: 12 | B24: =IF(Students!B17="","",Students!B17) | C24: =IF(Students!C17="","",Students!C17) | G24: =IF(OR(B24="",COUNTA(D24:F24)=0),"",SUM(D24:F24)) | H24: =IF(G24="","",$G$4) | I24: =IF(G24="","",G24/H24) | J24: =IF(I24="","",IF(I24>=0.9,"A+",IF(I24>=0.8,"A",IF(I24>=0.7,"B",IF(I24>=0.6,"C",IF(I24>=0.5,"D","F")))))) | K24: =IF(I24="","",RANK(I24,$I$13:$I$62,0)) | L24: =IF(K24="","",IF(K24=1,"🥇 1st Award",IF(K24=2,"🥈 2nd Award",IF(K24=3,"🥉 3rd Award","")))) | M24: =IF(K24="","",K24+COUNTIF($I$13:I24,I24)-1)
... A62: 50 | B62: =IF(Students!B55="","",Students!B55) | C62: =IF(Students!C55="","",Students!C55) | G62: =IF(OR(B62="",COUNTA(D62:F62)=0),"",SUM(D62:F62)) | H62: =IF(G62="","",$G$4) | I62: =IF(G62="","",G62/H62) | J62: =IF(I62="","",IF(I62>=0.9,"A+",IF(I62>=0.8,"A",IF(I62>=0.7,"B",IF(I62>=0.6,"C",IF(I62>=0.5,"D","F")))))) | K62: =IF(I62="","",RANK(I62,$I$13:$I$62,0)) | L62: =IF(K62="","",IF(K62=1,"🥇 1st Award",IF(K62=2,"🥈 2nd Award",IF(K62=3,"🥉 3rd Award","")))) | M62: =IF(K62="","",K62+COUNTIF($I$13:I62,I62)-1)

Sheet Com Nov 2026
A1: FUTURE TALENT ACADEMY JAMSHORO
A2: Computer Class — Monthly Marksheet — November 2026
D3: Test 1 | E3: Test 2 | F3: Test 3 | G3: Out of
A4: Teacher: Sir Nazeer Ahmed Jamali | C4: Total marks of each test → | D4: 50 | E4: 50 | F4: 50 | G4: =SUM(D4:F4) -> 150
A6: 🏆 TOP 3 — AWARD WINNERS
A7: Pos. | B7: Student Name | F7: Percentage | H7: Grade | J7: Award
A8: =IF(IFERROR(INDEX($K$13:$K$62,MATCH(1,$M$13:$M$62,0))<=3,FALSE()),INDEX($K$13:$K$62,MATCH(1,$M$13:$M$62,0)),"") | B8: =IF(IFERROR(INDEX($K$13:$K$62,MATCH(1,$M$13:$M$62,0))<=3,FALSE()),INDEX($B$13:$B$62,MATCH(1,$M$13:$M$62,0)),"") | F8: =IF(IFERROR(INDEX($K$13:$K$62,MATCH(1,$M$13:$M$62,0))<=3,FALSE()),INDEX($I$13:$I$62,MATCH(1,$M$13:$M$62,0)),"") | H8: =IF(IFERROR(INDEX($K$13:$K$62,MATCH(1,$M$13:$M$62,0))<=3,FALSE()),INDEX($J$13:$J$62,MATCH(1,$M$13:$M$62,0)),"") | J8: =IF(IFERROR(INDEX($K$13:$K$62,MATCH(1,$M$13:$M$62,0))<=3,FALSE()),INDEX($L$13:$L$62,MATCH(1,$M$13:$M$62,0)),"")
A9: =IF(IFERROR(INDEX($K$13:$K$62,MATCH(2,$M$13:$M$62,0))<=3,FALSE()),INDEX($K$13:$K$62,MATCH(2,$M$13:$M$62,0)),"") | B9: =IF(IFERROR(INDEX($K$13:$K$62,MATCH(2,$M$13:$M$62,0))<=3,FALSE()),INDEX($B$13:$B$62,MATCH(2,$M$13:$M$62,0)),"") | F9: =IF(IFERROR(INDEX($K$13:$K$62,MATCH(2,$M$13:$M$62,0))<=3,FALSE()),INDEX($I$13:$I$62,MATCH(2,$M$13:$M$62,0)),"") | H9: =IF(IFERROR(INDEX($K$13:$K$62,MATCH(2,$M$13:$M$62,0))<=3,FALSE()),INDEX($J$13:$J$62,MATCH(2,$M$13:$M$62,0)),"") | J9: =IF(IFERROR(INDEX($K$13:$K$62,MATCH(2,$M$13:$M$62,0))<=3,FALSE()),INDEX($L$13:$L$62,MATCH(2,$M$13:$M$62,0)),"")
A10: =IF(IFERROR(INDEX($K$13:$K$62,MATCH(3,$M$13:$M$62,0))<=3,FALSE()),INDEX($K$13:$K$62,MATCH(3,$M$13:$M$62,0)),"") | B10: =IF(IFERROR(INDEX($K$13:$K$62,MATCH(3,$M$13:$M$62,0))<=3,FALSE()),INDEX($B$13:$B$62,MATCH(3,$M$13:$M$62,0)),"") | F10: =IF(IFERROR(INDEX($K$13:$K$62,MATCH(3,$M$13:$M$62,0))<=3,FALSE()),INDEX($I$13:$I$62,MATCH(3,$M$13:$M$62,0)),"") | H10: =IF(IFERROR(INDEX($K$13:$K$62,MATCH(3,$M$13:$M$62,0))<=3,FALSE()),INDEX($J$13:$J$62,MATCH(3,$M$13:$M$62,0)),"") | J10: =IF(IFERROR(INDEX($K$13:$K$62,MATCH(3,$M$13:$M$62,0))<=3,FALSE()),INDEX($L$13:$L$62,MATCH(3,$M$13:$M$62,0)),"")
A11: =IF(IFERROR(INDEX($K$13:$K$62,MATCH(4,$M$13:$M$62,0))<=3,FALSE()),INDEX($K$13:$K$62,MATCH(4,$M$13:$M$62,0)),"") | B11: =IF(IFERROR(INDEX($K$13:$K$62,MATCH(4,$M$13:$M$62,0))<=3,FALSE()),INDEX($B$13:$B$62,MATCH(4,$M$13:$M$62,0)),"") | F11: =IF(IFERROR(INDEX($K$13:$K$62,MATCH(4,$M$13:$M$62,0))<=3,FALSE()),INDEX($I$13:$I$62,MATCH(4,$M$13:$M$62,0)),"") | H11: =IF(IFERROR(INDEX($K$13:$K$62,MATCH(4,$M$13:$M$62,0))<=3,FALSE()),INDEX($J$13:$J$62,MATCH(4,$M$13:$M$62,0)),"") | J11: =IF(IFERROR(INDEX($K$13:$K$62,MATCH(4,$M$13:$M$62,0))<=3,FALSE()),INDEX($L$13:$L$62,MATCH(4,$M$13:$M$62,0)),"")
A12: S.No | B12: Student Name | C12: Father Name | D12: Test 1 | E12: Test 2 | F12: Test 3 | G12: Total | H12: Out of | I12: Percentage | J12: Grade | K12: Position | L12: Award | M12: Order
A13: 1 | B13: =IF(Students!F6="","",Students!F6) -> Sara Bibi (example) | C13: =IF(Students!G6="","",Students!G6) -> Abdul Rehman | G13: =IF(OR(B13="",COUNTA(D13:F13)=0),"",SUM(D13:F13)) | H13: =IF(G13="","",$G$4) | I13: =IF(G13="","",G13/H13) | J13: =IF(I13="","",IF(I13>=0.9,"A+",IF(I13>=0.8,"A",IF(I13>=0.7,"B",IF(I13>=0.6,"C",IF(I13>=0.5,"D","F")))))) | K13: =IF(I13="","",RANK(I13,$I$13:$I$62,0)) | L13: =IF(K13="","",IF(K13=1,"🥇 1st Award",IF(K13=2,"🥈 2nd Award",IF(K13=3,"🥉 3rd Award","")))) | M13: =IF(K13="","",K13+COUNTIF($I$13:I13,I13)-1)
A14: 2 | B14: =IF(Students!F7="","",Students!F7) | C14: =IF(Students!G7="","",Students!G7) | G14: =IF(OR(B14="",COUNTA(D14:F14)=0),"",SUM(D14:F14)) | H14: =IF(G14="","",$G$4) | I14: =IF(G14="","",G14/H14) | J14: =IF(I14="","",IF(I14>=0.9,"A+",IF(I14>=0.8,"A",IF(I14>=0.7,"B",IF(I14>=0.6,"C",IF(I14>=0.5,"D","F")))))) | K14: =IF(I14="","",RANK(I14,$I$13:$I$62,0)) | L14: =IF(K14="","",IF(K14=1,"🥇 1st Award",IF(K14=2,"🥈 2nd Award",IF(K14=3,"🥉 3rd Award","")))) | M14: =IF(K14="","",K14+COUNTIF($I$13:I14,I14)-1)
A15: 3 | B15: =IF(Students!F8="","",Students!F8) | C15: =IF(Students!G8="","",Students!G8) | G15: =IF(OR(B15="",COUNTA(D15:F15)=0),"",SUM(D15:F15)) | H15: =IF(G15="","",$G$4) | I15: =IF(G15="","",G15/H15) | J15: =IF(I15="","",IF(I15>=0.9,"A+",IF(I15>=0.8,"A",IF(I15>=0.7,"B",IF(I15>=0.6,"C",IF(I15>=0.5,"D","F")))))) | K15: =IF(I15="","",RANK(I15,$I$13:$I$62,0)) | L15: =IF(K15="","",IF(K15=1,"🥇 1st Award",IF(K15=2,"🥈 2nd Award",IF(K15=3,"🥉 3rd Award","")))) | M15: =IF(K15="","",K15+COUNTIF($I$13:I15,I15)-1)
A16: 4 | B16: =IF(Students!F9="","",Students!F9) | C16: =IF(Students!G9="","",Students!G9) | G16: =IF(OR(B16="",COUNTA(D16:F16)=0),"",SUM(D16:F16)) | H16: =IF(G16="","",$G$4) | I16: =IF(G16="","",G16/H16) | J16: =IF(I16="","",IF(I16>=0.9,"A+",IF(I16>=0.8,"A",IF(I16>=0.7,"B",IF(I16>=0.6,"C",IF(I16>=0.5,"D","F")))))) | K16: =IF(I16="","",RANK(I16,$I$13:$I$62,0)) | L16: =IF(K16="","",IF(K16=1,"🥇 1st Award",IF(K16=2,"🥈 2nd Award",IF(K16=3,"🥉 3rd Award","")))) | M16: =IF(K16="","",K16+COUNTIF($I$13:I16,I16)-1)
A17: 5 | B17: =IF(Students!F10="","",Students!F10) | C17: =IF(Students!G10="","",Students!G10) | G17: =IF(OR(B17="",COUNTA(D17:F17)=0),"",SUM(D17:F17)) | H17: =IF(G17="","",$G$4) | I17: =IF(G17="","",G17/H17) | J17: =IF(I17="","",IF(I17>=0.9,"A+",IF(I17>=0.8,"A",IF(I17>=0.7,"B",IF(I17>=0.6,"C",IF(I17>=0.5,"D","F")))))) | K17: =IF(I17="","",RANK(I17,$I$13:$I$62,0)) | L17: =IF(K17="","",IF(K17=1,"🥇 1st Award",IF(K17=2,"🥈 2nd Award",IF(K17=3,"🥉 3rd Award","")))) | M17: =IF(K17="","",K17+COUNTIF($I$13:I17,I17)-1)
A18: 6 | B18: =IF(Students!F11="","",Students!F11) | C18: =IF(Students!G11="","",Students!G11) | G18: =IF(OR(B18="",COUNTA(D18:F18)=0),"",SUM(D18:F18)) | H18: =IF(G18="","",$G$4) | I18: =IF(G18="","",G18/H18) | J18: =IF(I18="","",IF(I18>=0.9,"A+",IF(I18>=0.8,"A",IF(I18>=0.7,"B",IF(I18>=0.6,"C",IF(I18>=0.5,"D","F")))))) | K18: =IF(I18="","",RANK(I18,$I$13:$I$62,0)) | L18: =IF(K18="","",IF(K18=1,"🥇 1st Award",IF(K18=2,"🥈 2nd Award",IF(K18=3,"🥉 3rd Award","")))) | M18: =IF(K18="","",K18+COUNTIF($I$13:I18,I18)-1)
A19: 7 | B19: =IF(Students!F12="","",Students!F12) | C19: =IF(Students!G12="","",Students!G12) | G19: =IF(OR(B19="",COUNTA(D19:F19)=0),"",SUM(D19:F19)) | H19: =IF(G19="","",$G$4) | I19: =IF(G19="","",G19/H19) | J19: =IF(I19="","",IF(I19>=0.9,"A+",IF(I19>=0.8,"A",IF(I19>=0.7,"B",IF(I19>=0.6,"C",IF(I19>=0.5,"D","F")))))) | K19: =IF(I19="","",RANK(I19,$I$13:$I$62,0)) | L19: =IF(K19="","",IF(K19=1,"🥇 1st Award",IF(K19=2,"🥈 2nd Award",IF(K19=3,"🥉 3rd Award","")))) | M19: =IF(K19="","",K19+COUNTIF($I$13:I19,I19)-1)
A20: 8 | B20: =IF(Students!F13="","",Students!F13) | C20: =IF(Students!G13="","",Students!G13) | G20: =IF(OR(B20="",COUNTA(D20:F20)=0),"",SUM(D20:F20)) | H20: =IF(G20="","",$G$4) | I20: =IF(G20="","",G20/H20) | J20: =IF(I20="","",IF(I20>=0.9,"A+",IF(I20>=0.8,"A",IF(I20>=0.7,"B",IF(I20>=0.6,"C",IF(I20>=0.5,"D","F")))))) | K20: =IF(I20="","",RANK(I20,$I$13:$I$62,0)) | L20: =IF(K20="","",IF(K20=1,"🥇 1st Award",IF(K20=2,"🥈 2nd Award",IF(K20=3,"🥉 3rd Award","")))) | M20: =IF(K20="","",K20+COUNTIF($I$13:I20,I20)-1)
A21: 9 | B21: =IF(Students!F14="","",Students!F14) | C21: =IF(Students!G14="","",Students!G14) | G21: =IF(OR(B21="",COUNTA(D21:F21)=0),"",SUM(D21:F21)) | H21: =IF(G21="","",$G$4) | I21: =IF(G21="","",G21/H21) | J21: =IF(I21="","",IF(I21>=0.9,"A+",IF(I21>=0.8,"A",IF(I21>=0.7,"B",IF(I21>=0.6,"C",IF(I21>=0.5,"D","F")))))) | K21: =IF(I21="","",RANK(I21,$I$13:$I$62,0)) | L21: =IF(K21="","",IF(K21=1,"🥇 1st Award",IF(K21=2,"🥈 2nd Award",IF(K21=3,"🥉 3rd Award","")))) | M21: =IF(K21="","",K21+COUNTIF($I$13:I21,I21)-1)
A22: 10 | B22: =IF(Students!F15="","",Students!F15) | C22: =IF(Students!G15="","",Students!G15) | G22: =IF(OR(B22="",COUNTA(D22:F22)=0),"",SUM(D22:F22)) | H22: =IF(G22="","",$G$4) | I22: =IF(G22="","",G22/H22) | J22: =IF(I22="","",IF(I22>=0.9,"A+",IF(I22>=0.8,"A",IF(I22>=0.7,"B",IF(I22>=0.6,"C",IF(I22>=0.5,"D","F")))))) | K22: =IF(I22="","",RANK(I22,$I$13:$I$62,0)) | L22: =IF(K22="","",IF(K22=1,"🥇 1st Award",IF(K22=2,"🥈 2nd Award",IF(K22=3,"🥉 3rd Award","")))) | M22: =IF(K22="","",K22+COUNTIF($I$13:I22,I22)-1)
A23: 11 | B23: =IF(Students!F16="","",Students!F16) | C23: =IF(Students!G16="","",Students!G16) | G23: =IF(OR(B23="",COUNTA(D23:F23)=0),"",SUM(D23:F23)) | H23: =IF(G23="","",$G$4) | I23: =IF(G23="","",G23/H23) | J23: =IF(I23="","",IF(I23>=0.9,"A+",IF(I23>=0.8,"A",IF(I23>=0.7,"B",IF(I23>=0.6,"C",IF(I23>=0.5,"D","F")))))) | K23: =IF(I23="","",RANK(I23,$I$13:$I$62,0)) | L23: =IF(K23="","",IF(K23=1,"🥇 1st Award",IF(K23=2,"🥈 2nd Award",IF(K23=3,"🥉 3rd Award","")))) | M23: =IF(K23="","",K23+COUNTIF($I$13:I23,I23)-1)
A24: 12 | B24: =IF(Students!F17="","",Students!F17) | C24: =IF(Students!G17="","",Students!G17) | G24: =IF(OR(B24="",COUNTA(D24:F24)=0),"",SUM(D24:F24)) | H24: =IF(G24="","",$G$4) | I24: =IF(G24="","",G24/H24) | J24: =IF(I24="","",IF(I24>=0.9,"A+",IF(I24>=0.8,"A",IF(I24>=0.7,"B",IF(I24>=0.6,"C",IF(I24>=0.5,"D","F")))))) | K24: =IF(I24="","",RANK(I24,$I$13:$I$62,0)) | L24: =IF(K24="","",IF(K24=1,"🥇 1st Award",IF(K24=2,"🥈 2nd Award",IF(K24=3,"🥉 3rd Award","")))) | M24: =IF(K24="","",K24+COUNTIF($I$13:I24,I24)-1)
... A62: 50 | B62: =IF(Students!F55="","",Students!F55) | C62: =IF(Students!G55="","",Students!G55) | G62: =IF(OR(B62="",COUNTA(D62:F62)=0),"",SUM(D62:F62)) | H62: =IF(G62="","",$G$4) | I62: =IF(G62="","",G62/H62) | J62: =IF(I62="","",IF(I62>=0.9,"A+",IF(I62>=0.8,"A",IF(I62>=0.7,"B",IF(I62>=0.6,"C",IF(I62>=0.5,"D","F")))))) | K62: =IF(I62="","",RANK(I62,$I$13:$I$62,0)) | L62: =IF(K62="","",IF(K62=1,"🥇 1st Award",IF(K62=2,"🥈 2nd Award",IF(K62=3,"🥉 3rd Award","")))) | M62: =IF(K62="","",K62+COUNTIF($I$13:I62,I62)-1)

Sheet Eng Dec 2026
A1: FUTURE TALENT ACADEMY JAMSHORO
A2: English Class — Monthly Marksheet — December 2026
D3: Test 1 | E3: Test 2 | F3: Test 3 | G3: Out of
A4: Teacher: Sir Sajjad Ali Birhmani | C4: Total marks of each test → | D4: 50 | E4: 50 | F4: 50 | G4: =SUM(D4:F4) -> 150
A6: 🏆 TOP 3 — AWARD WINNERS
A7: Pos. | B7: Student Name | F7: Percentage | H7: Grade | J7: Award
A8: =IF(IFERROR(INDEX($K$13:$K$62,MATCH(1,$M$13:$M$62,0))<=3,FALSE()),INDEX($K$13:$K$62,MATCH(1,$M$13:$M$62,0)),"") | B8: =IF(IFERROR(INDEX($K$13:$K$62,MATCH(1,$M$13:$M$62,0))<=3,FALSE()),INDEX($B$13:$B$62,MATCH(1,$M$13:$M$62,0)),"") | F8: =IF(IFERROR(INDEX($K$13:$K$62,MATCH(1,$M$13:$M$62,0))<=3,FALSE()),INDEX($I$13:$I$62,MATCH(1,$M$13:$M$62,0)),"") | H8: =IF(IFERROR(INDEX($K$13:$K$62,MATCH(1,$M$13:$M$62,0))<=3,FALSE()),INDEX($J$13:$J$62,MATCH(1,$M$13:$M$62,0)),"") | J8: =IF(IFERROR(INDEX($K$13:$K$62,MATCH(1,$M$13:$M$62,0))<=3,FALSE()),INDEX($L$13:$L$62,MATCH(1,$M$13:$M$62,0)),"")
A9: =IF(IFERROR(INDEX($K$13:$K$62,MATCH(2,$M$13:$M$62,0))<=3,FALSE()),INDEX($K$13:$K$62,MATCH(2,$M$13:$M$62,0)),"") | B9: =IF(IFERROR(INDEX($K$13:$K$62,MATCH(2,$M$13:$M$62,0))<=3,FALSE()),INDEX($B$13:$B$62,MATCH(2,$M$13:$M$62,0)),"") | F9: =IF(IFERROR(INDEX($K$13:$K$62,MATCH(2,$M$13:$M$62,0))<=3,FALSE()),INDEX($I$13:$I$62,MATCH(2,$M$13:$M$62,0)),"") | H9: =IF(IFERROR(INDEX($K$13:$K$62,MATCH(2,$M$13:$M$62,0))<=3,FALSE()),INDEX($J$13:$J$62,MATCH(2,$M$13:$M$62,0)),"") | J9: =IF(IFERROR(INDEX($K$13:$K$62,MATCH(2,$M$13:$M$62,0))<=3,FALSE()),INDEX($L$13:$L$62,MATCH(2,$M$13:$M$62,0)),"")
A10: =IF(IFERROR(INDEX($K$13:$K$62,MATCH(3,$M$13:$M$62,0))<=3,FALSE()),INDEX($K$13:$K$62,MATCH(3,$M$13:$M$62,0)),"") | B10: =IF(IFERROR(INDEX($K$13:$K$62,MATCH(3,$M$13:$M$62,0))<=3,FALSE()),INDEX($B$13:$B$62,MATCH(3,$M$13:$M$62,0)),"") | F10: =IF(IFERROR(INDEX($K$13:$K$62,MATCH(3,$M$13:$M$62,0))<=3,FALSE()),INDEX($I$13:$I$62,MATCH(3,$M$13:$M$62,0)),"") | H10: =IF(IFERROR(INDEX($K$13:$K$62,MATCH(3,$M$13:$M$62,0))<=3,FALSE()),INDEX($J$13:$J$62,MATCH(3,$M$13:$M$62,0)),"") | J10: =IF(IFERROR(INDEX($K$13:$K$62,MATCH(3,$M$13:$M$62,0))<=3,FALSE()),INDEX($L$13:$L$62,MATCH(3,$M$13:$M$62,0)),"")
A11: =IF(IFERROR(INDEX($K$13:$K$62,MATCH(4,$M$13:$M$62,0))<=3,FALSE()),INDEX($K$13:$K$62,MATCH(4,$M$13:$M$62,0)),"") | B11: =IF(IFERROR(INDEX($K$13:$K$62,MATCH(4,$M$13:$M$62,0))<=3,FALSE()),INDEX($B$13:$B$62,MATCH(4,$M$13:$M$62,0)),"") | F11: =IF(IFERROR(INDEX($K$13:$K$62,MATCH(4,$M$13:$M$62,0))<=3,FALSE()),INDEX($I$13:$I$62,MATCH(4,$M$13:$M$62,0)),"") | H11: =IF(IFERROR(INDEX($K$13:$K$62,MATCH(4,$M$13:$M$62,0))<=3,FALSE()),INDEX($J$13:$J$62,MATCH(4,$M$13:$M$62,0)),"") | J11: =IF(IFERROR(INDEX($K$13:$K$62,MATCH(4,$M$13:$M$62,0))<=3,FALSE()),INDEX($L$13:$L$62,MATCH(4,$M$13:$M$62,0)),"")
A12: S.No | B12: Student Name | C12: Father Name | D12: Test 1 | E12: Test 2 | F12: Test 3 | G12: Total | H12: Out of | I12: Percentage | J12: Grade | K12: Position | L12: Award | M12: Order
A13: 1 | B13: =IF(Students!B6="","",Students!B6) -> Ali Ahmed (example) | C13: =IF(Students!C6="","",Students!C6) -> Ahmed Khan | G13: =IF(OR(B13="",COUNTA(D13:F13)=0),"",SUM(D13:F13)) | H13: =IF(G13="","",$G$4) | I13: =IF(G13="","",G13/H13) | J13: =IF(I13="","",IF(I13>=0.9,"A+",IF(I13>=0.8,"A",IF(I13>=0.7,"B",IF(I13>=0.6,"C",IF(I13>=0.5,"D","F")))))) | K13: =IF(I13="","",RANK(I13,$I$13:$I$62,0)) | L13: =IF(K13="","",IF(K13=1,"🥇 1st Award",IF(K13=2,"🥈 2nd Award",IF(K13=3,"🥉 3rd Award","")))) | M13: =IF(K13="","",K13+COUNTIF($I$13:I13,I13)-1)
