Workbook

Sheet Setup
A1: Future Talent Academy Jamshoro — Setup
A2: Fill in the yellow cells once. Every month sheet uses these values.
A4: Academy Name | B4: Future Talent Academy Jamshoro
A5: English Teacher Name
A6: Computer Teacher Name | B6: Sir Nazeer Ahmed Jamali
A8: English Class Fixed Fee | B8: 2000
A9: Computer Class Fixed Fee | B9: 2000
A11: English Teacher Share | B11: 0.5
A12: Computer Teacher Share | B12: 0.5
A13: Academy Share of Other Fees | B13: 1
A15: How it works
A16: 1. Students sheet: add each student once (keep the same order; add new students at the bottom).
A17: 2. Each month sheet (Oct 2026, Nov 2026 …) pulls names and fees automatically.
A18: 3. Each month, type only the AMOUNT the student paid, and any certificate / test paper fee charged.
A19: 4. Unpaid balance carries forward to the next month's 'Previous Due' column, separately for each fee type.
A20: 5. Teacher and academy shares are worked out from the money actually collected that month.

Sheet Students
A1: Student List — Enrolment & Monthly Fees
A2: Choose Yes/No for each class. The fee fills in from Setup; for a student who pays less, choose 1500 or 1000 (or type an amount).
A4: Serial No | B4: Student Name | C4: Father Name | D4: English Class | E4: English Fee | F4: Computer Class | G4: Computer Fee
A5: 1 | B5: Ali Ahmed (example) | C5: Ahmed Khan | D5: Yes | E5: =IF(D5="Yes",Setup!$B$8,"") -> 2000 | F5: Yes | G5: 1500
A6: 2 | E6: =IF(D6="Yes",Setup!$B$8,"") | G6: =IF(F6="Yes",Setup!$B$9,"")
A7: 3 | E7: =IF(D7="Yes",Setup!$B$8,"") | G7: =IF(F7="Yes",Setup!$B$9,"")
A8: 4 | E8: =IF(D8="Yes",Setup!$B$8,"") | G8: =IF(F8="Yes",Setup!$B$9,"")
A9: 5 | E9: =IF(D9="Yes",Setup!$B$8,"") | G9: =IF(F9="Yes",Setup!$B$9,"")
A10: 6 | E10: =IF(D10="Yes",Setup!$B$8,"") | G10: =IF(F10="Yes",Setup!$B$9,"")
A11: 7 | E11: =IF(D11="Yes",Setup!$B$8,"") | G11: =IF(F11="Yes",Setup!$B$9,"")
A12: 8 | E12: =IF(D12="Yes",Setup!$B$8,"") | G12: =IF(F12="Yes",Setup!$B$9,"")
A13: 9 | E13: =IF(D13="Yes",Setup!$B$8,"") | G13: =IF(F13="Yes",Setup!$B$9,"")
A14: 10 | E14: =IF(D14="Yes",Setup!$B$8,"") | G14: =IF(F14="Yes",Setup!$B$9,"")
A15: 11 | E15: =IF(D15="Yes",Setup!$B$8,"") | G15: =IF(F15="Yes",Setup!$B$9,"")
A16: 12 | E16: =IF(D16="Yes",Setup!$B$8,"") | G16: =IF(F16="Yes",Setup!$B$9,"")
A17: 13 | E17: =IF(D17="Yes",Setup!$B$8,"") | G17: =IF(F17="Yes",Setup!$B$9,"")
... A104: 100 | E104: =IF(D104="Yes",Setup!$B$8,"") | G104: =IF(F104="Yes",Setup!$B$9,"")

Sheet Oct 2026
A1: Future Talent Academy Jamshoro — Fee Register: October 2026
A2: Yellow cells: type the amount paid and any certificate / test paper fee. Previous dues come from the last month automatically.
A4: ENGLISH TEACHER | G4: COMPUTER TEACHER | M4: ACADEMY
A5: Name | C5: =IF(Setup!B5="","(enter name in Setup)",Setup!B5) -> (enter name in Setup) | G5: Name | I5: =Setup!B6 -> Sir Nazeer Ahmed Jamali | M5: From English | O5: =E114*(1-Setup!B11) -> 1000
A6: Share % | C6: =Setup!B11 -> 0.5 | G6: Share % | I6: =Setup!B12 -> 0.5 | M6: From Computer | O6: =I114*(1-Setup!B12) -> 0
A7: Amount to Receive | C7: =E114*Setup!B11 -> 1000 | G7: Amount to Receive | I7: =I114*Setup!B12 -> 0 | M7: From Other Fees | O7: =N114*Setup!B13 -> 0
M8: Total to Academy | O8: =SUM(O5:O7) -> 1000
A10: MONTH SUMMARY
A11: Previous Dues | C11: =C114+G114+K114 -> 0 | E11: This Month Charges | G11: =D114+H114+L114+M114 -> 3700 | I11: Collected | K11: =E114+I114+N114 -> 2000 | M11: Outstanding Now | O11: =P114 -> 1700
C12: ENGLISH CLASS | G12: COMPUTER CLASS | K12: OTHER FEES (Certificate / Test Paper) | P12: TOTAL
A13: Serial No | B13: Student Name | C13: Previous Due | D13: This Month Fee | E13: Paid | F13: Balance | G13: Previous Due | H13: This Month Fee | I13: Paid | J13: Balance | K13: Previous Due | L13: Certificate Fee | M13: Test Paper Fee | N13: Paid | O13: Balance | P13: Total Due Now | Q13: Status
A14: 1 | B14: =IF(Students!B5="","",Students!B5) -> Ali Ahmed (example) | D14: =IF(Students!D5="Yes",N(Students!E5),0) -> 2000 | E14: 2000 | F14: =N(C14)+N(D14)-N(E14) -> 0 | H14: =IF(Students!F5="Yes",N(Students!G5),0) -> 1500 | J14: =N(G14)+N(H14)-N(I14) -> 1500 | M14: 200 | O14: =N(K14)+N(L14)+N(M14)-N(N14) -> 200 | P14: =F14+J14+O14 -> 1700 | Q14: =IF(B14="","",IF(P14<=0,"Clear",IF(E14+I14+N14>0,"Partial","Due"))) -> Partial
A15: 2 | B15: =IF(Students!B6="","",Students!B6) | D15: =IF(Students!D6="Yes",N(Students!E6),0) -> 0 | F15: =N(C15)+N(D15)-N(E15) -> 0 | H15: =IF(Students!F6="Yes",N(Students!G6),0) -> 0 | J15: =N(G15)+N(H15)-N(I15) -> 0 | O15: =N(K15)+N(L15)+N(M15)-N(N15) -> 0 | P15: =F15+J15+O15 -> 0 | Q15: =IF(B15="","",IF(P15<=0,"Clear",IF(E15+I15+N15>0,"Partial","Due")))
A16: 3 | B16: =IF(Students!B7="","",Students!B7) | D16: =IF(Students!D7="Yes",N(Students!E7),0) -> 0 | F16: =N(C16)+N(D16)-N(E16) -> 0 | H16: =IF(Students!F7="Yes",N(Students!G7),0) -> 0 | J16: =N(G16)+N(H16)-N(I16) -> 0 | O16: =N(K16)+N(L16)+N(M16)-N(N16) -> 0 | P16: =F16+J16+O16 -> 0 | Q16: =IF(B16="","",IF(P16<=0,"Clear",IF(E16+I16+N16>0,"Partial","Due")))
A17: 4 | B17: =IF(Students!B8="","",Students!B8) | D17: =IF(Students!D8="Yes",N(Students!E8),0) -> 0 | F17: =N(C17)+N(D17)-N(E17) -> 0 | H17: =IF(Students!F8="Yes",N(Students!G8),0) -> 0 | J17: =N(G17)+N(H17)-N(I17) -> 0 | O17: =N(K17)+N(L17)+N(M17)-N(N17) -> 0 | P17: =F17+J17+O17 -> 0 | Q17: =IF(B17="","",IF(P17<=0,"Clear",IF(E17+I17+N17>0,"Partial","Due")))
A18: 5 | B18: =IF(Students!B9="","",Students!B9) | D18: =IF(Students!D9="Yes",N(Students!E9),0) -> 0 | F18: =N(C18)+N(D18)-N(E18) -> 0 | H18: =IF(Students!F9="Yes",N(Students!G9),0) -> 0 | J18: =N(G18)+N(H18)-N(I18) -> 0 | O18: =N(K18)+N(L18)+N(M18)-N(N18) -> 0 | P18: =F18+J18+O18 -> 0 | Q18: =IF(B18="","",IF(P18<=0,"Clear",IF(E18+I18+N18>0,"Partial","Due")))
A19: 6 | B19: =IF(Students!B10="","",Students!B10) | D19: =IF(Students!D10="Yes",N(Students!E10),0) -> 0 | F19: =N(C19)+N(D19)-N(E19) -> 0 | H19: =IF(Students!F10="Yes",N(Students!G10),0) -> 0 | J19: =N(G19)+N(H19)-N(I19) -> 0 | O19: =N(K19)+N(L19)+N(M19)-N(N19) -> 0 | P19: =F19+J19+O19 -> 0 | Q19: =IF(B19="","",IF(P19<=0,"Clear",IF(E19+I19+N19>0,"Partial","Due")))
A20: 7 | B20: =IF(Students!B11="","",Students!B11) | D20: =IF(Students!D11="Yes",N(Students!E11),0) -> 0 | F20: =N(C20)+N(D20)-N(E20) -> 0 | H20: =IF(Students!F11="Yes",N(Students!G11),0) -> 0 | J20: =N(G20)+N(H20)-N(I20) -> 0 | O20: =N(K20)+N(L20)+N(M20)-N(N20) -> 0 | P20: =F20+J20+O20 -> 0 | Q20: =IF(B20="","",IF(P20<=0,"Clear",IF(E20+I20+N20>0,"Partial","Due")))
A21: 8 | B21: =IF(Students!B12="","",Students!B12) | D21: =IF(Students!D12="Yes",N(Students!E12),0) -> 0 | F21: =N(C21)+N(D21)-N(E21) -> 0 | H21: =IF(Students!F12="Yes",N(Students!G12),0) -> 0 | J21: =N(G21)+N(H21)-N(I21) -> 0 | O21: =N(K21)+N(L21)+N(M21)-N(N21) -> 0 | P21: =F21+J21+O21 -> 0 | Q21: =IF(B21="","",IF(P21<=0,"Clear",IF(E21+I21+N21>0,"Partial","Due")))
A22: 9 | B22: =IF(Students!B13="","",Students!B13) | D22: =IF(Students!D13="Yes",N(Students!E13),0) -> 0 | F22: =N(C22)+N(D22)-N(E22) -> 0 | H22: =IF(Students!F13="Yes",N(Students!G13),0) -> 0 | J22: =N(G22)+N(H22)-N(I22) -> 0 | O22: =N(K22)+N(L22)+N(M22)-N(N22) -> 0 | P22: =F22+J22+O22 -> 0 | Q22: =IF(B22="","",IF(P22<=0,"Clear",IF(E22+I22+N22>0,"Partial","Due")))
A23: 10 | B23: =IF(Students!B14="","",Students!B14) | D23: =IF(Students!D14="Yes",N(Students!E14),0) -> 0 | F23: =N(C23)+N(D23)-N(E23) -> 0 | H23: =IF(Students!F14="Yes",N(Students!G14),0) -> 0 | J23: =N(G23)+N(H23)-N(I23) -> 0 | O23: =N(K23)+N(L23)+N(M23)-N(N23) -> 0 | P23: =F23+J23+O23 -> 0 | Q23: =IF(B23="","",IF(P23<=0,"Clear",IF(E23+I23+N23>0,"Partial","Due")))
A24: 11 | B24: =IF(Students!B15="","",Students!B15) | D24: =IF(Students!D15="Yes",N(Students!E15),0) -> 0 | F24: =N(C24)+N(D24)-N(E24) -> 0 | H24: =IF(Students!F15="Yes",N(Students!G15),0) -> 0 | J24: =N(G24)+N(H24)-N(I24) -> 0 | O24: =N(K24)+N(L24)+N(M24)-N(N24) -> 0 | P24: =F24+J24+O24 -> 0 | Q24: =IF(B24="","",IF(P24<=0,"Clear",IF(E24+I24+N24>0,"Partial","Due")))
A25: 12 | B25: =IF(Students!B16="","",Students!B16) | D25: =IF(Students!D16="Yes",N(Students!E16),0) -> 0 | F25: =N(C25)+N(D25)-N(E25) -> 0 | H25: =IF(Students!F16="Yes",N(Students!G16),0) -> 0 | J25: =N(G25)+N(H25)-N(I25) -> 0 | O25: =N(K25)+N(L25)+N(M25)-N(N25) -> 0 | P25: =F25+J25+O25 -> 0 | Q25: =IF(B25="","",IF(P25<=0,"Clear",IF(E25+I25+N25>0,"Partial","Due")))
A26: 13 | B26: =IF(Students!B17="","",Students!B17) | D26: =IF(Students!D17="Yes",N(Students!E17),0) -> 0 | F26: =N(C26)+N(D26)-N(E26) -> 0 | H26: =IF(Students!F17="Yes",N(Students!G17),0) -> 0 | J26: =N(G26)+N(H26)-N(I26) -> 0 | O26: =N(K26)+N(L26)+N(M26)-N(N26) -> 0 | P26: =F26+J26+O26 -> 0 | Q26: =IF(B26="","",IF(P26<=0,"Clear",IF(E26+I26+N26>0,"Partial","Due")))
... A113: 100 | B113: =IF(Students!B104="","",Students!B104) | D113: =IF(Students!D104="Yes",N(Students!E104),0) -> 0 | F113: =N(C113)+N(D113)-N(E113) -> 0 | H113: =IF(Students!F104="Yes",N(Students!G104),0) -> 0 | J113: =N(G113)+N(H113)-N(I113) -> 0 | O113: =N(K113)+N(L113)+N(M113)-N(N113) -> 0 | P113: =F113+J113+O113 -> 0 | Q113: =IF(B113="","",IF(P113<=0,"Clear",IF(E113+I113+N113>0,"Partial","Due")))
A114: TOTAL | C114: =SUM(C14:C113) -> 0 | D114: =SUM(D14:D113) -> 2000 | E114: =SUM(E14:E113) -> 2000 | F114: =SUM(F14:F113) -> 0 | G114: =SUM(G14:G113) -> 0 | H114: =SUM(H14:H113) -> 1500 | I114: =SUM(I14:I113) -> 0 | J114: =SUM(J14:J113) -> 1500 | ... P114: =SUM(P14:P113) -> 1700 | Q114: =COUNTIF(Q14:Q113,"Due")+COUNTIF(Q14:Q113,"Partial")&" with dues" -> 1 with dues

Sheet Nov 2026
A1: Future Talent Academy Jamshoro — Fee Register: November 2026
A2: Yellow cells: type the amount paid and any certificate / test paper fee. Previous dues come from the last month automatically.
A4: ENGLISH TEACHER | G4: COMPUTER TEACHER | M4: ACADEMY
A5: Name | C5: =IF(Setup!B5="","(enter name in Setup)",Setup!B5) -> (enter name in Setup) | G5: Name | I5: =Setup!B6 -> Sir Nazeer Ahmed Jamali | M5: From English | O5: =E114*(1-Setup!B11) -> 0
A6: Share % | C6: =Setup!B11 -> 0.5 | G6: Share % | I6: =Setup!B12 -> 0.5 | M6: From Computer | O6: =I114*(1-Setup!B12) -> 0
A7: Amount to Receive | C7: =E114*Setup!B11 -> 0 | G7: Amount to Receive | I7: =I114*Setup!B12 -> 0 | M7: From Other Fees | O7: =N114*Setup!B13 -> 0
M8: Total to Academy | O8: =SUM(O5:O7) -> 0
A10: MONTH SUMMARY
A11: Previous Dues | C11: =C114+G114+K114 -> 1700 | E11: This Month Charges | G11: =D114+H114+L114+M114 -> 3500 | I11: Collected | K11: =E114+I114+N114 -> 0 | M11: Outstanding Now | O11: =P114 -> 5200
C12: ENGLISH CLASS | G12: COMPUTER CLASS | K12: OTHER FEES (Certificate / Test Paper) | P12: TOTAL
A13: Serial No | B13: Student Name | C13: Previous Due | D13: This Month Fee | E13: Paid | F13: Balance | G13: Previous Due | H13: This Month Fee | I13: Paid | J13: Balance | K13: Previous Due | L13: Certificate Fee | M13: Test Paper Fee | N13: Paid | O13: Balance | P13: Total Due Now | Q13: Status
A14: 1 | B14: =IF(Students!B5="","",Students!B5) -> Ali Ahmed (example) | C14: ='Oct 2026'!F14 -> 0 | D14: =IF(Students!D5="Yes",N(Students!E5),0) -> 2000 | F14: =N(C14)+N(D14)-N(E14) -> 2000 | G14: ='Oct 2026'!J14 -> 1500 | H14: =IF(Students!F5="Yes",N(Students!G5),0) -> 1500 | J14: =N(G14)+N(H14)-N(I14) -> 3000 | K14: ='Oct 2026'!O14 -> 200 | O14: =N(K14)+N(L14)+N(M14)-N(N14) -> 200 | P14: =F14+J14+O14 -> 5200 | Q14: =IF(B14="","",IF(P14<=0,"Clear",IF(E14+I14+N14>0,"Partial","Due"))) -> Due
A15: 2 | B15: =IF(Students!B6="","",Students!B6) | C15: ='Oct 2026'!F15 -> 0 | D15: =IF(Students!D6="Yes",N(Students!E6),0) -> 0 | F15: =N(C15)+N(D15)-N(E15) -> 0 | G15: ='Oct 2026'!J15 -> 0 | H15: =IF(Students!F6="Yes",N(Students!G6),0) -> 0 | J15: =N(G15)+N(H15)-N(I15) -> 0 | K15: ='Oct 2026'!O15 -> 0 | O15: =N(K15)+N(L15)+N(M15)-N(N15) -> 0 | P15: =F15+J15+O15 -> 0 | Q15: =IF(B15="","",IF(P15<=0,"Clear",IF(E15+I15+N15>0,"Partial","Due")))
A16: 3 | B16: =IF(Students!B7="","",Students!B7) | C16: ='Oct 2026'!F16 -> 0 | D16: =IF(Students!D7="Yes",N(Students!E7),0) -> 0 | F16: =N(C16)+N(D16)-N(E16) -> 0 | G16: ='Oct 2026'!J16 -> 0 | H16: =IF(Students!F7="Yes",N(Students!G7),0) -> 0 | J16: =N(G16)+N(H16)-N(I16) -> 0 | K16: ='Oct 2026'!O16 -> 0 | O16: =N(K16)+N(L16)+N(M16)-N(N16) -> 0 | P16: =F16+J16+O16 -> 0 | Q16: =IF(B16="","",IF(P16<=0,"Clear",IF(E16+I16+N16>0,"Partial","Due")))
A17: 4 | B17: =IF(Students!B8="","",Students!B8) | C17: ='Oct 2026'!F17 -> 0 | D17: =IF(Students!D8="Yes",N(Students!E8),0) -> 0 | F17: =N(C17)+N(D17)-N(E17) -> 0 | G17: ='Oct 2026'!J17 -> 0 | H17: =IF(Students!F8="Yes",N(Students!G8),0) -> 0 | J17: =N(G17)+N(H17)-N(I17) -> 0 | K17: ='Oct 2026'!O17 -> 0 | O17: =N(K17)+N(L17)+N(M17)-N(N17) -> 0 | P17: =F17+J17+O17 -> 0 | Q17: =IF(B17="","",IF(P17<=0,"Clear",IF(E17+I17+N17>0,"Partial","Due")))
A18: 5 | B18: =IF(Students!B9="","",Students!B9) | C18: ='Oct 2026'!F18 -> 0 | D18: =IF(Students!D9="Yes",N(Students!E9),0) -> 0 | F18: =N(C18)+N(D18)-N(E18) -> 0 | G18: ='Oct 2026'!J18 -> 0 | H18: =IF(Students!F9="Yes",N(Students!G9),0) -> 0 | J18: =N(G18)+N(H18)-N(I18) -> 0 | K18: ='Oct 2026'!O18 -> 0 | O18: =N(K18)+N(L18)+N(M18)-N(N18) -> 0 | P18: =F18+J18+O18 -> 0 | Q18: =IF(B18="","",IF(P18<=0,"Clear",IF(E18+I18+N18>0,"Partial","Due")))
A19: 6 | B19: =IF(Students!B10="","",Students!B10) | C19: ='Oct 2026'!F19 -> 0 | D19: =IF(Students!D10="Yes",N(Students!E10),0) -> 0 | F19: =N(C19)+N(D19)-N(E19) -> 0 | G19: ='Oct 2026'!J19 -> 0 | H19: =IF(Students!F10="Yes",N(Students!G10),0) -> 0 | J19: =N(G19)+N(H19)-N(I19) -> 0 | K19: ='Oct 2026'!O19 -> 0 | O19: =N(K19)+N(L19)+N(M19)-N(N19) -> 0 | P19: =F19+J19+O19 -> 0 | Q19: =IF(B19="","",IF(P19<=0,"Clear",IF(E19+I19+N19>0,"Partial","Due")))
A20: 7 | B20: =IF(Students!B11="","",Students!B11) | C20: ='Oct 2026'!F20 -> 0 | D20: =IF(Students!D11="Yes",N(Students!E11),0) -> 0 | F20: =N(C20)+N(D20)-N(E20) -> 0 | G20: ='Oct 2026'!J20 -> 0 | H20: =IF(Students!F11="Yes",N(Students!G11),0) -> 0 | J20: =N(G20)+N(H20)-N(I20) -> 0 | K20: ='Oct 2026'!O20 -> 0 | O20: =N(K20)+N(L20)+N(M20)-N(N20) -> 0 | P20: =F20+J20+O20 -> 0 | Q20: =IF(B20="","",IF(P20<=0,"Clear",IF(E20+I20+N20>0,"Partial","Due")))
A21: 8 | B21: =IF(Students!B12="","",Students!B12) | C21: ='Oct 2026'!F21 -> 0 | D21: =IF(Students!D12="Yes",N(Students!E12),0) -> 0 | F21: =N(C21)+N(D21)-N(E21) -> 0 | G21: ='Oct 2026'!J21 -> 0 | H21: =IF(Students!F12="Yes",N(Students!G12),0) -> 0 | J21: =N(G21)+N(H21)-N(I21) -> 0 | K21: ='Oct 2026'!O21 -> 0 | O21: =N(K21)+N(L21)+N(M21)-N(N21) -> 0 | P21: =F21+J21+O21 -> 0 | Q21: =IF(B21="","",IF(P21<=0,"Clear",IF(E21+I21+N21>0,"Partial","Due")))
A22: 9 | B22: =IF(Students!B13="","",Students!B13) | C22: ='Oct 2026'!F22 -> 0 | D22: =IF(Students!D13="Yes",N(Students!E13),0) -> 0 | F22: =N(C22)+N(D22)-N(E22) -> 0 | G22: ='Oct 2026'!J22 -> 0 | H22: =IF(Students!F13="Yes",N(Students!G13),0) -> 0 | J22: =N(G22)+N(H22)-N(I22) -> 0 | K22: ='Oct 2026'!O22 -> 0 | O22: =N(K22)+N(L22)+N(M22)-N(N22) -> 0 | P22: =F22+J22+O22 -> 0 | Q22: =IF(B22="","",IF(P22<=0,"Clear",IF(E22+I22+N22>0,"Partial","Due")))
A23: 10 | B23: =IF(Students!B14="","",Students!B14) | C23: ='Oct 2026'!F23 -> 0 | D23: =IF(Students!D14="Yes",N(Students!E14),0) -> 0 | F23: =N(C23)+N(D23)-N(E23) -> 0 | G23: ='Oct 2026'!J23 -> 0 | H23: =IF(Students!F14="Yes",N(Students!G14),0) -> 0 | J23: =N(G23)+N(H23)-N(I23) -> 0 | K23: ='Oct 2026'!O23 -> 0 | O23: =N(K23)+N(L23)+N(M23)-N(N23) -> 0 | P23: =F23+J23+O23 -> 0 | Q23: =IF(B23="","",IF(P23<=0,"Clear",IF(E23+I23+N23>0,"Partial","Due")))
A24: 11 | B24: =IF(Students!B15="","",Students!B15) | C24: ='Oct 2026'!F24 -> 0 | D24: =IF(Students!D15="Yes",N(Students!E15),0) -> 0 | F24: =N(C24)+N(D24)-N(E24) -> 0 | G24: ='Oct 2026'!J24 -> 0 | H24: =IF(Students!F15="Yes",N(Students!G15),0) -> 0 | J24: =N(G24)+N(H24)-N(I24) -> 0 | K24: ='Oct 2026'!O24 -> 0 | O24: =N(K24)+N(L24)+N(M24)-N(N24) -> 0 | P24: =F24+J24+O24 -> 0 | Q24: =IF(B24="","",IF(P24<=0,"Clear",IF(E24+I24+N24>0,"Partial","Due")))
A25: 12 | B25: =IF(Students!B16="","",Students!B16) | C25: ='Oct 2026'!F25 -> 0 | D25: =IF(Students!D16="Yes",N(Students!E16),0) -> 0 | F25: =N(C25)+N(D25)-N(E25) -> 0 | G25: ='Oct 2026'!J25 -> 0 | H25: =IF(Students!F16="Yes",N(Students!G16),0) -> 0 | J25: =N(G25)+N(H25)-N(I25) -> 0 | K25: ='Oct 2026'!O25 -> 0 | O25: =N(K25)+N(L25)+N(M25)-N(N25) -> 0 | P25: =F25+J25+O25 -> 0 | Q25: =IF(B25="","",IF(P25<=0,"Clear",IF(E25+I25+N25>0,"Partial","Due")))
... A113: 100 | B113: =IF(Students!B104="","",Students!B104) | C113: ='Oct 2026'!F113 -> 0 | D113: =IF(Students!D104="Yes",N(Students!E104),0) -> 0 | F113: =N(C113)+N(D113)-N(E113) -> 0 | G113: ='Oct 2026'!J113 -> 0 | H113: =IF(Students!F104="Yes",N(Students!G104),0) -> 0 | J113: =N(G113)+N(H113)-N(I113) -> 0 | K113: ='Oct 2026'!O113 -> 0 | O113: =N(K113)+N(L113)+N(M113)-N(N113) -> 0 | P113: =F113+J113+O113 -> 0 | Q113: =IF(B113="","",IF(P113<=0,"Clear",IF(E113+I113+N113>0,"Partial","Due")))
A114: TOTAL | C114: =SUM(C14:C113) -> 0 | D114: =SUM(D14:D113) -> 2000 | E114: =SUM(E14:E113) -> 0 | F114: =SUM(F14:F113) -> 2000 | G114: =SUM(G14:G113) -> 1500 | H114: =SUM(H14:H113) -> 1500 | I114: =SUM(I14:I113) -> 0 | J114: =SUM(J14:J113) -> 3000 | ... P114: =SUM(P14:P113) -> 5200 | Q114: =COUNTIF(Q14:Q113,"Due")+COUNTIF(Q14:Q113,"Partial")&" with dues" -> 1 with dues

Sheet Dec 2026
A1: Future Talent Academy Jamshoro — Fee Register: December 2026
A2: Yellow cells: type the amount paid and any certificate / test paper fee. Previous dues come from the last month automatically.
A4: ENGLISH TEACHER | G4: COMPUTER TEACHER | M4: ACADEMY
A5: Name | C5: =IF(Setup!B5="","(enter name in Setup)",Setup!B5) -> (enter name in Setup) | G5: Name | I5: =Setup!B6 -> Sir Nazeer Ahmed Jamali | M5: From English | O5: =E114*(1-Setup!B11) -> 0
A6: Share % | C6: =Setup!B11 -> 0.5 | G6: Share % | I6: =Setup!B12 -> 0.5 | M6: From Computer | O6: =I114*(1-Setup!B12) -> 0
A7: Amount to Receive | C7: =E114*Setup!B11 -> 0 | G7: Amount to Receive | I7: =I114*Setup!B12 -> 0 | M7: From Other Fees | O7: =N114*Setup!B13 -> 0
M8: Total to Academy | O8: =SUM(O5:O7) -> 0
A10: MONTH SUMMARY
A11: Previous Dues | C11: =C114+G114+K114 -> 5200 | E11: This Month Charges | G11: =D114+H114+L114+M114 -> 3500 | I11: Collected | K11: =E114+I114+N114 -> 0 | M11: Outstanding Now | O11: =P114 -> 8700
C12: ENGLISH CLASS | G12: COMPUTER CLASS | K12: OTHER FEES (Certificate / Test Paper) | P12: TOTAL
A13: Serial No | B13: Student Name | C13: Previous Due | D13: This Month Fee | E13: Paid | F13: Balance | G13: Previous Due | H13: This Month Fee | I13: Paid | J13: Balance | K13: Previous Due | L13: Certificate Fee | M13: Test Paper Fee | N13: Paid | O13: Balance | P13: Total Due Now | Q13: Status
A14: 1 | B14: =IF(Students!B5="","",Students!B5) -> Ali Ahmed (example) | C14: ='Nov 2026'!F14 -> 2000 | D14: =IF(Students!D5="Yes",N(Students!E5),0) -> 2000 | F14: =N(C14)+N(D14)-N(E14) -> 4000 | G14: ='Nov 2026'!J14 -> 3000 | H14: =IF(Students!F5="Yes",N(Students!G5),0) -> 1500 | J14: =N(G14)+N(H14)-N(I14) -> 4500 | K14: ='Nov 2026'!O14 -> 200 | O14: =N(K14)+N(L14)+N(M14)-N(N14) -> 200 | P14: =F14+J14+O14 -> 8700 | Q14: =IF(B14="","",IF(P14<=0,"Clear",IF(E14+I14+N14>0,"Partial","Due"))) -> Due
A15: 2 | B15: =IF(Students!B6="","",Students!B6) | C15: ='Nov 2026'!F15 -> 0 | D15: =IF(Students!D6="Yes",N(Students!E6),0) -> 0 | F15: =N(C15)+N(D15)-N(E15) -> 0 | G15: ='Nov 2026'!J15 -> 0 | H15: =IF(Students!F6="Yes",N(Students!G6),0) -> 0 | J15: =N(G15)+N(H15)-N(I15) -> 0 | K15: ='Nov 2026'!O15 -> 0 | O15: =N(K15)+N(L15)+N(M15)-N(N15) -> 0 | P15: =F15+J15+O15 -> 0 | Q15: =IF(B15="","",IF(P15<=0,"Clear",IF(E15+I15+N15>0,"Partial","Due")))
A16: 3 | B16: =IF(Students!B7="","",Students!B7) | C16: ='Nov 2026'!F16 -> 0 | D16: =IF(Students!D7="Yes",N(Students!E7),0) -> 0 | F16: =N(C16)+N(D16)-N(E16) -> 0 | G16: ='Nov 2026'!J16 -> 0 | H16: =IF(Students!F7="Yes",N(Students!G7),0) -> 0 | J16: =N(G16)+N(H16)-N(I16) -> 0 | K16: ='Nov 2026'!O16 -> 0 | O16: =N(K16)+N(L16)+N(M16)-N(N16) -> 0 | P16: =F16+J16+O16 -> 0 | Q16: =IF(B16="","",IF(P16<=0,"Clear",IF(E16+I16+N16>0,"Partial","Due")))
A17: 4 | B17: =IF(Students!B8="","",Students!B8) | C17: ='Nov 2026'!F17 -> 0 | D17: =IF(Students!D8="Yes",N(Students!E8),0) -> 0 | F17: =N(C17)+N(D17)-N(E17) -> 0 | G17: ='Nov 2026'!J17 -> 0 | H17: =IF(Students!F8="Yes",N(Students!G8),0) -> 0 | J17: =N(G17)+N(H17)-N(I17) -> 0 | K17: ='Nov 2026'!O17 -> 0 | O17: =N(K17)+N(L17)+N(M17)-N(N17) -> 0 | P17: =F17+J17+O17 -> 0 | Q17: =IF(B17="","",IF(P17<=0,"Clear",IF(E17+I17+N17>0,"Partial","Due")))
A18: 5 | B18: =IF(Students!B9="","",Students!B9) | C18: ='Nov 2026'!F18 -> 0 | D18: =IF(Students!D9="Yes",N(Students!E9),0) -> 0 | F18: =N(C18)+N(D18)-N(E18) -> 0 | G18: ='Nov 2026'!J18 -> 0 | H18: =IF(Students!F9="Yes",N(Students!G9),0) -> 0 | J18: =N(G18)+N(H18)-N(I18) -> 0 | K18: ='Nov 2026'!O18 -> 0 | O18: =N(K18)+N(L18)+N(M18)-N(N18) -> 0 | P18: =F18+J18+O18 -> 0 | Q18: =IF(B18="","",IF(P18<=0,"Clear",IF(E18+I18+N18>0,"Partial","Due")))
A19: 6 | B19: =IF(Students!B10="","",Students!B10) | C19: ='Nov 2026'!F19 -> 0 | D19: =IF(Students!D10="Yes",N(Students!E10),0) -> 0 | F19: =N(C19)+N(D19)-N(E19) -> 0 | G19: ='Nov 2026'!J19 -> 0 | H19: =IF(Students!F10="Yes",N(Students!G10),0) -> 0 | J19: =N(G19)+N(H19)-N(I19) -> 0 | K19: ='Nov 2026'!O19 -> 0 | O19: =N(K19)+N(L19)+N(M19)-N(N19) -> 0 | P19: =F19+J19+O19 -> 0 | Q19: =IF(B19="","",IF(P19<=0,"Clear",IF(E19+I19+N19>0,"Partial","Due")))
A20: 7 | B20: =IF(Students!B11="","",Students!B11) | C20: ='Nov 2026'!F20 -> 0 | D20: =IF(Students!D11="Yes",N(Students!E11),0) -> 0 | F20: =N(C20)+N(D20)-N(E20) -> 0 | G20: ='Nov 2026'!J20 -> 0 | H20: =IF(Students!F11="Yes",N(Students!G11),0) -> 0 | J20: =N(G20)+N(H20)-N(I20) -> 0 | K20: ='Nov 2026'!O20 -> 0 | O20: =N(K20)+N(L20)+N(M20)-N(N20) -> 0 | P20: =F20+J20+O20 -> 0 | Q20: =IF(B20="","",IF(P20<=0,"Clear",IF(E20+I20+N20>0,"Partial","Due")))
A21: 8 | B21: =IF(Students!B12="","",Students!B12) | C21: ='Nov 2026'!F21 -> 0 | D21: =IF(Students!D12="Yes",N(Students!E12),0) -> 0 | F21: =N(C21)+N(D21)-N(E21) -> 0 | G21: ='Nov 2026'!J21 -> 0 | H21: =IF(Students!F12="Yes",N(Students!G12),0) -> 0 | J21: =N(G21)+N(H21)-N(I21) -> 0 | K21: ='Nov 2026'!O21 -> 0 | O21: =N(K21)+N(L21)+N(M21)-N(N21) -> 0 | P21: =F21+J21+O21 -> 0 | Q21: =IF(B21="","",IF(P21<=0,"Clear",IF(E21+I21+N21>0,"Partial","Due")))
A22: 9 | B22: =IF(Students!B13="","",Students!B13) | C22: ='Nov 2026'!F22 -> 0 | D22: =IF(Students!D13="Yes",N(Students!E13),0) -> 0 | F22: =N(C22)+N(D22)-N(E22) -> 0 | G22: ='Nov 2026'!J22 -> 0 | H22: =IF(Students!F13="Yes",N(Students!G13),0) -> 0 | J22: =N(G22)+N(H22)-N(I22) -> 0 | K22: ='Nov 2026'!O22 -> 0 | O22: =N(K22)+N(L22)+N(M22)-N(N22) -> 0 | P22: =F22+J22+O22 -> 0 | Q22: =IF(B22="","",IF(P22<=0,"Clear",IF(E22+I22+N22>0,"Partial","Due")))
A23: 10 | B23: =IF(Students!B14="","",Students!B14) | C23: ='Nov 2026'!F23 -> 0 | D23: =IF(Students!D14="Yes",N(Students!E14),0) -> 0 | F23: =N(C23)+N(D23)-N(E23) -> 0 | G23: ='Nov 2026'!J23 -> 0 | H23: =IF(Students!F14="Yes",N(Students!G14),0) -> 0 | J23: =N(G23)+N(H23)-N(I23) -> 0 | K23: ='Nov 2026'!O23 -> 0 | O23: =N(K23)+N(L23)+N(M23)-N(N23) -> 0 | P23: =F23+J23+O23 -> 0 | Q23: =IF(B23="","",IF(P23<=0,"Clear",IF(E23+I23+N23>0,"Partial","Due")))
A24: 11 | B24: =IF(Students!B15="","",Students!B15) | C24: ='Nov 2026'!F24 -> 0 | D24: =IF(Students!D15="Yes",N(Students!E15),0) -> 0 | F24: =N(C24)+N(D24)-N(E24) -> 0 | G24: ='Nov 2026'!J24 -> 0 | H24: =IF(Students!F15="Yes",N(Students!G15),0) -> 0 | J24: =N(G24)+N(H24)-N(I24) -> 0 | K24: ='Nov 2026'!O24 -> 0 | O24: =N(K24)+N(L24)+N(M24)-N(N24) -> 0 | P24: =F24+J24+O24 -> 0 | Q24: =IF(B24="","",IF(P24<=0,"Clear",IF(E24+I24+N24>0,"Partial","Due")))
A25: 12 | B25: =IF(Students!B16="","",Students!B16) | C25: ='Nov 2026'!F25 -> 0 | D25: =IF(Students!D16="Yes",N(Students!E16),0) -> 0 | F25: =N(C25)+N(D25)-N(E25) -> 0 | G25: ='Nov 2026'!J25 -> 0 | H25: =IF(Students!F16="Yes",N(Students!G16),0) -> 0 | J25: =N(G25)+N(H25)-N(I25) -> 0 | K25: ='Nov 2026'!O25 -> 0 | O25: =N(K25)+N(L25)+N(M25)-N(N25) -> 0 | P25: =F25+J25+O25 -> 0 | Q25: =IF(B25="","",IF(P25<=0,"Clear",IF(E25+I25+N25>0,"Partial","Due")))
... A113: 100 | B113: =IF(Students!B104="","",Students!B104) | C113: ='Nov 2026'!F113 -> 0 | D113: =IF(Students!D104="Yes",N(Students!E104),0) -> 0 | F113: =N(C113)+N(D113)-N(E113) -> 0 | G113: ='Nov 2026'!J113 -> 0 | H113: =IF(Students!F104="Yes",N(Students!G104),0) -> 0 | J113: =N(G113)+N(H113)-N(I113) -> 0 | K113: ='Nov 2026'!O113 -> 0 | O113: =N(K113)+N(L113)+N(M113)-N(N113) -> 0 | P113: =F113+J113+O113 -> 0 | Q113: =IF(B113="","",IF(P113<=0,"Clear",IF(E113+I113+N113>0,"Partial","Due")))
A114: TOTAL | C114: =SUM(C14:C113) -> 2000 | D114: =SUM(D14:D113) -> 2000 | E114: =SUM(E14:E113) -> 0 | F114: =SUM(F14:F113) -> 4000 | G114: =SUM(G14:G113) -> 3000 | H114: =SUM(H14:H113) -> 1500 | I114: =SUM(I14:I113) -> 0 | J114: =SUM(J14:J113) -> 4500 | ... P114: =SUM(P14:P113) -> 8700 | Q114: =COUNTIF(Q14:Q113,"Due")+COUNTIF(Q14:Q113,"Partial")&" with dues" -> 1 with dues

Sheet Jan 2027
A1: Future Talent Academy Jamshoro — Fee Register: January 2027
A2: Yellow cells: type the amount paid and any certificate / test paper fee. Previous dues come from the last month automatically.
A4: ENGLISH TEACHER | G4: COMPUTER TEACHER | M4: ACADEMY
A5: Name | C5: =IF(Setup!B5="","(enter name in Setup)",Setup!B5) -> (enter name in Setup) | G5: Name | I5: =Setup!B6 -> Sir Nazeer Ahmed Jamali | M5: From English | O5: =E114*(1-Setup!B11) -> 0
A6: Share % | C6: =Setup!B11 -> 0.5 | G6: Share % | I6: =Setup!B12 -> 0.5 | M6: From Computer | O6: =I114*(1-Setup!B12) -> 0
A7: Amount to Receive | C7: =E114*Setup!B11 -> 0 | G7: Amount to Receive | I7: =I114*Setup!B12 -> 0 | M7: From Other Fees | O7: =N114*Setup!B13 -> 0
M8: Total to Academy | O8: =SUM(O5:O7) -> 0
A10: MONTH SUMMARY
A11: Previous Dues | C11: =C114+G114+K114 -> 8700 | E11: This Month Charges | G11: =D114+H114+L114+M114 -> 3500 | I11: Collected | K11: =E114+I114+N114 -> 0 | M11: Outstanding Now | O11: =P114 -> 12200
C12: ENGLISH CLASS | G12: COMPUTER CLASS | K12: OTHER FEES (Certificate / Test Paper) | P12: TOTAL
A13: Serial No | B13: Student Name | C13: Previous Due | D13: This Month Fee | E13: Paid | F13: Balance | G13: Previous Due | H13: This Month Fee | I13: Paid | J13: Balance | K13: Previous Due | L13: Certificate Fee | M13: Test Paper Fee | N13: Paid | O13: Balance | P13: Total Due Now | Q13: Status
A14: 1 | B14: =IF(Students!B5="","",Students!B5) -> Ali Ahmed (example) | C14: ='Dec 2026'!F14 -> 4000 | D14: =IF(Students!D5="Yes",N(Students!E5),0) -> 2000 | F14: =N(C14)+N(D14)-N(E14) -> 6000 | G14: ='Dec 2026'!J14 -> 4500 | H14: =IF(Students!F5="Yes",N(Students!G5),0) -> 1500 | J14: =N(G14)+N(H14)-N(I14) -> 6000 | K14: ='Dec 2026'!O14 -> 200 | O14: =N(K14)+N(L14)+N(M14)-N(N14) -> 200 | P14: =F14+J14+O14 -> 12200 | Q14: =IF(B14="","",IF(P14<=0,"Clear",IF(E14+I14+N14>0,"Partial","Due"))) -> Due
A15: 2 | B15: =IF(Students!B6="","",Students!B6) | C15: ='Dec 2026'!F15 -> 0 | D15: =IF(Students!D6="Yes",N(Students!E6),0) -> 0 | F15: =N(C15)+N(D15)-N(E15) -> 0 | G15: ='Dec 2026'!J15 -> 0 | H15: =IF(Students!F6="Yes",N(Students!G6),0) -> 0 | J15: =N(G15)+N(H15)-N(I15) -> 0 | K15: ='Dec 2026'!O15 -> 0 | O15: =N(K15)+N(L15)+N(M15)-N(N15) -> 0 | P15: =F15+J15+O15 -> 0 | Q15: =IF(B15="","",IF(P15<=0,"Clear",IF(E15+I15+N15>0,"Partial","Due")))
A16: 3 | B16: =IF(Students!B7="","",Students!B7) | C16: ='Dec 2026'!F16 -> 0 | D16: =IF(Students!D7="Yes",N(Students!E7),0) -> 0 | F16: =N(C16)+N(D16)-N(E16) -> 0 | G16: ='Dec 2026'!J16 -> 0 | H16: =IF(Students!F7="Yes",N(Students!G7),0) -> 0 | J16: =N(G16)+N(H16)-N(I16) -> 0 | K16: ='Dec 2026'!O16 -> 0 | O16: =N(K16)+N(L16)+N(M16)-N(N16) -> 0 | P16: =F16+J16+O16 -> 0 | Q16: =IF(B16="","",IF(P16<=0,"Clear",IF(E16+I16+N16>0,"Partial","Due")))
A17: 4 | B17: =IF(Students!B8="","",Students!B8) | C17: ='Dec 2026'!F17 -> 0 | D17: =IF(Students!D8="Yes",N(Students!E8),0) -> 0 | F17: =N(C17)+N(D17)-N(E17) -> 0 | G17: ='Dec 2026'!J17 -> 0 | H17: =IF(Students!F8="Yes",N(Students!G8),0) -> 0 | J17: =N(G17)+N(H17)-N(I17) -> 0 | K17: ='Dec 2026'!O17 -> 0 | O17: =N(K17)+N(L17)+N(M17)-N(N17) -> 0 | P17: =F17+J17+O17 -> 0 | Q17: =IF(B17="","",IF(P17<=0,"Clear",IF(E17+I17+N17>0,"Partial","Due")))
A18: 5 | B18: =IF(Students!B9="","",Students!B9) | C18: ='Dec 2026'!F18 -> 0 | D18: =IF(Students!D9="Yes",N(Students!E9),0) -> 0 | F18: =N(C18)+N(D18)-N(E18) -> 0 | G18: ='Dec 2026'!J18 -> 0 | H18: =IF(Students!F9="Yes",N(Students!G9),0) -> 0 | J18: =N(G18)+N(H18)-N(I18) -> 0 | K18: ='Dec 2026'!O18 -> 0 | O18: =N(K18)+N(L18)+N(M18)-N(N18) -> 0 | P18: =F18+J18+O18 -> 0 | Q18: =IF(B18="","",IF(P18<=0,"Clear",IF(E18+I18+N18>0,"Partial","Due")))
A19: 6 | B19: =IF(Students!B10="","",Students!B10) | C19: ='Dec 2026'!F19 -> 0 | D19: =IF(Students!D10="Yes",N(Students!E10),0) -> 0 | F19: =N(C19)+N(D19)-N(E19) -> 0 | G19: ='Dec 2026'!J19 -> 0 | H19: =IF(Students!F10="Yes",N(Students!G10),0) -> 0 | J19: =N(G19)+N(H19)-N(I19) -> 0 | K19: ='Dec 2026'!O19 -> 0 | O19: =N(K19)+N(L19)+N(M19)-N(N19) -> 0 | P19: =F19+J19+O19 -> 0 | Q19: =IF(B19="","",IF(P19<=0,"Clear",IF(E19+I19+N19>0,"Partial","Due")))
A20: 7 | B20: =IF(Students!B11="","",Students!B11) | C20: ='Dec 2026'!F20 -> 0 | D20: =IF(Students!D11="Yes",N(Students!E11),0) -> 0 | F20: =N(C20)+N(D20)-N(E20) -> 0 | G20: ='Dec 2026'!J20 -> 0 | H20: =IF(Students!F11="Yes",N(Students!G11),0) -> 0 | J20: =N(G20)+N(H20)-N(I20) -> 0 | K20: ='Dec 2026'!O20 -> 0 | O20: =N(K20)+N(L20)+N(M20)-N(N20) -> 0 | P20: =F20+J20+O20 -> 0 | Q20: =IF(B20="","",IF(P20<=0,"Clear",IF(E20+I20+N20>0,"Partial","Due")))
A21: 8 | B21: =IF(Students!B12="","",Students!B12) | C21: ='Dec 2026'!F21 -> 0 | D21: =IF(Students!D12="Yes",N(Students!E12),0) -> 0 | F21: =N(C21)+N(D21)-N(E21) -> 0 | G21: ='Dec 2026'!J21 -> 0 | H21: =IF(Students!F12="Yes",N(Students!G12),0) -> 0 | J21: =N(G21)+N(H21)-N(I21) -> 0 | K21: ='Dec 2026'!O21 -> 0 | O21: =N(K21)+N(L21)+N(M21)-N(N21) -> 0 | P21: =F21+J21+O21 -> 0 | Q21: =IF(B21="","",IF(P21<=0,"Clear",IF(E21+I21+N21>0,"Partial","Due")))
A22: 9 | B22: =IF(Students!B13="","",Students!B13) | C22: ='Dec 2026'!F22 -> 0 | D22: =IF(Students!D13="Yes",N(Students!E13),0) -> 0 | F22: =N(C22)+N(D22)-N(E22) -> 0 | G22: ='Dec 2026'!J22 -> 0 | H22: =IF(Students!F13="Yes",N(Students!G13),0) -> 0 | J22: =N(G22)+N(H22)-N(I22) -> 0 | K22: ='Dec 2026'!O22 -> 0 | O22: =N(K22)+N(L22)+N(M22)-N(N22) -> 0 | P22: =F22+J22+O22 -> 0 | Q22: =IF(B22="","",IF(P22<=0,"Clear",IF(E22+I22+N22>0,"Partial","Due")))
A23: 10 | B23: =IF(Students!B14="","",Students!B14) | C23: ='Dec 2026'!F23 -> 0 | D23: =IF(Students!D14="Yes",N(Students!E14),0) -> 0 | F23: =N(C23)+N(D23)-N(E23) -> 0 | G23: ='Dec 2026'!J23 -> 0 | H23: =IF(Students!F14="Yes",N(Students!G14),0) -> 0 | J23: =N(G23)+N(H23)-N(I23) -> 0 | K23: ='Dec 2026'!O23 -> 0 | O23: =N(K23)+N(L23)+N(M23)-N(N23) -> 0 | P23: =F23+J23+O23 -> 0 | Q23: =IF(B23="","",IF(P23<=0,"Clear",IF(E23+I23+N23>0,"Partial","Due")))
A24: 11 | B24: =IF(Students!B15="","",Students!B15) | C24: ='Dec 2026'!F24 -> 0 | D24: =IF(Students!D15="Yes",N(Students!E15),0) -> 0 | F24: =N(C24)+N(D24)-N(E24) -> 0 | G24: ='Dec 2026'!J24 -> 0 | H24: =IF(Students!F15="Yes",N(Students!G15),0) -> 0 | J24: =N(G24)+N(H24)-N(I24) -> 0 | K24: ='Dec 2026'!O24 -> 0 | O24: =N(K24)+N(L24)+N(M24)-N(N24) -> 0 | P24: =F24+J24+O24 -> 0 | Q24: =IF(B24="","",IF(P24<=0,"Clear",IF(E24+I24+N24>0,"Partial","Due")))
A25: 12 | B25: =IF(Students!B16="","",Students!B16) | C25: ='Dec 2026'!F25 -> 0 | D25: =IF(Students!D16="Yes",N(Students!E16),0) -> 0 | F25: =N(C25)+N(D25)-N(E25) -> 0 | G25: ='Dec 2026'!J25 -> 0 | H25: =IF(Students!F16="Yes",N(Students!G16),0) -> 0 | J25: =N(G25)+N(H25)-N(I25) -> 0 | K25: ='Dec 2026'!O25 -> 0 | O25: =N(K25)+N(L25)+N(M25)-N(N25) -> 0 | P25: =F25+J25+O25 -> 0 | Q25: =IF(B25="","",IF(P25<=0,"Clear",IF(E25+I25+N25>0,"Partial","Due")))
... A113: 100 | B113: =IF(Students!B104="","",Students!B104) | C113: ='Dec 2026'!F113 -> 0 | D113: =IF(Students!D104="Yes",N(Students!E104),0) -> 0 | F113: =N(C113)+N(D113)-N(E113) -> 0 | G113: ='Dec 2026'!J113 -> 0 | H113: =IF(Students!F104="Yes",N(Students!G104),0) -> 0 | J113: =N(G113)+N(H113)-N(I113) -> 0 | K113: ='Dec 2026'!O113 -> 0 | O113: =N(K113)+N(L113)+N(M113)-N(N113) -> 0 | P113: =F113+J113+O113 -> 0 | Q113: =IF(B113="","",IF(P113<=0,"Clear",IF(E113+I113+N113>0,"Partial","Due")))
A114: TOTAL | C114: =SUM(C14:C113) -> 4000 | D114: =SUM(D14:D113) -> 2000 | E114: =SUM(E14:E113) -> 0 | F114: =SUM(F14:F113) -> 6000 | G114: =SUM(G14:G113) -> 4500 | H114: =SUM(H14:H113) -> 1500 | I114: =SUM(I14:I113) -> 0 | J114: =SUM(J14:J113) -> 6000 | ... P114: =SUM(P14:P113) -> 12200 | Q114: =COUNTIF(Q14:Q113,"Due")+COUNTIF(Q14:Q113,"Partial")&" with dues" -> 1 with dues

Sheet Feb 2027
A1: Future Talent Academy Jamshoro — Fee Register: February 2027
A2: Yellow cells: type the amount paid and any certificate / test paper fee. Previous dues come from the last month automatically.
A4: ENGLISH TEACHER | G4: COMPUTER TEACHER | M4: ACADEMY
A5: Name | C5: =IF(Setup!B5="","(enter name in Setup)",Setup!B5) -> (enter name in Setup) | G5: Name | I5: =Setup!B6 -> Sir Nazeer Ahmed Jamali | M5: From English | O5: =E114*(1-Setup!B11) -> 0
A6: Share % | C6: =Setup!B11 -> 0.5 | G6: Share % | I6: =Setup!B12 -> 0.5 | M6: From Computer | O6: =I114*(1-Setup!B12) -> 0
A7: Amount to Receive | C7: =E114*Setup!B11 -> 0 | G7: Amount to Receive | I7: =I114*Setup!B12 -> 0 | M7: From Other Fees | O7: =N114*Setup!B13 -> 0
M8: Total to Academy | O8: =SUM(O5:O7) -> 0
A10: MONTH SUMMARY
A11: Previous Dues | C11: =C114+G114+K114 -> 12200 | E11: This Month Charges | G11: =D114+H114+L114+M114 -> 3500 | I11: Collected | K11: =E114+I114+N114 -> 0 | M11: Outstanding Now | O11: =P114 -> 15700
C12: ENGLISH CLASS | G12: COMPUTER CLASS | K12: OTHER FEES (Certificate / Test Paper) | P12: TOTAL
A13: Serial No | B13: Student Name | C13: Previous Due | D13: This Month Fee | E13: Paid | F13: Balance | G13: Previous Due | H13: This Month Fee | I13: Paid | J13: Balance | K13: Previous Due | L13: Certificate Fee | M13: Test Paper Fee | N13: Paid | O13: Balance | P13: Total Due Now | Q13: Status
A14: 1 | B14: =IF(Students!B5="","",Students!B5) -> Ali Ahmed (example) | C14: ='Jan 2027'!F14 -> 6000 | D14: =IF(Students!D5="Yes",N(Students!E5),0) -> 2000 | F14: =N(C14)+N(D14)-N(E14) -> 8000 | G14: ='Jan 2027'!J14 -> 6000 | H14: =IF(Students!F5="Yes",N(Students!G5),0) -> 1500 | J14: =N(G14)+N(H14)-N(I14) -> 7500 | K14: ='Jan 2027'!O14 -> 200 | O14: =N(K14)+N(L14)+N(M14)-N(N14) -> 200 | P14: =F14+J14+O14 -> 15700 | Q14: =IF(B14="","",IF(P14<=0,"Clear",IF(E14+I14+N14>0,"Partial","Due"))) -> Due
A15: 2 | B15: =IF(Students!B6="","",Students!B6) | C15: ='Jan 2027'!F15 -> 0 | D15: =IF(Students!D6="Yes",N(Students!E6),0) -> 0 | F15: =N(C15)+N(D15)-N(E15) -> 0 | G15: ='Jan 2027'!J15 -> 0 | H15: =IF(Students!F6="Yes",N(Students!G6),0) -> 0 | J15: =N(G15)+N(H15)-N(I15) -> 0 | K15: ='Jan 2027'!O15 -> 0 | O15: =N(K15)+N(L15)+N(M15)-N(N15) -> 0 | P15: =F15+J15+O15 -> 0 | Q15: =IF(B15="","",IF(P15<=0,"Clear",IF(E15+I15+N15>0,"Partial","Due")))
A16: 3 | B16: =IF(Students!B7="","",Students!B7) | C16: ='Jan 2027'!F16 -> 0 | D16: =IF(Students!D7="Yes",N(Students!E7),0) -> 0 | F16: =N(C16)+N(D16)-N(E16) -> 0 | G16: ='Jan 2027'!J16 -> 0 | H16: =IF(Students!F7="Yes",N(Students!G7),0) -> 0 | J16: =N(G16)+N(H16)-N(I16) -> 0 | K16: ='Jan 2027'!O16 -> 0 | O16: =N(K16)+N(L16)+N(M16)-N(N16) -> 0 | P16: =F16+J16+O16 -> 0 | Q16: =IF(B16="","",IF(P16<=0,"Clear",IF(E16+I16+N16>0,"Partial","Due")))
A17: 4 | B17: =IF(Students!B8="","",Students!B8) | C17: ='Jan 2027'!F17 -> 0 | D17: =IF(Students!D8="Yes",N(Students!E8),0) -> 0 | F17: =N(C17)+N(D17)-N(E17) -> 0 | G17: ='Jan 2027'!J17 -> 0 | H17: =IF(Students!F8="Yes",N(Students!G8),0) -> 0 | J17: =N(G17)+N(H17)-N(I17) -> 0 | K17: ='Jan 2027'!O17 -> 0 | O17: =N(K17)+N(L17)+N(M17)-N(N17) -> 0 | P17: =F17+J17+O17 -> 0 | Q17: =IF(B17="","",IF(P17<=0,"Clear",IF(E17+I17+N17>0,"Partial","Due")))
A18: 5 | B18: =IF(Students!B9="","",Students!B9) | C18: ='Jan 2027'!F18 -> 0 | D18: =IF(Students!D9="Yes",N(Students!E9),0) -> 0 | F18: =N(C18)+N(D18)-N(E18) -> 0 | G18: ='Jan 2027'!J18 -> 0 | H18: =IF(Students!F9="Yes",N(Students!G9),0) -> 0 | J18: =N(G18)+N(H18)-N(I18) -> 0 | K18: ='Jan 2027'!O18 -> 0 | O18: =N(K18)+N(L18)+N(M18)-N(N18) -> 0 | P18: =F18+J18+O18 -> 0 | Q18: =IF(B18="","",IF(P18<=0,"Clear",IF(E18+I18+N18>0,"Partial","Due")))
A19: 6 | B19: =IF(Students!B10="","",Students!B10) | C19: ='Jan 2027'!F19 -> 0 | D19: =IF(Students!D10="Yes",N(Students!E10),0) -> 0 | F19: =N(C19)+N(D19)-N(E19) -> 0 | G19: ='Jan 2027'!J19 -> 0 | H19: =IF(Students!F10="Yes",N(Students!G10),0) -> 0 | J19: =N(G19)+N(H19)-N(I19) -> 0 | K19: ='Jan 2027'!O19 -> 0 | O19: =N(K19)+N(L19)+N(M19)-N(N19) -> 0 | P19: =F19+J19+O19 -> 0 | Q19: =IF(B19="","",IF(P19<=0,"Clear",IF(E19+I19+N19>0,"Partial","Due")))
A20: 7 | B20: =IF(Students!B11="","",Students!B11) | C20: ='Jan 2027'!F20 -> 0 | D20: =IF(Students!D11="Yes",N(Students!E11),0) -> 0 | F20: =N(C20)+N(D20)-N(E20) -> 0 | G20: ='Jan 2027'!J20 -> 0 | H20: =IF(Students!F11="Yes",N(Students!G11),0) -> 0 | J20: =N(G20)+N(H20)-N(I20) -> 0 | K20: ='Jan 2027'!O20 -> 0 | O20: =N(K20)+N(L20)+N(M20)-N(N20) -> 0 | P20: =F20+J20+O20 -> 0 | Q20: =IF(B20="","",IF(P20<=0,"Clear",IF(E20+I20+N20>0,"Partial","Due")))
A21: 8 | B21: =IF(Students!B12="","",Students!B12) | C21: ='Jan 2027'!F21 -> 0 | D21: =IF(Students!D12="Yes",N(Students!E12),0) -> 0 | F21: =N(C21)+N(D21)-N(E21) -> 0 | G21: ='Jan 2027'!J21 -> 0 | H21: =IF(Students!F12="Yes",N(Students!G12),0) -> 0 | J21: =N(G21)+N(H21)-N(I21) -> 0 | K21: ='Jan 2027'!O21 -> 0 | O21: =N(K21)+N(L21)+N(M21)-N(N21) -> 0 | P21: =F21+J21+O21 -> 0 | Q21: =IF(B21="","",IF(P21<=0,"Clear",IF(E21+I21+N21>0,"Partial","Due")))
A22: 9 | B22: =IF(Students!B13="","",Students!B13) | C22: ='Jan 2027'!F22 -> 0 | D22: =IF(Students!D13="Yes",N(Students!E13),0) -> 0 | F22: =N(C22)+N(D22)-N(E22) -> 0 | G22: ='Jan 2027'!J22 -> 0 | H22: =IF(Students!F13="Yes",N(Students!G13),0) -> 0 | J22: =N(G22)+N(H22)-N(I22) -> 0 | K22: ='Jan 2027'!O22 -> 0 | O22: =N(K22)+N(L22)+N(M22)-N(N22) -> 0 | P22: =F22+J22+O22 -> 0 | Q22: =IF(B22="","",IF(P22<=0,"Clear",IF(E22+I22+N22>0,"Partial","Due")))
A23: 10 | B23: =IF(Students!B14="","",Students!B14) | C23: ='Jan 2027'!F23 -> 0 | D23: =IF(Students!D14="Yes",N(Students!E14),0) -> 0 | F23: =N(C23)+N(D23)-N(E23) -> 0 | G23: ='Jan 2027'!J23 -> 0 | H23: =IF(Students!F14="Yes",N(Students!G14),0) -> 0 | J23: =N(G23)+N(H23)-N(I23) -> 0 | K23: ='Jan 2027'!O23 -> 0 | O23: =N(K23)+N(L23)+N(M23)-N(N23) -> 0 | P23: =F23+J23+O23 -> 0 | Q23: =IF(B23="","",IF(P23<=0,"Clear",IF(E23+I23+N23>0,"Partial","Due")))
A24: 11 | B24: =IF(Students!B15="","",Students!B15) | C24: ='Jan 2027'!F24 -> 0 | D24: =IF(Students!D15="Yes",N(Students!E15),0) -> 0 | F24: =N(C24)+N(D24)-N(E24) -> 0 | G24: ='Jan 2027'!J24 -> 0 | H24: =IF(Students!F15="Yes",N(Students!G15),0) -> 0 | J24: =N(G24)+N(H24)-N(I24) -> 0 | K24: ='Jan 2027'!O24 -> 0 | O24: =N(K24)+N(L24)+N(M24)-N(N24) -> 0 | P24: =F24+J24+O24 -> 0 | Q24: =IF(B24="","",IF(P24<=0,"Clear",IF(E24+I24+N24>0,"Partial","Due")))
A25: 12 | B25: =IF(Students!B16="","",Students!B16) | C25: ='Jan 2027'!F25 -> 0 | D25: =IF(Students!D16="Yes",N(Students!E16),0) -> 0 | F25: =N(C25)+N(D25)-N(E25) -> 0 | G25: ='Jan 2027'!J25 -> 0 | H25: =IF(Students!F16="Yes",N(Students!G16),0) -> 0 | J25: =N(G25)+N(H25)-N(I25) -> 0 | K25: ='Jan 2027'!O25 -> 0 | O25: =N(K25)+N(L25)+N(M25)-N(N25) -> 0 | P25: =F25+J25+O25 -> 0 | Q25: =IF(B25="","",IF(P25<=0,"Clear",IF(E25+I25+N25>0,"Partial","Due")))
... A113: 100 | B113: =IF(Students!B104="","",Students!B104) | C113: ='Jan 2027'!F113 -> 0 | D113: =IF(Students!D104="Yes",N(Students!E104),0) -> 0 | F113: =N(C113)+N(D113)-N(E113) -> 0 | G113: ='Jan 2027'!J113 -> 0 | H113: =IF(Students!F104="Yes",N(Students!G104),0) -> 0 | J113: =N(G113)+N(H113)-N(I113) -> 0 | K113: ='Jan 2027'!O113 -> 0 | O113: =N(K113)+N(L113)+N(M113)-N(N113) -> 0 | P113: =F113+J113+O113 -> 0 | Q113: =IF(B113="","",IF(P113<=0,"Clear",IF(E113+I113+N113>0,"Partial","Due")))
A114: TOTAL | C114: =SUM(C14:C113) -> 6000 | D114: =SUM(D14:D113) -> 2000 | E114: =SUM(E14:E113) -> 0 | F114: =SUM(F14:F113) -> 8000 | G114: =SUM(G14:G113) -> 6000 | H114: =SUM(H14:H113) -> 1500 | I114: =SUM(I14:I113) -> 0 | J114: =SUM(J14:J113) -> 7500 | ... P114: =SUM(P14:P113) -> 15700 | Q114: =COUNTIF(Q14:Q113,"Due")+COUNTIF(Q14:Q113,"Partial")&" with dues" -> 1 with dues

Sheet Mar 2027
A1: Future Talent Academy Jamshoro — Fee Register: March 2027
A2: Yellow cells: type the amount paid and any certificate / test paper fee. Previous dues come from the last month automatically.
A4: ENGLISH TEACHER | G4: COMPUTER TEACHER | M4: ACADEMY
A5: Name | C5: =IF(Setup!B5="","(enter name in Setup)",Setup!B5) -> (enter name in Setup) | G5: Name | I5: =Setup!B6 -> Sir Nazeer Ahmed Jamali | M5: From English | O5: =E114*(1-Setup!B11) -> 0
A6: Share % | C6: =Setup!B11 -> 0.5 | G6: Share % | I6: =Setup!B12 -> 0.5 | M6: From Computer | O6: =I114*(1-Setup!B12) -> 0
A7: Amount to Receive | C7: =E114*Setup!B11 -> 0 | G7: Amount to Receive | I7: =I114*Setup!B12 -> 0 | M7: From Other Fees | O7: =N114*Setup!B13 -> 0
M8: Total to Academy | O8: =SUM(O5:O7) -> 0
A10: MONTH SUMMARY
A11: Previous Dues | C11: =C114+G114+K114 -> 15700 | E11: This Month Charges | G11: =D114+H114+L114+M114 -> 3500 | I11: Collected | K11: =E114+I114+N114 -> 0 | M11: Outstanding Now | O11: =P114 -> 19200
C12: ENGLISH CLASS | G12: COMPUTER CLASS | K12: OTHER FEES (Certificate / Test Paper) | P12: TOTAL
A13: Serial No | B13: Student Name | C13: Previous Due | D13: This Month Fee | E13: Paid | F13: Balance | G13: Previous Due | H13: This Month Fee | I13: Paid | J13: Balance | K13: Previous Due | L13: Certificate Fee | M13: Test Paper Fee | N13: Paid | O13: Balance | P13: Total Due Now | Q13: Status
A14: 1 | B14: =IF(Students!B5="","",Students!B5) -> Ali Ahmed (example) | C14: ='Feb 2027'!F14 -> 8000 | D14: =IF(Students!D5="Yes",N(Students!E5),0) -> 2000 | F14: =N(C14)+N(D14)-N(E14) -> 10000 | G14: ='Feb 2027'!J14 -> 7500 | H14: =IF(Students!F5="Yes",N(Students!G5),0) -> 1500 | J14: =N(G14)+N(H14)-N(I14) -> 9000 | K14: ='Feb 2027'!O14 -> 200 | O14: =N(K14)+N(L14)+N(M14)-N(N14) -> 200 | P14: =F14+J14+O14 -> 19200 | Q14: =IF(B14="","",IF(P14<=0,"Clear",IF(E14+I14+N14>0,"Partial","Due"))) -> Due
A15: 2 | B15: =IF(Students!B6="","",Students!B6) | C15: ='Feb 2027'!F15 -> 0 | D15: =IF(Students!D6="Yes",N(Students!E6),0) -> 0 | F15: =N(C15)+N(D15)-N(E15) -> 0 | G15: ='Feb 2027'!J15 -> 0 | H15: =IF(Students!F6="Yes",N(Students!G6),0) -> 0 | J15: =N(G15)+N(H15)-N(I15) -> 0 | K15: ='Feb 2027'!O15 -> 0 | O15: =N(K15)+N(L15)+N(M15)-N(N15) -> 0 | P15: =F15+J15+O15 -> 0 | Q15: =IF(B15="","",IF(P15<=0,"Clear",IF(E15+I15+N15>0,"Partial","Due")))
A16: 3 | B16: =IF(Students!B7="","",Students!B7) | C16: ='Feb 2027'!F16 -> 0 | D16: =IF(Students!D7="Yes",N(Students!E7),0) -> 0 | F16: =N(C16)+N(D16)-N(E16) -> 0 | G16: ='Feb 2027'!J16 -> 0 | H16: =IF(Students!F7="Yes",N(Students!G7),0) -> 0 | J16: =N(G16)+N(H16)-N(I16) -> 0 | K16: ='Feb 2027'!O16 -> 0 | O16: =N(K16)+N(L16)+N(M16)-N(N16) -> 0 | P16: =F16+J16+O16 -> 0 | Q16: =IF(B16="","",IF(P16<=0,"Clear",IF(E16+I16+N16>0,"Partial","Due")))
A17: 4 | B17: =IF(Students!B8="","",Students!B8) | C17: ='Feb 2027'!F17 -> 0 | D17: =IF(Students!D8="Yes",N(Students!E8),0) -> 0 | F17: =N(C17)+N(D17)-N(E17) -> 0 | G17: ='Feb 2027'!J17 -> 0 | H17: =IF(Students!F8="Yes",N(Students!G8),0) -> 0 | J17: =N(G17)+N(H17)-N(I17) -> 0 | K17: ='Feb 2027'!O17 -> 0 | O17: =N(K17)+N(L17)+N(M17)-N(N17) -> 0 | P17: =F17+J17+O17 -> 0 | Q17: =IF(B17="","",IF(P17<=0,"Clear",IF(E17+I17+N17>0,"Partial","Due")))
A18: 5 | B18: =IF(Students!B9="","",Students!B9) | C18: ='Feb 2027'!F18 -> 0 | D18: =IF(Students!D9="Yes",N(Students!E9),0) -> 0 | F18: =N(C18)+N(D18)-N(E18) -> 0 | G18: ='Feb 2027'!J18 -> 0 | H18: =IF(Students!F9="Yes",N(Students!G9),0) -> 0 | J18: =N(G18)+N(H18)-N(I18) -> 0 | K18: ='Feb 2027'!O18 -> 0 | O18: =N(K18)+N(L18)+N(M18)-N(N18) -> 0 | P18: =F18+J18+O18 -> 0 | Q18: =IF(B18="","",IF(P18<=0,"Clear",IF(E18+I18+N18>0,"Partial","Due")))
A19: 6 | B19: =IF(Students!B10="","",Students!B10) | C19: ='Feb 2027'!F19 -> 0 | D19: =IF(Students!D10="Yes",N(Students!E10),0) -> 0 | F19: =N(C19)+N(D19)-N(E19) -> 0 | G19: ='Feb 2027'!J19 -> 0 | H19: =IF(Students!F10="Yes",N(Students!G10),0) -> 0 | J19: =N(G19)+N(H19)-N(I19) -> 0 | K19: ='Feb 2027'!O19 -> 0 | O19: =N(K19)+N(L19)+N(M19)-N(N19) -> 0 | P19: =F19+J19+O19 -> 0 | Q19: =IF(B19="","",IF(P19<=0,"Clear",IF(E19+I19+N19>0,"Partial","Due")))
A20: 7 | B20: =IF(Students!B11="","",Students!B11) | C20: ='Feb 2027'!F20 -> 0 | D20: =IF(Students!D11="Yes",N(Students!E11),0) -> 0 | F20: =N(C20)+N(D20)-N(E20) -> 0 | G20: ='Feb 2027'!J20 -> 0 | H20: =IF(Students!F11="Yes",N(Students!G11),0) -> 0 | J20: =N(G20)+N(H20)-N(I20) -> 0 | K20: ='Feb 2027'!O20 -> 0 | O20: =N(K20)+N(L20)+N(M20)-N(N20) -> 0 | P20: =F20+J20+O20 -> 0 | Q20: =IF(B20="","",IF(P20<=0,"Clear",IF(E20+I20+N20>0,"Partial","Due")))
A21: 8 | B21: =IF(Students!B12="","",Students!B12) | C21: ='Feb 2027'!F21 -> 0 | D21: =IF(Students!D12="Yes",N(Students!E12),0) -> 0 | F21: =N(C21)+N(D21)-N(E21) -> 0 | G21: ='Feb 2027'!J21 -> 0 | H21: =IF(Students!F12="Yes",N(Students!G12),0) -> 0 | J21: =N(G21)+N(H21)-N(I21) -> 0 | K21: ='Feb 2027'!O21 -> 0 | O21: =N(K21)+N(L21)+N(M21)-N(N21) -> 0 | P21: =F21+J21+O21 -> 0 | Q21: =IF(B21="","",IF(P21<=0,"Clear",IF(E21+I21+N21>0,"Partial","Due")))
A22: 9 | B22: =IF(Students!B13="","",Students!B13) | C22: ='Feb 2027'!F22 -> 0 | D22: =IF(Students!D13="Yes",N(Students!E13),0) -> 0 | F22: =N(C22)+N(D22)-N(E22) -> 0 | G22: ='Feb 2027'!J22 -> 0 | H22: =IF(Students!F13="Yes",N(Students!G13),0) -> 0 | J22: =N(G22)+N(H22)-N(I22) -> 0 | K22: ='Feb 2027'!O22 -> 0 | O22: =N(K22)+N(L22)+N(M22)-N(N22) -> 0 | P22: =F22+J22+O22 -> 0 | Q22: =IF(B22="","",IF(P22<=0,"Clear",IF(E22+I22+N22>0,"Partial","Due")))
A23: 10 | B23: =IF(Students!B14="","",Students!B14) | C23: ='Feb 2027'!F23 -> 0 | D23: =IF(Students!D14="Yes",N(Students!E14),0) -> 0 | F23: =N(C23)+N(D23)-N(E23) -> 0 | G23: ='Feb 2027'!J23 -> 0 | H23: =IF(Students!F14="Yes",N(Students!G14),0) -> 0 | J23: =N(G23)+N(H23)-N(I23) -> 0 | K23: ='Feb 2027'!O23 -> 0 | O23: =N(K23)+N(L23)+N(M23)-N(N23) -> 0 | P23: =F23+J23+O23 -> 0 | Q23: =IF(B23="","",IF(P23<=0,"Clear",IF(E23+I23+N23>0,"Partial","Due")))
A24: 11 | B24: =IF(Students!B15="","",Students!B15) | C24: ='Feb 2027'!F24 -> 0 | D24: =IF(Students!D15="Yes",N(Students!E15),0) -> 0 | F24: =N(C24)+N(D24)-N(E24) -> 0 | G24: ='Feb 2027'!J24 -> 0 | H24: =IF(Students!F15="Yes",N(Students!G15),0) -> 0 | J24: =N(G24)+N(H24)-N(I24) -> 0 | K24: ='Feb 2027'!O24 -> 0 | O24: =N(K24)+N(L24)+N(M24)-N(N24) -> 0 | P24: =F24+J24+O24 -> 0 | Q24: =IF(B24="","",IF(P24<=0,"Clear",IF(E24+I24+N24>0,"Partial","Due")))
A25: 12 | B25: =IF(Students!B16="","",Students!B16) | C25: ='Feb 2027'!F25 -> 0 | D25: =IF(Students!D16="Yes",N(Students!E16),0) -> 0 | F25: =N(C25)+N(D25)-N(E25) -> 0 | G25: ='Feb 2027'!J25 -> 0 | H25: =IF(Students!F16="Yes",N(Students!G16),0) -> 0 | J25: =N(G25)+N(H25)-N(I25) -> 0 | K25: ='Feb 2027'!O25 -> 0 | O25: =N(K25)+N(L25)+N(M25)-N(N25) -> 0 | P25: =F25+J25+O25 -> 0 | Q25: =IF(B25="","",IF(P25<=0,"Clear",IF(E25+I25+N25>0,"Partial","Due")))
... A113: 100 | B113: =IF(Students!B104="","",Students!B104) | C113: ='Feb 2027'!F113 -> 0 | D113: =IF(Students!D104="Yes",N(Students!E104),0) -> 0 | F113: =N(C113)+N(D113)-N(E113) -> 0 | G113: ='Feb 2027'!J113 -> 0 | H113: =IF(Students!F104="Yes",N(Students!G104),0) -> 0 | J113: =N(G113)+N(H113)-N(I113) -> 0 | K113: ='Feb 2027'!O113 -> 0 | O113: =N(K113)+N(L113)+N(M113)-N(N113) -> 0 | P113: =F113+J113+O113 -> 0 | Q113: =IF(B113="","",IF(P113<=0,"Clear",IF(E113+I113+N113>0,"Partial","Due")))
A114: TOTAL | C114: =SUM(C14:C113) -> 8000 | D114: =SUM(D14:D113) -> 2000 | E114: =SUM(E14:E113) -> 0 | F114: =SUM(F14:F113) -> 10000 | G114: =SUM(G14:G113) -> 7500 | H114: =SUM(H14:H113) -> 1500 | I114: =SUM(I14:I113) -> 0 | J114: =SUM(J14:J113) -> 9000 | ... P114: =SUM(P14:P113) -> 19200 | Q114: =COUNTIF(Q14:Q113,"Due")+COUNTIF(Q14:Q113,"Partial")&" with dues" -> 1 with dues

Sheet Apr 2027
A1: Future Talent Academy Jamshoro — Fee Register: April 2027
A2: Yellow cells: type the amount paid and any certificate / test paper fee. Previous dues come from the last month automatically.
A4: ENGLISH TEACHER | G4: COMPUTER TEACHER | M4: ACADEMY
A5: Name | C5: =IF(Setup!B5="","(enter name in Setup)",Setup!B5) -> (enter name in Setup) | G5: Name | I5: =Setup!B6 -> Sir Nazeer Ahmed Jamali | M5: From English | O5: =E114*(1-Setup!B11) -> 0
A6: Share % | C6: =Setup!B11 -> 0.5 | G6: Share % | I6: =Setup!B12 -> 0.5 | M6: From Computer | O6: =I114*(1-Setup!B12) -> 0
A7: Amount to Receive | C7: =E114*Setup!B11 -> 0 | G7: Amount to Receive | I7: =I114*Setup!B12 -> 0 | M7: From Other Fees | O7: =N114*Setup!B13 -> 0
M8: Total to Academy | O8: =SUM(O5:O7) -> 0
A10: MONTH SUMMARY
A11: Previous Dues | C11: =C114+G114+K114 -> 19200 | E11: This Month Charges | G11: =D114+H114+L114+M114 -> 3500 | I11: Collected | K11: =E114+I114+N114 -> 0 | M11: Outstanding Now | O11: =P114 -> 22700
C12: ENGLISH CLASS | G12: COMPUTER CLASS | K12: OTHER FEES (Certificate / Test Paper) | P12: TOTAL
A13: Serial No | B13: Student Name | C13: Previous Due | D13: This Month Fee | E13: Paid | F13: Balance | G13: Previous Due | H13: This Month Fee | I13: Paid | J13: Balance | K13: Previous Due | L13: Certificate Fee | M13: Test Paper Fee | N13: Paid | O13: Balance | P13: Total Due Now | Q13: Status
A14: 1 | B14: =IF(Students!B5="","",Students!B5) -> Ali Ahmed (example) | C14: ='Mar 2027'!F14 -> 10000 | D14: =IF(Students!D5="Yes",N(Students!E5),0) -> 2000 | F14: =N(C14)+N(D14)-N(E14) -> 12000 | G14: ='Mar 2027'!J14 -> 9000 | H14: =IF(Students!F5="Yes",N(Students!G5),0) -> 1500 | J14: =N(G14)+N(H14)-N(I14) -> 10500 | K14: ='Mar 2027'!O14 -> 200 | O14: =N(K14)+N(L14)+N(M14)-N(N14) -> 200 | P14: =F14+J14+O14 -> 22700 | Q14: =IF(B14="","",IF(P14<=0,"Clear",IF(E14+I14+N14>0,"Partial","Due"))) -> Due
A15: 2 | B15: =IF(Students!B6="","",Students!B6) | C15: ='Mar 2027'!F15 -> 0 | D15: =IF(Students!D6="Yes",N(Students!E6),0) -> 0 | F15: =N(C15)+N(D15)-N(E15) -> 0 | G15: ='Mar 2027'!J15 -> 0 | H15: =IF(Students!F6="Yes",N(Students!G6),0) -> 0 | J15: =N(G15)+N(H15)-N(I15) -> 0 | K15: ='Mar 2027'!O15 -> 0 | O15: =N(K15)+N(L15)+N(M15)-N(N15) -> 0 | P15: =F15+J15+O15 -> 0 | Q15: =IF(B15="","",IF(P15<=0,"Clear",IF(E15+I15+N15>0,"Partial","Due")))
A16: 3 | B16: =IF(Students!B7="","",Students!B7) | C16: ='Mar 2027'!F16 -> 0 | D16: =IF(Students!D7="Yes",N(Students!E7),0) -> 0 | F16: =N(C16)+N(D16)-N(E16) -> 0 | G16: ='Mar 2027'!J16 -> 0 | H16: =IF(Students!F7="Yes",N(Students!G7),0) -> 0 | J16: =N(G16)+N(H16)-N(I16) -> 0 | K16: ='Mar 2027'!O16 -> 0 | O16: =N(K16)+N(L16)+N(M16)-N(N16) -> 0 | P16: =F16+J16+O16 -> 0 | Q16: =IF(B16="","",IF(P16<=0,"Clear",IF(E16+I16+N16>0,"Partial","Due")))
A17: 4 | B17: =IF(Students!B8="","",Students!B8) | C17: ='Mar 2027'!F17 -> 0 | D17: =IF(Students!D8="Yes",N(Students!E8),0) -> 0 | F17: =N(C17)+N(D17)-N(E17) -> 0 | G17: ='Mar 2027'!J17 -> 0 | H17: =IF(Students!F8="Yes",N(Students!G8),0) -> 0 | J17: =N(G17)+N(H17)-N(I17) -> 0 | K17: ='Mar 2027'!O17 -> 0 | O17: =N(K17)+N(L17)+N(M17)-N(N17) -> 0 | P17: =F17+J17+O17 -> 0 | Q17: =IF(B17="","",IF(P17<=0,"Clear",IF(E17+I17+N17>0,"Partial","Due")))
A18: 5 | B18: =IF(Students!B9="","",Students!B9) | C18: ='Mar 2027'!F18 -> 0 | D18: =IF(Students!D9="Yes",N(Students!E9),0) -> 0 | F18: =N(C18)+N(D18)-N(E18) -> 0 | G18: ='Mar 2027'!J18 -> 0 | H18: =IF(Students!F9="Yes",N(Students!G9),0) -> 0 | J18: =N(G18)+N(H18)-N(I18) -> 0 | K18: ='Mar 2027'!O18 -> 0 | O18: =N(K18)+N(L18)+N(M18)-N(N18) -> 0 | P18: =F18+J18+O18 -> 0 | Q18: =IF(B18="","",IF(P18<=0,"Clear",IF(E18+I18+N18>0,"Partial","Due")))
A19: 6 | B19: =IF(Students!B10="","",Students!B10) | C19: ='Mar 2027'!F19 -> 0 | D19: =IF(Students!D10="Yes",N(Students!E10),0) -> 0 | F19: =N(C19)+N(D19)-N(E19) -> 0 | G19: ='Mar 2027'!J19 -> 0 | H19: =IF(Students!F10="Yes",N(Students!G10),0) -> 0 | J19: =N(G19)+N(H19)-N(I19) -> 0 | K19: ='Mar 2027'!O19 -> 0 | O19: =N(K19)+N(L19)+N(M19)-N(N19) -> 0 | P19: =F19+J19+O19 -> 0 | Q19: =IF(B19="","",IF(P19<=0,"Clear",IF(E19+I19+N19>0,"Partial","Due")))
A20: 7 | B20: =IF(Students!B11="","",Students!B11) | C20: ='Mar 2027'!F20 -> 0 | D20: =IF(Students!D11="Yes",N(Students!E11),0) -> 0 | F20: =N(C20)+N(D20)-N(E20) -> 0 | G20: ='Mar 2027'!J20 -> 0 | H20: =IF(Students!F11="Yes",N(Students!G11),0) -> 0 | J20: =N(G20)+N(H20)-N(I20) -> 0 | K20: ='Mar 2027'!O20 -> 0 | O20: =N(K20)+N(L20)+N(M20)-N(N20) -> 0 | P20: =F20+J20+O20 -> 0 | Q20: =IF(B20="","",IF(P20<=0,"Clear",IF(E20+I20+N20>0,"Partial","Due")))
A21: 8 | B21: =IF(Students!B12="","",Students!B12) | C21: ='Mar 2027'!F21 -> 0 | D21: =IF(Students!D12="Yes",N(Students!E12),0) -> 0 | F21: =N(C21)+N(D21)-N(E21) -> 0 | G21: ='Mar 2027'!J21 -> 0 | H21: =IF(Students!F12="Yes",N(Students!G12),0) -> 0 | J21: =N(G21)+N(H21)-N(I21) -> 0 | K21: ='Mar 2027'!O21 -> 0 | O21: =N(K21)+N(L21)+N(M21)-N(N21) -> 0 | P21: =F21+J21+O21 -> 0 | Q21: =IF(B21="","",IF(P21<=0,"Clear",IF(E21+I21+N21>0,"Partial","Due")))
A22: 9 | B22: =IF(Students!B13="","",Students!B13) | C22: ='Mar 2027'!F22 -> 0 | D22: =IF(Students!D13="Yes",N(Students!E13),0) -> 0 | F22: =N(C22)+N(D22)-N(E22) -> 0 | G22: ='Mar 2027'!J22 -> 0 | H22: =IF(Students!F13="Yes",N(Students!G13),0) -> 0 | J22: =N(G22)+N(H22)-N(I22) -> 0 | K22: ='Mar 2027'!O22 -> 0 | O22: =N(K22)+N(L22)+N(M22)-N(N22) -> 0 | P22: =F22+J22+O22 -> 0 | Q22: =IF(B22="","",IF(P22<=0,"Clear",IF(E22+I22+N22>0,"Partial","Due")))
A23: 10 | B23: =IF(Students!B14="","",Students!B14) | C23: ='Mar 2027'!F23 -> 0 | D23: =IF(Students!D14="Yes",N(Students!E14),0) -> 0 | F23: =N(C23)+N(D23)-N(E23) -> 0 | G23: ='Mar 2027'!J23 -> 0 | H23: =IF(Students!F14="Yes",N(Students!G14),0) -> 0 | J23: =N(G23)+N(H23)-N(I23) -> 0 | K23: ='Mar 2027'!O23 -> 0 | O23: =N(K23)+N(L23)+N(M23)-N(N23) -> 0 | P23: =F23+J23+O23 -> 0 | Q23: =IF(B23="","",IF(P23<=0,"Clear",IF(E23+I23+N23>0,"Partial","Due")))
A24: 11 | B24: =IF(Students!B15="","",Students!B15) | C24: ='Mar 2027'!F24 -> 0 | D24: =IF(Students!D15="Yes",N(Students!E15),0) -> 0 | F24: =N(C24)+N(D24)-N(E24) -> 0 | G24: ='Mar 2027'!J24 -> 0 | H24: =IF(Students!F15="Yes",N(Students!G15),0) -> 0 | J24: =N(G24)+N(H24)-N(I24) -> 0 | K24: ='Mar 2027'!O24 -> 0 | O24: =N(K24)+N(L24)+N(M24)-N(N24) -> 0 | P24: =F24+J24+O24 -> 0 | Q24: =IF(B24="","",IF(P24<=0,"Clear",IF(E24+I24+N24>0,"Partial","Due")))
A25: 12 | B25: =IF(Students!B16="","",Students!B16) | C25: ='Mar 2027'!F25 -> 0 | D25: =IF(Students!D16="Yes",N(Students!E16),0) -> 0 | F25: =N(C25)+N(D25)-N(E25) -> 0 | G25: ='Mar 2027'!J25 -> 0 | H25: =IF(Students!F16="Yes",N(Students!G16),0) -> 0 | J25: =N(G25)+N(H25)-N(I25) -> 0 | K25: ='Mar 2027'!O25 -> 0 | O25: =N(K25)+N(L25)+N(M25)-N(N25) -> 0 | P25: =F25+J25+O25 -> 0 | Q25: =IF(B25="","",IF(P25<=0,"Clear",IF(E25+I25+N25>0,"Partial","Due")))
... A113: 100 | B113: =IF(Students!B104="","",Students!B104) | C113: ='Mar 2027'!F113 -> 0 | D113: =IF(Students!D104="Yes",N(Students!E104),0) -> 0 | F113: =N(C113)+N(D113)-N(E113) -> 0 | G113: ='Mar 2027'!J113 -> 0 | H113: =IF(Students!F104="Yes",N(Students!G104),0) -> 0 | J113: =N(G113)+N(H113)-N(I113) -> 0 | K113: ='Mar 2027'!O113 -> 0 | O113: =N(K113)+N(L113)+N(M113)-N(N113) -> 0 | P113: =F113+J113+O113 -> 0 | Q113: =IF(B113="","",IF(P113<=0,"Clear",IF(E113+I113+N113>0,"Partial","Due")))
A114: TOTAL | C114: =SUM(C14:C113) -> 10000 | D114: =SUM(D14:D113) -> 2000 | E114: =SUM(E14:E113) -> 0 | F114: =SUM(F14:F113) -> 12000 | G114: =SUM(G14:G113) -> 9000 | H114: =SUM(H14:H113) -> 1500 | I114: =SUM(I14:I113) -> 0 | J114: =SUM(J14:J113) -> 10500 | ... P114: =SUM(P14:P113) -> 22700 | Q114: =COUNTIF(Q14:Q113,"Due")+COUNTIF(Q14:Q113,"Partial")&" with dues" -> 1 with dues

Sheet May 2027
A1: Future Talent Academy Jamshoro — Fee Register: May 2027
A2: Yellow cells: type the amount paid and any certificate / test paper fee. Previous dues come from the last month automatically.
A4: ENGLISH TEACHER | G4: COMPUTER TEACHER | M4: ACADEMY
A5: Name | C5: =IF(Setup!B5="","(enter name in Setup)",Setup!B5) -> (enter name in Setup) | G5: Name | I5: =Setup!B6 -> Sir Nazeer Ahmed Jamali | M5: From English | O5: =E114*(1-Setup!B11) -> 0
A6: Share % | C6: =Setup!B11 -> 0.5 | G6: Share % | I6: =Setup!B12 -> 0.5 | M6: From Computer | O6: =I114*(1-Setup!B12) -> 0
A7: Amount to Receive | C7: =E114*Setup!B11 -> 0 | G7: Amount to Receive | I7: =I114*Setup!B12 -> 0 | M7: From Other Fees | O7: =N114*Setup!B13 -> 0
M8: Total to Academy | O8: =SUM(O5:O7) -> 0
A10: MONTH SUMMARY
A11: Previous Dues | C11: =C114+G114+K114 -> 22700 | E11: This Month Charges | G11: =D114+H114+L114+M114 -> 3500 | I11: Collected | K11: =E114+I114+N114 -> 0 | M11: Outstanding Now | O11: =P114 -> 26200
C12: ENGLISH CLASS | G12: COMPUTER CLASS | K12: OTHER FEES (Certificate / Test Paper) | P12: TOTAL
A13: Serial No | B13: Student Name | C13: Previous Due | D13: This Month Fee | E13: Paid | F13: Balance | G13: Previous Due | H13: This Month Fee | I13: Paid | J13: Balance | K13: Previous Due | L13: Certificate Fee | M13: Test Paper Fee | N13: Paid | O13: Balance | P13: Total Due Now | Q13: Status
A14: 1 | B14: =IF(Students!B5="","",Students!B5) -> Ali Ahmed (example) | C14: ='Apr 2027'!F14 -> 12000 | D14: =IF(Students!D5="Yes",N(Students!E5),0) -> 2000 | F14: =N(C14)+N(D14)-N(E14) -> 14000 | G14: ='Apr 2027'!J14 -> 10500 | H14: =IF(Students!F5="Yes",N(Students!G5),0) -> 1500 | J14: =N(G14)+N(H14)-N(I14) -> 12000 | K14: ='Apr 2027'!O14 -> 200 | O14: =N(K14)+N(L14)+N(M14)-N(N14) -> 200 | P14: =F14+J14+O14 -> 26200 | Q14: =IF(B14="","",IF(P14<=0,"Clear",IF(E14+I14+N14>0,"Partial","Due"))) -> Due
A15: 2 | B15: =IF(Students!B6="","",Students!B6) | C15: ='Apr 2027'!F15 -> 0 | D15: =IF(Students!D6="Yes",N(Students!E6),0) -> 0 | F15: =N(C15)+N(D15)-N(E15) -> 0 | G15: ='Apr 2027'!J15 -> 0 | H15: =IF(Students!F6="Yes",N(Students!G6),0) -> 0 | J15: =N(G15)+N(H15)-N(I15) -> 0 | K15: ='Apr 2027'!O15 -> 0 | O15: =N(K15)+N(L15)+N(M15)-N(N15) -> 0 | P15: =F15+J15+O15 -> 0 | Q15: =IF(B15="","",IF(P15<=0,"Clear",IF(E15+I15+N15>0,"Partial","Due")))
A16: 3 | B16: =IF(Students!B7="","",Students!B7) | C16: ='Apr 2027'!F16 -> 0 | D16: =IF(Students!D7="Yes",N(Students!E7),0) -> 0 | F16: =N(C16)+N(D16)-N(E16) -> 0 | G16: ='Apr 2027'!J16 -> 0 | H16: =IF(Students!F7="Yes",N(Students!G7),0) -> 0 | J16: =N(G16)+N(H16)-N(I16) -> 0 | K16: ='Apr 2027'!O16 -> 0 | O16: =N(K16)+N(L16)+N(M16)-N(N16) -> 0 | P16: =F16+J16+O16 -> 0 | Q16: =IF(B16="","",IF(P16<=0,"Clear",IF(E16+I16+N16>0,"Partial","Due")))
A17: 4 | B17: =IF(Students!B8="","",Students!B8) | C17: ='Apr 2027'!F17 -> 0 | D17: =IF(Students!D8="Yes",N(Students!E8),0) -> 0 | F17: =N(C17)+N(D17)-N(E17) -> 0 | G17: ='Apr 2027'!J17 -> 0 | H17: =IF(Students!F8="Yes",N(Students!G8),0) -> 0 | J17: =N(G17)+N(H17)-N(I17) -> 0 | K17: ='Apr 2027'!O17 -> 0 | O17: =N(K17)+N(L17)+N(M17)-N(N17) -> 0 | P17: =F17+J17+O17 -> 0 | Q17: =IF(B17="","",IF(P17<=0,"Clear",IF(E17+I17+N17>0,"Partial","Due")))
A18: 5 | B18: =IF(Students!B9="","",Students!B9) | C18: ='Apr 2027'!F18 -> 0 | D18: =IF(Students!D9="Yes",N(Students!E9),0) -> 0 | F18: =N(C18)+N(D18)-N(E18) -> 0 | G18: ='Apr 2027'!J18 -> 0 | H18: =IF(Students!F9="Yes",N(Students!G9),0) -> 0 | J18: =N(G18)+N(H18)-N(I18) -> 0 | K18: ='Apr 2027'!O18 -> 0 | O18: =N(K18)+N(L18)+N(M18)-N(N18) -> 0 | P18: =F18+J18+O18 -> 0 | Q18: =IF(B18="","",IF(P18<=0,"Clear",IF(E18+I18+N18>0,"Partial","Due")))
A19: 6 | B19: =IF(Students!B10="","",Students!B10) | C19: ='Apr 2027'!F19 -> 0 | D19: =IF(Students!D10="Yes",N(Students!E10),0) -> 0 | F19: =N(C19)+N(D19)-N(E19) -> 0 | G19: ='Apr 2027'!J19 -> 0 | H19: =IF(Students!F10="Yes",N(Students!G10),0) -> 0 | J19: =N(G19)+N(H19)-N(I19) -> 0 | K19: ='Apr 2027'!O19 -> 0 | O19: =N(K19)+N(L19)+N(M19)-N(N19) -> 0 | P19: =F19+J19+O19 -> 0 | Q19: =IF(B19="","",IF(P19<=0,"Clear",IF(E19+I19+N19>0,"Partial","Due")))
