Workbook

Sheet Setup
A1: Kids Coaching — Setup
A2: Fill in the yellow cells once. Every month sheet uses these values.
A4: Academy Name | B4: Future Talent Academy Jamshoro
A6: Class 1 Name | B6: Kids Class 1
A7: Class 1 Teacher | B7: Miss Farzana
A9: Class 2 Name | B9: Kids Class 2
A10: Class 2 Teacher | B10: Miss Fozia
A12: Teacher Share | B12: 0.5
A13: Academy Share | B13: =1-B12 -> 0.5
A15: How it works
A16: 1. Students sheet: write each child's name and their own monthly fee (fees are different for each child).
A17: 2. Each month sheet shows both classes on the same page, side by side.
A18: 3. Each month, type only the AMOUNT the child paid.
A19: 4. Any unpaid fee carries forward to next month's 'Previous Due' automatically.
A20: 5. No certificate or test fees: monthly fee only.

Sheet Students
A1: Kids Coaching — Student List & Monthly Fees
A2: Write each child's name and their monthly fee. Keep the order the same; add new children at the bottom.
A3: =Setup!B6&" — "&Setup!B7 -> Kids Class 1 — Miss Farzana | F3: =Setup!B9&" — "&Setup!B10 -> Kids Class 2 — Miss Fozia
A4: Serial No | B4: Student Name | C4: Father Name | D4: Monthly Fee | F4: Serial No | G4: Student Name | H4: Father Name | I4: Monthly Fee
A5: 1 | B5: Sara (example) | C5: Imran Ali | D5: 1000 | F5: 1 | G5: Hamza (example) | H5: Abdul Rehman | I5: 1500
A6: 2 | F6: 2
A7: 3 | F7: 3
A8: 4 | F8: 4
A9: 5 | F9: 5
A10: 6 | F10: 6
A11: 7 | F11: 7
A12: 8 | F12: 8
A13: 9 | F13: 9
A14: 10 | F14: 10
A15: 11 | F15: 11
A16: 12 | F16: 12
A17: 13 | F17: 13
... A54: 50 | F54: 50

Sheet Oct 2026
A1: Future Talent Academy Jamshoro — Kids Coaching Fees: October 2026
A2: Yellow cells: type the amount each child paid. Previous dues come from last month automatically.
A4: =UPPER(Setup!B6) -> KIDS CLASS 1 | I4: =UPPER(Setup!B9) -> KIDS CLASS 2
A5: TEACHER SECTION | I5: TEACHER SECTION
A6: Teacher Name | D6: =Setup!B7 -> Miss Farzana | I6: Teacher Name | L6: =Setup!B10 -> Miss Fozia
A7: Fee Collected | D7: =E66 -> 1000 | I7: Fee Collected | L7: =M66 -> 500
A8: Teacher Share | D8: =E66*Setup!$B$12 -> 500 | I8: Teacher Share | L8: =M66*Setup!$B$12 -> 250
A9: Academy Share | D9: =E66*Setup!$B$13 -> 500 | I9: Academy Share | L9: =M66*Setup!$B$13 -> 250
A10: Pending Fees | D10: =F66 -> 0 | I10: Pending Fees | L10: =N66 -> 1000
A12: ACADEMY SECTION (both classes)
A13: Total Collected | C13: =E66+M66 -> 1500 | E13: Teachers' Share | G13: =D8+L8 -> 750 | I13: Academy Share | K13: =D9+L9 -> 750 | M13: Pending (both) | O13: =F66+N66 -> 1000
A15: Serial No | B15: Student Name | C15: Previous Due | D15: Monthly Fee | E15: Paid | F15: Balance | G15: Status | I15: Serial No | J15: Student Name | K15: Previous Due | L15: Monthly Fee | M15: Paid | N15: Balance | O15: Status
A16: 1 | B16: =IF(Students!B5="","",Students!B5) -> Sara (example) | D16: =IF(B16="",0,N(Students!D5)) -> 1000 | E16: 1000 | F16: =N(C16)+N(D16)-N(E16) -> 0 | G16: =IF(B16="","",IF(F16<=0,"Clear",IF(N(E16)>0,"Partial","Due"))) -> Clear | I16: 1 | J16: =IF(Students!G5="","",Students!G5) -> Hamza (example) | L16: =IF(J16="",0,N(Students!I5)) -> 1500 | M16: 500 | N16: =N(K16)+N(L16)-N(M16) -> 1000 | O16: =IF(J16="","",IF(N16<=0,"Clear",IF(N(M16)>0,"Partial","Due"))) -> Partial
A17: 2 | B17: =IF(Students!B6="","",Students!B6) | D17: =IF(B17="",0,N(Students!D6)) -> 0 | F17: =N(C17)+N(D17)-N(E17) -> 0 | G17: =IF(B17="","",IF(F17<=0,"Clear",IF(N(E17)>0,"Partial","Due"))) | I17: 2 | J17: =IF(Students!G6="","",Students!G6) | L17: =IF(J17="",0,N(Students!I6)) -> 0 | N17: =N(K17)+N(L17)-N(M17) -> 0 | O17: =IF(J17="","",IF(N17<=0,"Clear",IF(N(M17)>0,"Partial","Due")))
A18: 3 | B18: =IF(Students!B7="","",Students!B7) | D18: =IF(B18="",0,N(Students!D7)) -> 0 | F18: =N(C18)+N(D18)-N(E18) -> 0 | G18: =IF(B18="","",IF(F18<=0,"Clear",IF(N(E18)>0,"Partial","Due"))) | I18: 3 | J18: =IF(Students!G7="","",Students!G7) | L18: =IF(J18="",0,N(Students!I7)) -> 0 | N18: =N(K18)+N(L18)-N(M18) -> 0 | O18: =IF(J18="","",IF(N18<=0,"Clear",IF(N(M18)>0,"Partial","Due")))
A19: 4 | B19: =IF(Students!B8="","",Students!B8) | D19: =IF(B19="",0,N(Students!D8)) -> 0 | F19: =N(C19)+N(D19)-N(E19) -> 0 | G19: =IF(B19="","",IF(F19<=0,"Clear",IF(N(E19)>0,"Partial","Due"))) | I19: 4 | J19: =IF(Students!G8="","",Students!G8) | L19: =IF(J19="",0,N(Students!I8)) -> 0 | N19: =N(K19)+N(L19)-N(M19) -> 0 | O19: =IF(J19="","",IF(N19<=0,"Clear",IF(N(M19)>0,"Partial","Due")))
A20: 5 | B20: =IF(Students!B9="","",Students!B9) | D20: =IF(B20="",0,N(Students!D9)) -> 0 | F20: =N(C20)+N(D20)-N(E20) -> 0 | G20: =IF(B20="","",IF(F20<=0,"Clear",IF(N(E20)>0,"Partial","Due"))) | I20: 5 | J20: =IF(Students!G9="","",Students!G9) | L20: =IF(J20="",0,N(Students!I9)) -> 0 | N20: =N(K20)+N(L20)-N(M20) -> 0 | O20: =IF(J20="","",IF(N20<=0,"Clear",IF(N(M20)>0,"Partial","Due")))
A21: 6 | B21: =IF(Students!B10="","",Students!B10) | D21: =IF(B21="",0,N(Students!D10)) -> 0 | F21: =N(C21)+N(D21)-N(E21) -> 0 | G21: =IF(B21="","",IF(F21<=0,"Clear",IF(N(E21)>0,"Partial","Due"))) | I21: 6 | J21: =IF(Students!G10="","",Students!G10) | L21: =IF(J21="",0,N(Students!I10)) -> 0 | N21: =N(K21)+N(L21)-N(M21) -> 0 | O21: =IF(J21="","",IF(N21<=0,"Clear",IF(N(M21)>0,"Partial","Due")))
A22: 7 | B22: =IF(Students!B11="","",Students!B11) | D22: =IF(B22="",0,N(Students!D11)) -> 0 | F22: =N(C22)+N(D22)-N(E22) -> 0 | G22: =IF(B22="","",IF(F22<=0,"Clear",IF(N(E22)>0,"Partial","Due"))) | I22: 7 | J22: =IF(Students!G11="","",Students!G11) | L22: =IF(J22="",0,N(Students!I11)) -> 0 | N22: =N(K22)+N(L22)-N(M22) -> 0 | O22: =IF(J22="","",IF(N22<=0,"Clear",IF(N(M22)>0,"Partial","Due")))
A23: 8 | B23: =IF(Students!B12="","",Students!B12) | D23: =IF(B23="",0,N(Students!D12)) -> 0 | F23: =N(C23)+N(D23)-N(E23) -> 0 | G23: =IF(B23="","",IF(F23<=0,"Clear",IF(N(E23)>0,"Partial","Due"))) | I23: 8 | J23: =IF(Students!G12="","",Students!G12) | L23: =IF(J23="",0,N(Students!I12)) -> 0 | N23: =N(K23)+N(L23)-N(M23) -> 0 | O23: =IF(J23="","",IF(N23<=0,"Clear",IF(N(M23)>0,"Partial","Due")))
A24: 9 | B24: =IF(Students!B13="","",Students!B13) | D24: =IF(B24="",0,N(Students!D13)) -> 0 | F24: =N(C24)+N(D24)-N(E24) -> 0 | G24: =IF(B24="","",IF(F24<=0,"Clear",IF(N(E24)>0,"Partial","Due"))) | I24: 9 | J24: =IF(Students!G13="","",Students!G13) | L24: =IF(J24="",0,N(Students!I13)) -> 0 | N24: =N(K24)+N(L24)-N(M24) -> 0 | O24: =IF(J24="","",IF(N24<=0,"Clear",IF(N(M24)>0,"Partial","Due")))
A25: 10 | B25: =IF(Students!B14="","",Students!B14) | D25: =IF(B25="",0,N(Students!D14)) -> 0 | F25: =N(C25)+N(D25)-N(E25) -> 0 | G25: =IF(B25="","",IF(F25<=0,"Clear",IF(N(E25)>0,"Partial","Due"))) | I25: 10 | J25: =IF(Students!G14="","",Students!G14) | L25: =IF(J25="",0,N(Students!I14)) -> 0 | N25: =N(K25)+N(L25)-N(M25) -> 0 | O25: =IF(J25="","",IF(N25<=0,"Clear",IF(N(M25)>0,"Partial","Due")))
A26: 11 | B26: =IF(Students!B15="","",Students!B15) | D26: =IF(B26="",0,N(Students!D15)) -> 0 | F26: =N(C26)+N(D26)-N(E26) -> 0 | G26: =IF(B26="","",IF(F26<=0,"Clear",IF(N(E26)>0,"Partial","Due"))) | I26: 11 | J26: =IF(Students!G15="","",Students!G15) | L26: =IF(J26="",0,N(Students!I15)) -> 0 | N26: =N(K26)+N(L26)-N(M26) -> 0 | O26: =IF(J26="","",IF(N26<=0,"Clear",IF(N(M26)>0,"Partial","Due")))
A27: 12 | B27: =IF(Students!B16="","",Students!B16) | D27: =IF(B27="",0,N(Students!D16)) -> 0 | F27: =N(C27)+N(D27)-N(E27) -> 0 | G27: =IF(B27="","",IF(F27<=0,"Clear",IF(N(E27)>0,"Partial","Due"))) | I27: 12 | J27: =IF(Students!G16="","",Students!G16) | L27: =IF(J27="",0,N(Students!I16)) -> 0 | N27: =N(K27)+N(L27)-N(M27) -> 0 | O27: =IF(J27="","",IF(N27<=0,"Clear",IF(N(M27)>0,"Partial","Due")))
A28: 13 | B28: =IF(Students!B17="","",Students!B17) | D28: =IF(B28="",0,N(Students!D17)) -> 0 | F28: =N(C28)+N(D28)-N(E28) -> 0 | G28: =IF(B28="","",IF(F28<=0,"Clear",IF(N(E28)>0,"Partial","Due"))) | I28: 13 | J28: =IF(Students!G17="","",Students!G17) | L28: =IF(J28="",0,N(Students!I17)) -> 0 | N28: =N(K28)+N(L28)-N(M28) -> 0 | O28: =IF(J28="","",IF(N28<=0,"Clear",IF(N(M28)>0,"Partial","Due")))
... A65: 50 | B65: =IF(Students!B54="","",Students!B54) | D65: =IF(B65="",0,N(Students!D54)) -> 0 | F65: =N(C65)+N(D65)-N(E65) -> 0 | G65: =IF(B65="","",IF(F65<=0,"Clear",IF(N(E65)>0,"Partial","Due"))) | I65: 50 | J65: =IF(Students!G54="","",Students!G54) | L65: =IF(J65="",0,N(Students!I54)) -> 0 | N65: =N(K65)+N(L65)-N(M65) -> 0 | O65: =IF(J65="","",IF(N65<=0,"Clear",IF(N(M65)>0,"Partial","Due")))
A66: TOTAL | C66: =SUM(C16:C65) -> 0 | D66: =SUM(D16:D65) -> 1000 | E66: =SUM(E16:E65) -> 1000 | F66: =SUM(F16:F65) -> 0 | G66: =(COUNTIF(G16:G65,"Due")+COUNTIF(G16:G65,"Partial"))&" with dues" -> 0 with dues | I66: TOTAL | K66: =SUM(K16:K65) -> 0 | L66: =SUM(L16:L65) -> 1500 | M66: =SUM(M16:M65) -> 500 | N66: =SUM(N16:N65) -> 1000 | O66: =(COUNTIF(O16:O65,"Due")+COUNTIF(O16:O65,"Partial"))&" with dues" -> 1 with dues

Sheet Nov 2026
A1: Future Talent Academy Jamshoro — Kids Coaching Fees: November 2026
A2: Yellow cells: type the amount each child paid. Previous dues come from last month automatically.
A4: =UPPER(Setup!B6) -> KIDS CLASS 1 | I4: =UPPER(Setup!B9) -> KIDS CLASS 2
A5: TEACHER SECTION | I5: TEACHER SECTION
A6: Teacher Name | D6: =Setup!B7 -> Miss Farzana | I6: Teacher Name | L6: =Setup!B10 -> Miss Fozia
A7: Fee Collected | D7: =E66 -> 0 | I7: Fee Collected | L7: =M66 -> 0
A8: Teacher Share | D8: =E66*Setup!$B$12 -> 0 | I8: Teacher Share | L8: =M66*Setup!$B$12 -> 0
A9: Academy Share | D9: =E66*Setup!$B$13 -> 0 | I9: Academy Share | L9: =M66*Setup!$B$13 -> 0
A10: Pending Fees | D10: =F66 -> 1000 | I10: Pending Fees | L10: =N66 -> 2500
A12: ACADEMY SECTION (both classes)
A13: Total Collected | C13: =E66+M66 -> 0 | E13: Teachers' Share | G13: =D8+L8 -> 0 | I13: Academy Share | K13: =D9+L9 -> 0 | M13: Pending (both) | O13: =F66+N66 -> 3500
A15: Serial No | B15: Student Name | C15: Previous Due | D15: Monthly Fee | E15: Paid | F15: Balance | G15: Status | I15: Serial No | J15: Student Name | K15: Previous Due | L15: Monthly Fee | M15: Paid | N15: Balance | O15: Status
A16: 1 | B16: =IF(Students!B5="","",Students!B5) -> Sara (example) | C16: ='Oct 2026'!F16 -> 0 | D16: =IF(B16="",0,N(Students!D5)) -> 1000 | F16: =N(C16)+N(D16)-N(E16) -> 1000 | G16: =IF(B16="","",IF(F16<=0,"Clear",IF(N(E16)>0,"Partial","Due"))) -> Due | I16: 1 | J16: =IF(Students!G5="","",Students!G5) -> Hamza (example) | K16: ='Oct 2026'!N16 -> 1000 | L16: =IF(J16="",0,N(Students!I5)) -> 1500 | N16: =N(K16)+N(L16)-N(M16) -> 2500 | O16: =IF(J16="","",IF(N16<=0,"Clear",IF(N(M16)>0,"Partial","Due"))) -> Due
A17: 2 | B17: =IF(Students!B6="","",Students!B6) | C17: ='Oct 2026'!F17 -> 0 | D17: =IF(B17="",0,N(Students!D6)) -> 0 | F17: =N(C17)+N(D17)-N(E17) -> 0 | G17: =IF(B17="","",IF(F17<=0,"Clear",IF(N(E17)>0,"Partial","Due"))) | I17: 2 | J17: =IF(Students!G6="","",Students!G6) | K17: ='Oct 2026'!N17 -> 0 | L17: =IF(J17="",0,N(Students!I6)) -> 0 | N17: =N(K17)+N(L17)-N(M17) -> 0 | O17: =IF(J17="","",IF(N17<=0,"Clear",IF(N(M17)>0,"Partial","Due")))
A18: 3 | B18: =IF(Students!B7="","",Students!B7) | C18: ='Oct 2026'!F18 -> 0 | D18: =IF(B18="",0,N(Students!D7)) -> 0 | F18: =N(C18)+N(D18)-N(E18) -> 0 | G18: =IF(B18="","",IF(F18<=0,"Clear",IF(N(E18)>0,"Partial","Due"))) | I18: 3 | J18: =IF(Students!G7="","",Students!G7) | K18: ='Oct 2026'!N18 -> 0 | L18: =IF(J18="",0,N(Students!I7)) -> 0 | N18: =N(K18)+N(L18)-N(M18) -> 0 | O18: =IF(J18="","",IF(N18<=0,"Clear",IF(N(M18)>0,"Partial","Due")))
A19: 4 | B19: =IF(Students!B8="","",Students!B8) | C19: ='Oct 2026'!F19 -> 0 | D19: =IF(B19="",0,N(Students!D8)) -> 0 | F19: =N(C19)+N(D19)-N(E19) -> 0 | G19: =IF(B19="","",IF(F19<=0,"Clear",IF(N(E19)>0,"Partial","Due"))) | I19: 4 | J19: =IF(Students!G8="","",Students!G8) | K19: ='Oct 2026'!N19 -> 0 | L19: =IF(J19="",0,N(Students!I8)) -> 0 | N19: =N(K19)+N(L19)-N(M19) -> 0 | O19: =IF(J19="","",IF(N19<=0,"Clear",IF(N(M19)>0,"Partial","Due")))
A20: 5 | B20: =IF(Students!B9="","",Students!B9) | C20: ='Oct 2026'!F20 -> 0 | D20: =IF(B20="",0,N(Students!D9)) -> 0 | F20: =N(C20)+N(D20)-N(E20) -> 0 | G20: =IF(B20="","",IF(F20<=0,"Clear",IF(N(E20)>0,"Partial","Due"))) | I20: 5 | J20: =IF(Students!G9="","",Students!G9) | K20: ='Oct 2026'!N20 -> 0 | L20: =IF(J20="",0,N(Students!I9)) -> 0 | N20: =N(K20)+N(L20)-N(M20) -> 0 | O20: =IF(J20="","",IF(N20<=0,"Clear",IF(N(M20)>0,"Partial","Due")))
A21: 6 | B21: =IF(Students!B10="","",Students!B10) | C21: ='Oct 2026'!F21 -> 0 | D21: =IF(B21="",0,N(Students!D10)) -> 0 | F21: =N(C21)+N(D21)-N(E21) -> 0 | G21: =IF(B21="","",IF(F21<=0,"Clear",IF(N(E21)>0,"Partial","Due"))) | I21: 6 | J21: =IF(Students!G10="","",Students!G10) | K21: ='Oct 2026'!N21 -> 0 | L21: =IF(J21="",0,N(Students!I10)) -> 0 | N21: =N(K21)+N(L21)-N(M21) -> 0 | O21: =IF(J21="","",IF(N21<=0,"Clear",IF(N(M21)>0,"Partial","Due")))
A22: 7 | B22: =IF(Students!B11="","",Students!B11) | C22: ='Oct 2026'!F22 -> 0 | D22: =IF(B22="",0,N(Students!D11)) -> 0 | F22: =N(C22)+N(D22)-N(E22) -> 0 | G22: =IF(B22="","",IF(F22<=0,"Clear",IF(N(E22)>0,"Partial","Due"))) | I22: 7 | J22: =IF(Students!G11="","",Students!G11) | K22: ='Oct 2026'!N22 -> 0 | L22: =IF(J22="",0,N(Students!I11)) -> 0 | N22: =N(K22)+N(L22)-N(M22) -> 0 | O22: =IF(J22="","",IF(N22<=0,"Clear",IF(N(M22)>0,"Partial","Due")))
A23: 8 | B23: =IF(Students!B12="","",Students!B12) | C23: ='Oct 2026'!F23 -> 0 | D23: =IF(B23="",0,N(Students!D12)) -> 0 | F23: =N(C23)+N(D23)-N(E23) -> 0 | G23: =IF(B23="","",IF(F23<=0,"Clear",IF(N(E23)>0,"Partial","Due"))) | I23: 8 | J23: =IF(Students!G12="","",Students!G12) | K23: ='Oct 2026'!N23 -> 0 | L23: =IF(J23="",0,N(Students!I12)) -> 0 | N23: =N(K23)+N(L23)-N(M23) -> 0 | O23: =IF(J23="","",IF(N23<=0,"Clear",IF(N(M23)>0,"Partial","Due")))
A24: 9 | B24: =IF(Students!B13="","",Students!B13) | C24: ='Oct 2026'!F24 -> 0 | D24: =IF(B24="",0,N(Students!D13)) -> 0 | F24: =N(C24)+N(D24)-N(E24) -> 0 | G24: =IF(B24="","",IF(F24<=0,"Clear",IF(N(E24)>0,"Partial","Due"))) | I24: 9 | J24: =IF(Students!G13="","",Students!G13) | K24: ='Oct 2026'!N24 -> 0 | L24: =IF(J24="",0,N(Students!I13)) -> 0 | N24: =N(K24)+N(L24)-N(M24) -> 0 | O24: =IF(J24="","",IF(N24<=0,"Clear",IF(N(M24)>0,"Partial","Due")))
A25: 10 | B25: =IF(Students!B14="","",Students!B14) | C25: ='Oct 2026'!F25 -> 0 | D25: =IF(B25="",0,N(Students!D14)) -> 0 | F25: =N(C25)+N(D25)-N(E25) -> 0 | G25: =IF(B25="","",IF(F25<=0,"Clear",IF(N(E25)>0,"Partial","Due"))) | I25: 10 | J25: =IF(Students!G14="","",Students!G14) | K25: ='Oct 2026'!N25 -> 0 | L25: =IF(J25="",0,N(Students!I14)) -> 0 | N25: =N(K25)+N(L25)-N(M25) -> 0 | O25: =IF(J25="","",IF(N25<=0,"Clear",IF(N(M25)>0,"Partial","Due")))
A26: 11 | B26: =IF(Students!B15="","",Students!B15) | C26: ='Oct 2026'!F26 -> 0 | D26: =IF(B26="",0,N(Students!D15)) -> 0 | F26: =N(C26)+N(D26)-N(E26) -> 0 | G26: =IF(B26="","",IF(F26<=0,"Clear",IF(N(E26)>0,"Partial","Due"))) | I26: 11 | J26: =IF(Students!G15="","",Students!G15) | K26: ='Oct 2026'!N26 -> 0 | L26: =IF(J26="",0,N(Students!I15)) -> 0 | N26: =N(K26)+N(L26)-N(M26) -> 0 | O26: =IF(J26="","",IF(N26<=0,"Clear",IF(N(M26)>0,"Partial","Due")))
A27: 12 | B27: =IF(Students!B16="","",Students!B16) | C27: ='Oct 2026'!F27 -> 0 | D27: =IF(B27="",0,N(Students!D16)) -> 0 | F27: =N(C27)+N(D27)-N(E27) -> 0 | G27: =IF(B27="","",IF(F27<=0,"Clear",IF(N(E27)>0,"Partial","Due"))) | I27: 12 | J27: =IF(Students!G16="","",Students!G16) | K27: ='Oct 2026'!N27 -> 0 | L27: =IF(J27="",0,N(Students!I16)) -> 0 | N27: =N(K27)+N(L27)-N(M27) -> 0 | O27: =IF(J27="","",IF(N27<=0,"Clear",IF(N(M27)>0,"Partial","Due")))
... A65: 50 | B65: =IF(Students!B54="","",Students!B54) | C65: ='Oct 2026'!F65 -> 0 | D65: =IF(B65="",0,N(Students!D54)) -> 0 | F65: =N(C65)+N(D65)-N(E65) -> 0 | G65: =IF(B65="","",IF(F65<=0,"Clear",IF(N(E65)>0,"Partial","Due"))) | I65: 50 | J65: =IF(Students!G54="","",Students!G54) | K65: ='Oct 2026'!N65 -> 0 | L65: =IF(J65="",0,N(Students!I54)) -> 0 | N65: =N(K65)+N(L65)-N(M65) -> 0 | O65: =IF(J65="","",IF(N65<=0,"Clear",IF(N(M65)>0,"Partial","Due")))
A66: TOTAL | C66: =SUM(C16:C65) -> 0 | D66: =SUM(D16:D65) -> 1000 | E66: =SUM(E16:E65) -> 0 | F66: =SUM(F16:F65) -> 1000 | G66: =(COUNTIF(G16:G65,"Due")+COUNTIF(G16:G65,"Partial"))&" with dues" -> 1 with dues | I66: TOTAL | K66: =SUM(K16:K65) -> 1000 | L66: =SUM(L16:L65) -> 1500 | M66: =SUM(M16:M65) -> 0 | N66: =SUM(N16:N65) -> 2500 | O66: =(COUNTIF(O16:O65,"Due")+COUNTIF(O16:O65,"Partial"))&" with dues" -> 1 with dues

Sheet Dec 2026
A1: Future Talent Academy Jamshoro — Kids Coaching Fees: December 2026
A2: Yellow cells: type the amount each child paid. Previous dues come from last month automatically.
A4: =UPPER(Setup!B6) -> KIDS CLASS 1 | I4: =UPPER(Setup!B9) -> KIDS CLASS 2
A5: TEACHER SECTION | I5: TEACHER SECTION
A6: Teacher Name | D6: =Setup!B7 -> Miss Farzana | I6: Teacher Name | L6: =Setup!B10 -> Miss Fozia
A7: Fee Collected | D7: =E66 -> 0 | I7: Fee Collected | L7: =M66 -> 0
A8: Teacher Share | D8: =E66*Setup!$B$12 -> 0 | I8: Teacher Share | L8: =M66*Setup!$B$12 -> 0
A9: Academy Share | D9: =E66*Setup!$B$13 -> 0 | I9: Academy Share | L9: =M66*Setup!$B$13 -> 0
A10: Pending Fees | D10: =F66 -> 2000 | I10: Pending Fees | L10: =N66 -> 4000
A12: ACADEMY SECTION (both classes)
A13: Total Collected | C13: =E66+M66 -> 0 | E13: Teachers' Share | G13: =D8+L8 -> 0 | I13: Academy Share | K13: =D9+L9 -> 0 | M13: Pending (both) | O13: =F66+N66 -> 6000
A15: Serial No | B15: Student Name | C15: Previous Due | D15: Monthly Fee | E15: Paid | F15: Balance | G15: Status | I15: Serial No | J15: Student Name | K15: Previous Due | L15: Monthly Fee | M15: Paid | N15: Balance | O15: Status
A16: 1 | B16: =IF(Students!B5="","",Students!B5) -> Sara (example) | C16: ='Nov 2026'!F16 -> 1000 | D16: =IF(B16="",0,N(Students!D5)) -> 1000 | F16: =N(C16)+N(D16)-N(E16) -> 2000 | G16: =IF(B16="","",IF(F16<=0,"Clear",IF(N(E16)>0,"Partial","Due"))) -> Due | I16: 1 | J16: =IF(Students!G5="","",Students!G5) -> Hamza (example) | K16: ='Nov 2026'!N16 -> 2500 | L16: =IF(J16="",0,N(Students!I5)) -> 1500 | N16: =N(K16)+N(L16)-N(M16) -> 4000 | O16: =IF(J16="","",IF(N16<=0,"Clear",IF(N(M16)>0,"Partial","Due"))) -> Due
A17: 2 | B17: =IF(Students!B6="","",Students!B6) | C17: ='Nov 2026'!F17 -> 0 | D17: =IF(B17="",0,N(Students!D6)) -> 0 | F17: =N(C17)+N(D17)-N(E17) -> 0 | G17: =IF(B17="","",IF(F17<=0,"Clear",IF(N(E17)>0,"Partial","Due"))) | I17: 2 | J17: =IF(Students!G6="","",Students!G6) | K17: ='Nov 2026'!N17 -> 0 | L17: =IF(J17="",0,N(Students!I6)) -> 0 | N17: =N(K17)+N(L17)-N(M17) -> 0 | O17: =IF(J17="","",IF(N17<=0,"Clear",IF(N(M17)>0,"Partial","Due")))
A18: 3 | B18: =IF(Students!B7="","",Students!B7) | C18: ='Nov 2026'!F18 -> 0 | D18: =IF(B18="",0,N(Students!D7)) -> 0 | F18: =N(C18)+N(D18)-N(E18) -> 0 | G18: =IF(B18="","",IF(F18<=0,"Clear",IF(N(E18)>0,"Partial","Due"))) | I18: 3 | J18: =IF(Students!G7="","",Students!G7) | K18: ='Nov 2026'!N18 -> 0 | L18: =IF(J18="",0,N(Students!I7)) -> 0 | N18: =N(K18)+N(L18)-N(M18) -> 0 | O18: =IF(J18="","",IF(N18<=0,"Clear",IF(N(M18)>0,"Partial","Due")))
A19: 4 | B19: =IF(Students!B8="","",Students!B8) | C19: ='Nov 2026'!F19 -> 0 | D19: =IF(B19="",0,N(Students!D8)) -> 0 | F19: =N(C19)+N(D19)-N(E19) -> 0 | G19: =IF(B19="","",IF(F19<=0,"Clear",IF(N(E19)>0,"Partial","Due"))) | I19: 4 | J19: =IF(Students!G8="","",Students!G8) | K19: ='Nov 2026'!N19 -> 0 | L19: =IF(J19="",0,N(Students!I8)) -> 0 | N19: =N(K19)+N(L19)-N(M19) -> 0 | O19: =IF(J19="","",IF(N19<=0,"Clear",IF(N(M19)>0,"Partial","Due")))
A20: 5 | B20: =IF(Students!B9="","",Students!B9) | C20: ='Nov 2026'!F20 -> 0 | D20: =IF(B20="",0,N(Students!D9)) -> 0 | F20: =N(C20)+N(D20)-N(E20) -> 0 | G20: =IF(B20="","",IF(F20<=0,"Clear",IF(N(E20)>0,"Partial","Due"))) | I20: 5 | J20: =IF(Students!G9="","",Students!G9) | K20: ='Nov 2026'!N20 -> 0 | L20: =IF(J20="",0,N(Students!I9)) -> 0 | N20: =N(K20)+N(L20)-N(M20) -> 0 | O20: =IF(J20="","",IF(N20<=0,"Clear",IF(N(M20)>0,"Partial","Due")))
A21: 6 | B21: =IF(Students!B10="","",Students!B10) | C21: ='Nov 2026'!F21 -> 0 | D21: =IF(B21="",0,N(Students!D10)) -> 0 | F21: =N(C21)+N(D21)-N(E21) -> 0 | G21: =IF(B21="","",IF(F21<=0,"Clear",IF(N(E21)>0,"Partial","Due"))) | I21: 6 | J21: =IF(Students!G10="","",Students!G10) | K21: ='Nov 2026'!N21 -> 0 | L21: =IF(J21="",0,N(Students!I10)) -> 0 | N21: =N(K21)+N(L21)-N(M21) -> 0 | O21: =IF(J21="","",IF(N21<=0,"Clear",IF(N(M21)>0,"Partial","Due")))
A22: 7 | B22: =IF(Students!B11="","",Students!B11) | C22: ='Nov 2026'!F22 -> 0 | D22: =IF(B22="",0,N(Students!D11)) -> 0 | F22: =N(C22)+N(D22)-N(E22) -> 0 | G22: =IF(B22="","",IF(F22<=0,"Clear",IF(N(E22)>0,"Partial","Due"))) | I22: 7 | J22: =IF(Students!G11="","",Students!G11) | K22: ='Nov 2026'!N22 -> 0 | L22: =IF(J22="",0,N(Students!I11)) -> 0 | N22: =N(K22)+N(L22)-N(M22) -> 0 | O22: =IF(J22="","",IF(N22<=0,"Clear",IF(N(M22)>0,"Partial","Due")))
A23: 8 | B23: =IF(Students!B12="","",Students!B12) | C23: ='Nov 2026'!F23 -> 0 | D23: =IF(B23="",0,N(Students!D12)) -> 0 | F23: =N(C23)+N(D23)-N(E23) -> 0 | G23: =IF(B23="","",IF(F23<=0,"Clear",IF(N(E23)>0,"Partial","Due"))) | I23: 8 | J23: =IF(Students!G12="","",Students!G12) | K23: ='Nov 2026'!N23 -> 0 | L23: =IF(J23="",0,N(Students!I12)) -> 0 | N23: =N(K23)+N(L23)-N(M23) -> 0 | O23: =IF(J23="","",IF(N23<=0,"Clear",IF(N(M23)>0,"Partial","Due")))
A24: 9 | B24: =IF(Students!B13="","",Students!B13) | C24: ='Nov 2026'!F24 -> 0 | D24: =IF(B24="",0,N(Students!D13)) -> 0 | F24: =N(C24)+N(D24)-N(E24) -> 0 | G24: =IF(B24="","",IF(F24<=0,"Clear",IF(N(E24)>0,"Partial","Due"))) | I24: 9 | J24: =IF(Students!G13="","",Students!G13) | K24: ='Nov 2026'!N24 -> 0 | L24: =IF(J24="",0,N(Students!I13)) -> 0 | N24: =N(K24)+N(L24)-N(M24) -> 0 | O24: =IF(J24="","",IF(N24<=0,"Clear",IF(N(M24)>0,"Partial","Due")))
A25: 10 | B25: =IF(Students!B14="","",Students!B14) | C25: ='Nov 2026'!F25 -> 0 | D25: =IF(B25="",0,N(Students!D14)) -> 0 | F25: =N(C25)+N(D25)-N(E25) -> 0 | G25: =IF(B25="","",IF(F25<=0,"Clear",IF(N(E25)>0,"Partial","Due"))) | I25: 10 | J25: =IF(Students!G14="","",Students!G14) | K25: ='Nov 2026'!N25 -> 0 | L25: =IF(J25="",0,N(Students!I14)) -> 0 | N25: =N(K25)+N(L25)-N(M25) -> 0 | O25: =IF(J25="","",IF(N25<=0,"Clear",IF(N(M25)>0,"Partial","Due")))
A26: 11 | B26: =IF(Students!B15="","",Students!B15) | C26: ='Nov 2026'!F26 -> 0 | D26: =IF(B26="",0,N(Students!D15)) -> 0 | F26: =N(C26)+N(D26)-N(E26) -> 0 | G26: =IF(B26="","",IF(F26<=0,"Clear",IF(N(E26)>0,"Partial","Due"))) | I26: 11 | J26: =IF(Students!G15="","",Students!G15) | K26: ='Nov 2026'!N26 -> 0 | L26: =IF(J26="",0,N(Students!I15)) -> 0 | N26: =N(K26)+N(L26)-N(M26) -> 0 | O26: =IF(J26="","",IF(N26<=0,"Clear",IF(N(M26)>0,"Partial","Due")))
A27: 12 | B27: =IF(Students!B16="","",Students!B16) | C27: ='Nov 2026'!F27 -> 0 | D27: =IF(B27="",0,N(Students!D16)) -> 0 | F27: =N(C27)+N(D27)-N(E27) -> 0 | G27: =IF(B27="","",IF(F27<=0,"Clear",IF(N(E27)>0,"Partial","Due"))) | I27: 12 | J27: =IF(Students!G16="","",Students!G16) | K27: ='Nov 2026'!N27 -> 0 | L27: =IF(J27="",0,N(Students!I16)) -> 0 | N27: =N(K27)+N(L27)-N(M27) -> 0 | O27: =IF(J27="","",IF(N27<=0,"Clear",IF(N(M27)>0,"Partial","Due")))
... A65: 50 | B65: =IF(Students!B54="","",Students!B54) | C65: ='Nov 2026'!F65 -> 0 | D65: =IF(B65="",0,N(Students!D54)) -> 0 | F65: =N(C65)+N(D65)-N(E65) -> 0 | G65: =IF(B65="","",IF(F65<=0,"Clear",IF(N(E65)>0,"Partial","Due"))) | I65: 50 | J65: =IF(Students!G54="","",Students!G54) | K65: ='Nov 2026'!N65 -> 0 | L65: =IF(J65="",0,N(Students!I54)) -> 0 | N65: =N(K65)+N(L65)-N(M65) -> 0 | O65: =IF(J65="","",IF(N65<=0,"Clear",IF(N(M65)>0,"Partial","Due")))
A66: TOTAL | C66: =SUM(C16:C65) -> 1000 | D66: =SUM(D16:D65) -> 1000 | E66: =SUM(E16:E65) -> 0 | F66: =SUM(F16:F65) -> 2000 | G66: =(COUNTIF(G16:G65,"Due")+COUNTIF(G16:G65,"Partial"))&" with dues" -> 1 with dues | I66: TOTAL | K66: =SUM(K16:K65) -> 2500 | L66: =SUM(L16:L65) -> 1500 | M66: =SUM(M16:M65) -> 0 | N66: =SUM(N16:N65) -> 4000 | O66: =(COUNTIF(O16:O65,"Due")+COUNTIF(O16:O65,"Partial"))&" with dues" -> 1 with dues

Sheet Jan 2027
A1: Future Talent Academy Jamshoro — Kids Coaching Fees: January 2027
A2: Yellow cells: type the amount each child paid. Previous dues come from last month automatically.
A4: =UPPER(Setup!B6) -> KIDS CLASS 1 | I4: =UPPER(Setup!B9) -> KIDS CLASS 2
A5: TEACHER SECTION | I5: TEACHER SECTION
A6: Teacher Name | D6: =Setup!B7 -> Miss Farzana | I6: Teacher Name | L6: =Setup!B10 -> Miss Fozia
A7: Fee Collected | D7: =E66 -> 0 | I7: Fee Collected | L7: =M66 -> 0
A8: Teacher Share | D8: =E66*Setup!$B$12 -> 0 | I8: Teacher Share | L8: =M66*Setup!$B$12 -> 0
A9: Academy Share | D9: =E66*Setup!$B$13 -> 0 | I9: Academy Share | L9: =M66*Setup!$B$13 -> 0
A10: Pending Fees | D10: =F66 -> 3000 | I10: Pending Fees | L10: =N66 -> 5500
A12: ACADEMY SECTION (both classes)
A13: Total Collected | C13: =E66+M66 -> 0 | E13: Teachers' Share | G13: =D8+L8 -> 0 | I13: Academy Share | K13: =D9+L9 -> 0 | M13: Pending (both) | O13: =F66+N66 -> 8500
A15: Serial No | B15: Student Name | C15: Previous Due | D15: Monthly Fee | E15: Paid | F15: Balance | G15: Status | I15: Serial No | J15: Student Name | K15: Previous Due | L15: Monthly Fee | M15: Paid | N15: Balance | O15: Status
A16: 1 | B16: =IF(Students!B5="","",Students!B5) -> Sara (example) | C16: ='Dec 2026'!F16 -> 2000 | D16: =IF(B16="",0,N(Students!D5)) -> 1000 | F16: =N(C16)+N(D16)-N(E16) -> 3000 | G16: =IF(B16="","",IF(F16<=0,"Clear",IF(N(E16)>0,"Partial","Due"))) -> Due | I16: 1 | J16: =IF(Students!G5="","",Students!G5) -> Hamza (example) | K16: ='Dec 2026'!N16 -> 4000 | L16: =IF(J16="",0,N(Students!I5)) -> 1500 | N16: =N(K16)+N(L16)-N(M16) -> 5500 | O16: =IF(J16="","",IF(N16<=0,"Clear",IF(N(M16)>0,"Partial","Due"))) -> Due
A17: 2 | B17: =IF(Students!B6="","",Students!B6) | C17: ='Dec 2026'!F17 -> 0 | D17: =IF(B17="",0,N(Students!D6)) -> 0 | F17: =N(C17)+N(D17)-N(E17) -> 0 | G17: =IF(B17="","",IF(F17<=0,"Clear",IF(N(E17)>0,"Partial","Due"))) | I17: 2 | J17: =IF(Students!G6="","",Students!G6) | K17: ='Dec 2026'!N17 -> 0 | L17: =IF(J17="",0,N(Students!I6)) -> 0 | N17: =N(K17)+N(L17)-N(M17) -> 0 | O17: =IF(J17="","",IF(N17<=0,"Clear",IF(N(M17)>0,"Partial","Due")))
A18: 3 | B18: =IF(Students!B7="","",Students!B7) | C18: ='Dec 2026'!F18 -> 0 | D18: =IF(B18="",0,N(Students!D7)) -> 0 | F18: =N(C18)+N(D18)-N(E18) -> 0 | G18: =IF(B18="","",IF(F18<=0,"Clear",IF(N(E18)>0,"Partial","Due"))) | I18: 3 | J18: =IF(Students!G7="","",Students!G7) | K18: ='Dec 2026'!N18 -> 0 | L18: =IF(J18="",0,N(Students!I7)) -> 0 | N18: =N(K18)+N(L18)-N(M18) -> 0 | O18: =IF(J18="","",IF(N18<=0,"Clear",IF(N(M18)>0,"Partial","Due")))
A19: 4 | B19: =IF(Students!B8="","",Students!B8) | C19: ='Dec 2026'!F19 -> 0 | D19: =IF(B19="",0,N(Students!D8)) -> 0 | F19: =N(C19)+N(D19)-N(E19) -> 0 | G19: =IF(B19="","",IF(F19<=0,"Clear",IF(N(E19)>0,"Partial","Due"))) | I19: 4 | J19: =IF(Students!G8="","",Students!G8) | K19: ='Dec 2026'!N19 -> 0 | L19: =IF(J19="",0,N(Students!I8)) -> 0 | N19: =N(K19)+N(L19)-N(M19) -> 0 | O19: =IF(J19="","",IF(N19<=0,"Clear",IF(N(M19)>0,"Partial","Due")))
A20: 5 | B20: =IF(Students!B9="","",Students!B9) | C20: ='Dec 2026'!F20 -> 0 | D20: =IF(B20="",0,N(Students!D9)) -> 0 | F20: =N(C20)+N(D20)-N(E20) -> 0 | G20: =IF(B20="","",IF(F20<=0,"Clear",IF(N(E20)>0,"Partial","Due"))) | I20: 5 | J20: =IF(Students!G9="","",Students!G9) | K20: ='Dec 2026'!N20 -> 0 | L20: =IF(J20="",0,N(Students!I9)) -> 0 | N20: =N(K20)+N(L20)-N(M20) -> 0 | O20: =IF(J20="","",IF(N20<=0,"Clear",IF(N(M20)>0,"Partial","Due")))
A21: 6 | B21: =IF(Students!B10="","",Students!B10) | C21: ='Dec 2026'!F21 -> 0 | D21: =IF(B21="",0,N(Students!D10)) -> 0 | F21: =N(C21)+N(D21)-N(E21) -> 0 | G21: =IF(B21="","",IF(F21<=0,"Clear",IF(N(E21)>0,"Partial","Due"))) | I21: 6 | J21: =IF(Students!G10="","",Students!G10) | K21: ='Dec 2026'!N21 -> 0 | L21: =IF(J21="",0,N(Students!I10)) -> 0 | N21: =N(K21)+N(L21)-N(M21) -> 0 | O21: =IF(J21="","",IF(N21<=0,"Clear",IF(N(M21)>0,"Partial","Due")))
A22: 7 | B22: =IF(Students!B11="","",Students!B11) | C22: ='Dec 2026'!F22 -> 0 | D22: =IF(B22="",0,N(Students!D11)) -> 0 | F22: =N(C22)+N(D22)-N(E22) -> 0 | G22: =IF(B22="","",IF(F22<=0,"Clear",IF(N(E22)>0,"Partial","Due"))) | I22: 7 | J22: =IF(Students!G11="","",Students!G11) | K22: ='Dec 2026'!N22 -> 0 | L22: =IF(J22="",0,N(Students!I11)) -> 0 | N22: =N(K22)+N(L22)-N(M22) -> 0 | O22: =IF(J22="","",IF(N22<=0,"Clear",IF(N(M22)>0,"Partial","Due")))
A23: 8 | B23: =IF(Students!B12="","",Students!B12) | C23: ='Dec 2026'!F23 -> 0 | D23: =IF(B23="",0,N(Students!D12)) -> 0 | F23: =N(C23)+N(D23)-N(E23) -> 0 | G23: =IF(B23="","",IF(F23<=0,"Clear",IF(N(E23)>0,"Partial","Due"))) | I23: 8 | J23: =IF(Students!G12="","",Students!G12) | K23: ='Dec 2026'!N23 -> 0 | L23: =IF(J23="",0,N(Students!I12)) -> 0 | N23: =N(K23)+N(L23)-N(M23) -> 0 | O23: =IF(J23="","",IF(N23<=0,"Clear",IF(N(M23)>0,"Partial","Due")))
A24: 9 | B24: =IF(Students!B13="","",Students!B13) | C24: ='Dec 2026'!F24 -> 0 | D24: =IF(B24="",0,N(Students!D13)) -> 0 | F24: =N(C24)+N(D24)-N(E24) -> 0 | G24: =IF(B24="","",IF(F24<=0,"Clear",IF(N(E24)>0,"Partial","Due"))) | I24: 9 | J24: =IF(Students!G13="","",Students!G13) | K24: ='Dec 2026'!N24 -> 0 | L24: =IF(J24="",0,N(Students!I13)) -> 0 | N24: =N(K24)+N(L24)-N(M24) -> 0 | O24: =IF(J24="","",IF(N24<=0,"Clear",IF(N(M24)>0,"Partial","Due")))
A25: 10 | B25: =IF(Students!B14="","",Students!B14) | C25: ='Dec 2026'!F25 -> 0 | D25: =IF(B25="",0,N(Students!D14)) -> 0 | F25: =N(C25)+N(D25)-N(E25) -> 0 | G25: =IF(B25="","",IF(F25<=0,"Clear",IF(N(E25)>0,"Partial","Due"))) | I25: 10 | J25: =IF(Students!G14="","",Students!G14) | K25: ='Dec 2026'!N25 -> 0 | L25: =IF(J25="",0,N(Students!I14)) -> 0 | N25: =N(K25)+N(L25)-N(M25) -> 0 | O25: =IF(J25="","",IF(N25<=0,"Clear",IF(N(M25)>0,"Partial","Due")))
A26: 11 | B26: =IF(Students!B15="","",Students!B15) | C26: ='Dec 2026'!F26 -> 0 | D26: =IF(B26="",0,N(Students!D15)) -> 0 | F26: =N(C26)+N(D26)-N(E26) -> 0 | G26: =IF(B26="","",IF(F26<=0,"Clear",IF(N(E26)>0,"Partial","Due"))) | I26: 11 | J26: =IF(Students!G15="","",Students!G15) | K26: ='Dec 2026'!N26 -> 0 | L26: =IF(J26="",0,N(Students!I15)) -> 0 | N26: =N(K26)+N(L26)-N(M26) -> 0 | O26: =IF(J26="","",IF(N26<=0,"Clear",IF(N(M26)>0,"Partial","Due")))
A27: 12 | B27: =IF(Students!B16="","",Students!B16) | C27: ='Dec 2026'!F27 -> 0 | D27: =IF(B27="",0,N(Students!D16)) -> 0 | F27: =N(C27)+N(D27)-N(E27) -> 0 | G27: =IF(B27="","",IF(F27<=0,"Clear",IF(N(E27)>0,"Partial","Due"))) | I27: 12 | J27: =IF(Students!G16="","",Students!G16) | K27: ='Dec 2026'!N27 -> 0 | L27: =IF(J27="",0,N(Students!I16)) -> 0 | N27: =N(K27)+N(L27)-N(M27) -> 0 | O27: =IF(J27="","",IF(N27<=0,"Clear",IF(N(M27)>0,"Partial","Due")))
... A65: 50 | B65: =IF(Students!B54="","",Students!B54) | C65: ='Dec 2026'!F65 -> 0 | D65: =IF(B65="",0,N(Students!D54)) -> 0 | F65: =N(C65)+N(D65)-N(E65) -> 0 | G65: =IF(B65="","",IF(F65<=0,"Clear",IF(N(E65)>0,"Partial","Due"))) | I65: 50 | J65: =IF(Students!G54="","",Students!G54) | K65: ='Dec 2026'!N65 -> 0 | L65: =IF(J65="",0,N(Students!I54)) -> 0 | N65: =N(K65)+N(L65)-N(M65) -> 0 | O65: =IF(J65="","",IF(N65<=0,"Clear",IF(N(M65)>0,"Partial","Due")))
A66: TOTAL | C66: =SUM(C16:C65) -> 2000 | D66: =SUM(D16:D65) -> 1000 | E66: =SUM(E16:E65) -> 0 | F66: =SUM(F16:F65) -> 3000 | G66: =(COUNTIF(G16:G65,"Due")+COUNTIF(G16:G65,"Partial"))&" with dues" -> 1 with dues | I66: TOTAL | K66: =SUM(K16:K65) -> 4000 | L66: =SUM(L16:L65) -> 1500 | M66: =SUM(M16:M65) -> 0 | N66: =SUM(N16:N65) -> 5500 | O66: =(COUNTIF(O16:O65,"Due")+COUNTIF(O16:O65,"Partial"))&" with dues" -> 1 with dues

Sheet Feb 2027
A1: Future Talent Academy Jamshoro — Kids Coaching Fees: February 2027
A2: Yellow cells: type the amount each child paid. Previous dues come from last month automatically.
A4: =UPPER(Setup!B6) -> KIDS CLASS 1 | I4: =UPPER(Setup!B9) -> KIDS CLASS 2
A5: TEACHER SECTION | I5: TEACHER SECTION
A6: Teacher Name | D6: =Setup!B7 -> Miss Farzana | I6: Teacher Name | L6: =Setup!B10 -> Miss Fozia
A7: Fee Collected | D7: =E66 -> 0 | I7: Fee Collected | L7: =M66 -> 0
A8: Teacher Share | D8: =E66*Setup!$B$12 -> 0 | I8: Teacher Share | L8: =M66*Setup!$B$12 -> 0
A9: Academy Share | D9: =E66*Setup!$B$13 -> 0 | I9: Academy Share | L9: =M66*Setup!$B$13 -> 0
A10: Pending Fees | D10: =F66 -> 4000 | I10: Pending Fees | L10: =N66 -> 7000
A12: ACADEMY SECTION (both classes)
A13: Total Collected | C13: =E66+M66 -> 0 | E13: Teachers' Share | G13: =D8+L8 -> 0 | I13: Academy Share | K13: =D9+L9 -> 0 | M13: Pending (both) | O13: =F66+N66 -> 11000
A15: Serial No | B15: Student Name | C15: Previous Due | D15: Monthly Fee | E15: Paid | F15: Balance | G15: Status | I15: Serial No | J15: Student Name | K15: Previous Due | L15: Monthly Fee | M15: Paid | N15: Balance | O15: Status
A16: 1 | B16: =IF(Students!B5="","",Students!B5) -> Sara (example) | C16: ='Jan 2027'!F16 -> 3000 | D16: =IF(B16="",0,N(Students!D5)) -> 1000 | F16: =N(C16)+N(D16)-N(E16) -> 4000 | G16: =IF(B16="","",IF(F16<=0,"Clear",IF(N(E16)>0,"Partial","Due"))) -> Due | I16: 1 | J16: =IF(Students!G5="","",Students!G5) -> Hamza (example) | K16: ='Jan 2027'!N16 -> 5500 | L16: =IF(J16="",0,N(Students!I5)) -> 1500 | N16: =N(K16)+N(L16)-N(M16) -> 7000 | O16: =IF(J16="","",IF(N16<=0,"Clear",IF(N(M16)>0,"Partial","Due"))) -> Due
A17: 2 | B17: =IF(Students!B6="","",Students!B6) | C17: ='Jan 2027'!F17 -> 0 | D17: =IF(B17="",0,N(Students!D6)) -> 0 | F17: =N(C17)+N(D17)-N(E17) -> 0 | G17: =IF(B17="","",IF(F17<=0,"Clear",IF(N(E17)>0,"Partial","Due"))) | I17: 2 | J17: =IF(Students!G6="","",Students!G6) | K17: ='Jan 2027'!N17 -> 0 | L17: =IF(J17="",0,N(Students!I6)) -> 0 | N17: =N(K17)+N(L17)-N(M17) -> 0 | O17: =IF(J17="","",IF(N17<=0,"Clear",IF(N(M17)>0,"Partial","Due")))
A18: 3 | B18: =IF(Students!B7="","",Students!B7) | C18: ='Jan 2027'!F18 -> 0 | D18: =IF(B18="",0,N(Students!D7)) -> 0 | F18: =N(C18)+N(D18)-N(E18) -> 0 | G18: =IF(B18="","",IF(F18<=0,"Clear",IF(N(E18)>0,"Partial","Due"))) | I18: 3 | J18: =IF(Students!G7="","",Students!G7) | K18: ='Jan 2027'!N18 -> 0 | L18: =IF(J18="",0,N(Students!I7)) -> 0 | N18: =N(K18)+N(L18)-N(M18) -> 0 | O18: =IF(J18="","",IF(N18<=0,"Clear",IF(N(M18)>0,"Partial","Due")))
A19: 4 | B19: =IF(Students!B8="","",Students!B8) | C19: ='Jan 2027'!F19 -> 0 | D19: =IF(B19="",0,N(Students!D8)) -> 0 | F19: =N(C19)+N(D19)-N(E19) -> 0 | G19: =IF(B19="","",IF(F19<=0,"Clear",IF(N(E19)>0,"Partial","Due"))) | I19: 4 | J19: =IF(Students!G8="","",Students!G8) | K19: ='Jan 2027'!N19 -> 0 | L19: =IF(J19="",0,N(Students!I8)) -> 0 | N19: =N(K19)+N(L19)-N(M19) -> 0 | O19: =IF(J19="","",IF(N19<=0,"Clear",IF(N(M19)>0,"Partial","Due")))
A20: 5 | B20: =IF(Students!B9="","",Students!B9) | C20: ='Jan 2027'!F20 -> 0 | D20: =IF(B20="",0,N(Students!D9)) -> 0 | F20: =N(C20)+N(D20)-N(E20) -> 0 | G20: =IF(B20="","",IF(F20<=0,"Clear",IF(N(E20)>0,"Partial","Due"))) | I20: 5 | J20: =IF(Students!G9="","",Students!G9) | K20: ='Jan 2027'!N20 -> 0 | L20: =IF(J20="",0,N(Students!I9)) -> 0 | N20: =N(K20)+N(L20)-N(M20) -> 0 | O20: =IF(J20="","",IF(N20<=0,"Clear",IF(N(M20)>0,"Partial","Due")))
A21: 6 | B21: =IF(Students!B10="","",Students!B10) | C21: ='Jan 2027'!F21 -> 0 | D21: =IF(B21="",0,N(Students!D10)) -> 0 | F21: =N(C21)+N(D21)-N(E21) -> 0 | G21: =IF(B21="","",IF(F21<=0,"Clear",IF(N(E21)>0,"Partial","Due"))) | I21: 6 | J21: =IF(Students!G10="","",Students!G10) | K21: ='Jan 2027'!N21 -> 0 | L21: =IF(J21="",0,N(Students!I10)) -> 0 | N21: =N(K21)+N(L21)-N(M21) -> 0 | O21: =IF(J21="","",IF(N21<=0,"Clear",IF(N(M21)>0,"Partial","Due")))
A22: 7 | B22: =IF(Students!B11="","",Students!B11) | C22: ='Jan 2027'!F22 -> 0 | D22: =IF(B22="",0,N(Students!D11)) -> 0 | F22: =N(C22)+N(D22)-N(E22) -> 0 | G22: =IF(B22="","",IF(F22<=0,"Clear",IF(N(E22)>0,"Partial","Due"))) | I22: 7 | J22: =IF(Students!G11="","",Students!G11) | K22: ='Jan 2027'!N22 -> 0 | L22: =IF(J22="",0,N(Students!I11)) -> 0 | N22: =N(K22)+N(L22)-N(M22) -> 0 | O22: =IF(J22="","",IF(N22<=0,"Clear",IF(N(M22)>0,"Partial","Due")))
A23: 8 | B23: =IF(Students!B12="","",Students!B12) | C23: ='Jan 2027'!F23 -> 0 | D23: =IF(B23="",0,N(Students!D12)) -> 0 | F23: =N(C23)+N(D23)-N(E23) -> 0 | G23: =IF(B23="","",IF(F23<=0,"Clear",IF(N(E23)>0,"Partial","Due"))) | I23: 8 | J23: =IF(Students!G12="","",Students!G12) | K23: ='Jan 2027'!N23 -> 0 | L23: =IF(J23="",0,N(Students!I12)) -> 0 | N23: =N(K23)+N(L23)-N(M23) -> 0 | O23: =IF(J23="","",IF(N23<=0,"Clear",IF(N(M23)>0,"Partial","Due")))
A24: 9 | B24: =IF(Students!B13="","",Students!B13) | C24: ='Jan 2027'!F24 -> 0 | D24: =IF(B24="",0,N(Students!D13)) -> 0 | F24: =N(C24)+N(D24)-N(E24) -> 0 | G24: =IF(B24="","",IF(F24<=0,"Clear",IF(N(E24)>0,"Partial","Due"))) | I24: 9 | J24: =IF(Students!G13="","",Students!G13) | K24: ='Jan 2027'!N24 -> 0 | L24: =IF(J24="",0,N(Students!I13)) -> 0 | N24: =N(K24)+N(L24)-N(M24) -> 0 | O24: =IF(J24="","",IF(N24<=0,"Clear",IF(N(M24)>0,"Partial","Due")))
A25: 10 | B25: =IF(Students!B14="","",Students!B14) | C25: ='Jan 2027'!F25 -> 0 | D25: =IF(B25="",0,N(Students!D14)) -> 0 | F25: =N(C25)+N(D25)-N(E25) -> 0 | G25: =IF(B25="","",IF(F25<=0,"Clear",IF(N(E25)>0,"Partial","Due"))) | I25: 10 | J25: =IF(Students!G14="","",Students!G14) | K25: ='Jan 2027'!N25 -> 0 | L25: =IF(J25="",0,N(Students!I14)) -> 0 | N25: =N(K25)+N(L25)-N(M25) -> 0 | O25: =IF(J25="","",IF(N25<=0,"Clear",IF(N(M25)>0,"Partial","Due")))
A26: 11 | B26: =IF(Students!B15="","",Students!B15) | C26: ='Jan 2027'!F26 -> 0 | D26: =IF(B26="",0,N(Students!D15)) -> 0 | F26: =N(C26)+N(D26)-N(E26) -> 0 | G26: =IF(B26="","",IF(F26<=0,"Clear",IF(N(E26)>0,"Partial","Due"))) | I26: 11 | J26: =IF(Students!G15="","",Students!G15) | K26: ='Jan 2027'!N26 -> 0 | L26: =IF(J26="",0,N(Students!I15)) -> 0 | N26: =N(K26)+N(L26)-N(M26) -> 0 | O26: =IF(J26="","",IF(N26<=0,"Clear",IF(N(M26)>0,"Partial","Due")))
A27: 12 | B27: =IF(Students!B16="","",Students!B16) | C27: ='Jan 2027'!F27 -> 0 | D27: =IF(B27="",0,N(Students!D16)) -> 0 | F27: =N(C27)+N(D27)-N(E27) -> 0 | G27: =IF(B27="","",IF(F27<=0,"Clear",IF(N(E27)>0,"Partial","Due"))) | I27: 12 | J27: =IF(Students!G16="","",Students!G16) | K27: ='Jan 2027'!N27 -> 0 | L27: =IF(J27="",0,N(Students!I16)) -> 0 | N27: =N(K27)+N(L27)-N(M27) -> 0 | O27: =IF(J27="","",IF(N27<=0,"Clear",IF(N(M27)>0,"Partial","Due")))
... A65: 50 | B65: =IF(Students!B54="","",Students!B54) | C65: ='Jan 2027'!F65 -> 0 | D65: =IF(B65="",0,N(Students!D54)) -> 0 | F65: =N(C65)+N(D65)-N(E65) -> 0 | G65: =IF(B65="","",IF(F65<=0,"Clear",IF(N(E65)>0,"Partial","Due"))) | I65: 50 | J65: =IF(Students!G54="","",Students!G54) | K65: ='Jan 2027'!N65 -> 0 | L65: =IF(J65="",0,N(Students!I54)) -> 0 | N65: =N(K65)+N(L65)-N(M65) -> 0 | O65: =IF(J65="","",IF(N65<=0,"Clear",IF(N(M65)>0,"Partial","Due")))
A66: TOTAL | C66: =SUM(C16:C65) -> 3000 | D66: =SUM(D16:D65) -> 1000 | E66: =SUM(E16:E65) -> 0 | F66: =SUM(F16:F65) -> 4000 | G66: =(COUNTIF(G16:G65,"Due")+COUNTIF(G16:G65,"Partial"))&" with dues" -> 1 with dues | I66: TOTAL | K66: =SUM(K16:K65) -> 5500 | L66: =SUM(L16:L65) -> 1500 | M66: =SUM(M16:M65) -> 0 | N66: =SUM(N16:N65) -> 7000 | O66: =(COUNTIF(O16:O65,"Due")+COUNTIF(O16:O65,"Partial"))&" with dues" -> 1 with dues

Sheet Mar 2027
A1: Future Talent Academy Jamshoro — Kids Coaching Fees: March 2027
A2: Yellow cells: type the amount each child paid. Previous dues come from last month automatically.
A4: =UPPER(Setup!B6) -> KIDS CLASS 1 | I4: =UPPER(Setup!B9) -> KIDS CLASS 2
A5: TEACHER SECTION | I5: TEACHER SECTION
A6: Teacher Name | D6: =Setup!B7 -> Miss Farzana | I6: Teacher Name | L6: =Setup!B10 -> Miss Fozia
A7: Fee Collected | D7: =E66 -> 0 | I7: Fee Collected | L7: =M66 -> 0
A8: Teacher Share | D8: =E66*Setup!$B$12 -> 0 | I8: Teacher Share | L8: =M66*Setup!$B$12 -> 0
A9: Academy Share | D9: =E66*Setup!$B$13 -> 0 | I9: Academy Share | L9: =M66*Setup!$B$13 -> 0
A10: Pending Fees | D10: =F66 -> 5000 | I10: Pending Fees | L10: =N66 -> 8500
A12: ACADEMY SECTION (both classes)
A13: Total Collected | C13: =E66+M66 -> 0 | E13: Teachers' Share | G13: =D8+L8 -> 0 | I13: Academy Share | K13: =D9+L9 -> 0 | M13: Pending (both) | O13: =F66+N66 -> 13500
A15: Serial No | B15: Student Name | C15: Previous Due | D15: Monthly Fee | E15: Paid | F15: Balance | G15: Status | I15: Serial No | J15: Student Name | K15: Previous Due | L15: Monthly Fee | M15: Paid | N15: Balance | O15: Status
A16: 1 | B16: =IF(Students!B5="","",Students!B5) -> Sara (example) | C16: ='Feb 2027'!F16 -> 4000 | D16: =IF(B16="",0,N(Students!D5)) -> 1000 | F16: =N(C16)+N(D16)-N(E16) -> 5000 | G16: =IF(B16="","",IF(F16<=0,"Clear",IF(N(E16)>0,"Partial","Due"))) -> Due | I16: 1 | J16: =IF(Students!G5="","",Students!G5) -> Hamza (example) | K16: ='Feb 2027'!N16 -> 7000 | L16: =IF(J16="",0,N(Students!I5)) -> 1500 | N16: =N(K16)+N(L16)-N(M16) -> 8500 | O16: =IF(J16="","",IF(N16<=0,"Clear",IF(N(M16)>0,"Partial","Due"))) -> Due
A17: 2 | B17: =IF(Students!B6="","",Students!B6) | C17: ='Feb 2027'!F17 -> 0 | D17: =IF(B17="",0,N(Students!D6)) -> 0 | F17: =N(C17)+N(D17)-N(E17) -> 0 | G17: =IF(B17="","",IF(F17<=0,"Clear",IF(N(E17)>0,"Partial","Due"))) | I17: 2 | J17: =IF(Students!G6="","",Students!G6) | K17: ='Feb 2027'!N17 -> 0 | L17: =IF(J17="",0,N(Students!I6)) -> 0 | N17: =N(K17)+N(L17)-N(M17) -> 0 | O17: =IF(J17="","",IF(N17<=0,"Clear",IF(N(M17)>0,"Partial","Due")))
A18: 3 | B18: =IF(Students!B7="","",Students!B7) | C18: ='Feb 2027'!F18 -> 0 | D18: =IF(B18="",0,N(Students!D7)) -> 0 | F18: =N(C18)+N(D18)-N(E18) -> 0 | G18: =IF(B18="","",IF(F18<=0,"Clear",IF(N(E18)>0,"Partial","Due"))) | I18: 3 | J18: =IF(Students!G7="","",Students!G7) | K18: ='Feb 2027'!N18 -> 0 | L18: =IF(J18="",0,N(Students!I7)) -> 0 | N18: =N(K18)+N(L18)-N(M18) -> 0 | O18: =IF(J18="","",IF(N18<=0,"Clear",IF(N(M18)>0,"Partial","Due")))
A19: 4 | B19: =IF(Students!B8="","",Students!B8) | C19: ='Feb 2027'!F19 -> 0 | D19: =IF(B19="",0,N(Students!D8)) -> 0 | F19: =N(C19)+N(D19)-N(E19) -> 0 | G19: =IF(B19="","",IF(F19<=0,"Clear",IF(N(E19)>0,"Partial","Due"))) | I19: 4 | J19: =IF(Students!G8="","",Students!G8) | K19: ='Feb 2027'!N19 -> 0 | L19: =IF(J19="",0,N(Students!I8)) -> 0 | N19: =N(K19)+N(L19)-N(M19) -> 0 | O19: =IF(J19="","",IF(N19<=0,"Clear",IF(N(M19)>0,"Partial","Due")))
A20: 5 | B20: =IF(Students!B9="","",Students!B9) | C20: ='Feb 2027'!F20 -> 0 | D20: =IF(B20="",0,N(Students!D9)) -> 0 | F20: =N(C20)+N(D20)-N(E20) -> 0 | G20: =IF(B20="","",IF(F20<=0,"Clear",IF(N(E20)>0,"Partial","Due"))) | I20: 5 | J20: =IF(Students!G9="","",Students!G9) | K20: ='Feb 2027'!N20 -> 0 | L20: =IF(J20="",0,N(Students!I9)) -> 0 | N20: =N(K20)+N(L20)-N(M20) -> 0 | O20: =IF(J20="","",IF(N20<=0,"Clear",IF(N(M20)>0,"Partial","Due")))
A21: 6 | B21: =IF(Students!B10="","",Students!B10) | C21: ='Feb 2027'!F21 -> 0 | D21: =IF(B21="",0,N(Students!D10)) -> 0 | F21: =N(C21)+N(D21)-N(E21) -> 0 | G21: =IF(B21="","",IF(F21<=0,"Clear",IF(N(E21)>0,"Partial","Due"))) | I21: 6 | J21: =IF(Students!G10="","",Students!G10) | K21: ='Feb 2027'!N21 -> 0 | L21: =IF(J21="",0,N(Students!I10)) -> 0 | N21: =N(K21)+N(L21)-N(M21) -> 0 | O21: =IF(J21="","",IF(N21<=0,"Clear",IF(N(M21)>0,"Partial","Due")))
A22: 7 | B22: =IF(Students!B11="","",Students!B11) | C22: ='Feb 2027'!F22 -> 0 | D22: =IF(B22="",0,N(Students!D11)) -> 0 | F22: =N(C22)+N(D22)-N(E22) -> 0 | G22: =IF(B22="","",IF(F22<=0,"Clear",IF(N(E22)>0,"Partial","Due"))) | I22: 7 | J22: =IF(Students!G11="","",Students!G11) | K22: ='Feb 2027'!N22 -> 0 | L22: =IF(J22="",0,N(Students!I11)) -> 0 | N22: =N(K22)+N(L22)-N(M22) -> 0 | O22: =IF(J22="","",IF(N22<=0,"Clear",IF(N(M22)>0,"Partial","Due")))
A23: 8 | B23: =IF(Students!B12="","",Students!B12) | C23: ='Feb 2027'!F23 -> 0 | D23: =IF(B23="",0,N(Students!D12)) -> 0 | F23: =N(C23)+N(D23)-N(E23) -> 0 | G23: =IF(B23="","",IF(F23<=0,"Clear",IF(N(E23)>0,"Partial","Due"))) | I23: 8 | J23: =IF(Students!G12="","",Students!G12) | K23: ='Feb 2027'!N23 -> 0 | L23: =IF(J23="",0,N(Students!I12)) -> 0 | N23: =N(K23)+N(L23)-N(M23) -> 0 | O23: =IF(J23="","",IF(N23<=0,"Clear",IF(N(M23)>0,"Partial","Due")))
A24: 9 | B24: =IF(Students!B13="","",Students!B13) | C24: ='Feb 2027'!F24 -> 0 | D24: =IF(B24="",0,N(Students!D13)) -> 0 | F24: =N(C24)+N(D24)-N(E24) -> 0 | G24: =IF(B24="","",IF(F24<=0,"Clear",IF(N(E24)>0,"Partial","Due"))) | I24: 9 | J24: =IF(Students!G13="","",Students!G13) | K24: ='Feb 2027'!N24 -> 0 | L24: =IF(J24="",0,N(Students!I13)) -> 0 | N24: =N(K24)+N(L24)-N(M24) -> 0 | O24: =IF(J24="","",IF(N24<=0,"Clear",IF(N(M24)>0,"Partial","Due")))
A25: 10 | B25: =IF(Students!B14="","",Students!B14) | C25: ='Feb 2027'!F25 -> 0 | D25: =IF(B25="",0,N(Students!D14)) -> 0 | F25: =N(C25)+N(D25)-N(E25) -> 0 | G25: =IF(B25="","",IF(F25<=0,"Clear",IF(N(E25)>0,"Partial","Due"))) | I25: 10 | J25: =IF(Students!G14="","",Students!G14) | K25: ='Feb 2027'!N25 -> 0 | L25: =IF(J25="",0,N(Students!I14)) -> 0 | N25: =N(K25)+N(L25)-N(M25) -> 0 | O25: =IF(J25="","",IF(N25<=0,"Clear",IF(N(M25)>0,"Partial","Due")))
A26: 11 | B26: =IF(Students!B15="","",Students!B15) | C26: ='Feb 2027'!F26 -> 0 | D26: =IF(B26="",0,N(Students!D15)) -> 0 | F26: =N(C26)+N(D26)-N(E26) -> 0 | G26: =IF(B26="","",IF(F26<=0,"Clear",IF(N(E26)>0,"Partial","Due"))) | I26: 11 | J26: =IF(Students!G15="","",Students!G15) | K26: ='Feb 2027'!N26 -> 0 | L26: =IF(J26="",0,N(Students!I15)) -> 0 | N26: =N(K26)+N(L26)-N(M26) -> 0 | O26: =IF(J26="","",IF(N26<=0,"Clear",IF(N(M26)>0,"Partial","Due")))
A27: 12 | B27: =IF(Students!B16="","",Students!B16) | C27: ='Feb 2027'!F27 -> 0 | D27: =IF(B27="",0,N(Students!D16)) -> 0 | F27: =N(C27)+N(D27)-N(E27) -> 0 | G27: =IF(B27="","",IF(F27<=0,"Clear",IF(N(E27)>0,"Partial","Due"))) | I27: 12 | J27: =IF(Students!G16="","",Students!G16) | K27: ='Feb 2027'!N27 -> 0 | L27: =IF(J27="",0,N(Students!I16)) -> 0 | N27: =N(K27)+N(L27)-N(M27) -> 0 | O27: =IF(J27="","",IF(N27<=0,"Clear",IF(N(M27)>0,"Partial","Due")))
... A65: 50 | B65: =IF(Students!B54="","",Students!B54) | C65: ='Feb 2027'!F65 -> 0 | D65: =IF(B65="",0,N(Students!D54)) -> 0 | F65: =N(C65)+N(D65)-N(E65) -> 0 | G65: =IF(B65="","",IF(F65<=0,"Clear",IF(N(E65)>0,"Partial","Due"))) | I65: 50 | J65: =IF(Students!G54="","",Students!G54) | K65: ='Feb 2027'!N65 -> 0 | L65: =IF(J65="",0,N(Students!I54)) -> 0 | N65: =N(K65)+N(L65)-N(M65) -> 0 | O65: =IF(J65="","",IF(N65<=0,"Clear",IF(N(M65)>0,"Partial","Due")))
A66: TOTAL | C66: =SUM(C16:C65) -> 4000 | D66: =SUM(D16:D65) -> 1000 | E66: =SUM(E16:E65) -> 0 | F66: =SUM(F16:F65) -> 5000 | G66: =(COUNTIF(G16:G65,"Due")+COUNTIF(G16:G65,"Partial"))&" with dues" -> 1 with dues | I66: TOTAL | K66: =SUM(K16:K65) -> 7000 | L66: =SUM(L16:L65) -> 1500 | M66: =SUM(M16:M65) -> 0 | N66: =SUM(N16:N65) -> 8500 | O66: =(COUNTIF(O16:O65,"Due")+COUNTIF(O16:O65,"Partial"))&" with dues" -> 1 with dues

Sheet Apr 2027
A1: Future Talent Academy Jamshoro — Kids Coaching Fees: April 2027
A2: Yellow cells: type the amount each child paid. Previous dues come from last month automatically.
A4: =UPPER(Setup!B6) -> KIDS CLASS 1 | I4: =UPPER(Setup!B9) -> KIDS CLASS 2
A5: TEACHER SECTION | I5: TEACHER SECTION
A6: Teacher Name | D6: =Setup!B7 -> Miss Farzana | I6: Teacher Name | L6: =Setup!B10 -> Miss Fozia
A7: Fee Collected | D7: =E66 -> 0 | I7: Fee Collected | L7: =M66 -> 0
A8: Teacher Share | D8: =E66*Setup!$B$12 -> 0 | I8: Teacher Share | L8: =M66*Setup!$B$12 -> 0
A9: Academy Share | D9: =E66*Setup!$B$13 -> 0 | I9: Academy Share | L9: =M66*Setup!$B$13 -> 0
A10: Pending Fees | D10: =F66 -> 6000 | I10: Pending Fees | L10: =N66 -> 10000
A12: ACADEMY SECTION (both classes)
A13: Total Collected | C13: =E66+M66 -> 0 | E13: Teachers' Share | G13: =D8+L8 -> 0 | I13: Academy Share | K13: =D9+L9 -> 0 | M13: Pending (both) | O13: =F66+N66 -> 16000
A15: Serial No | B15: Student Name | C15: Previous Due | D15: Monthly Fee | E15: Paid | F15: Balance | G15: Status | I15: Serial No | J15: Student Name | K15: Previous Due | L15: Monthly Fee | M15: Paid | N15: Balance | O15: Status
A16: 1 | B16: =IF(Students!B5="","",Students!B5) -> Sara (example) | C16: ='Mar 2027'!F16 -> 5000 | D16: =IF(B16="",0,N(Students!D5)) -> 1000 | F16: =N(C16)+N(D16)-N(E16) -> 6000 | G16: =IF(B16="","",IF(F16<=0,"Clear",IF(N(E16)>0,"Partial","Due"))) -> Due | I16: 1 | J16: =IF(Students!G5="","",Students!G5) -> Hamza (example) | K16: ='Mar 2027'!N16 -> 8500 | L16: =IF(J16="",0,N(Students!I5)) -> 1500 | N16: =N(K16)+N(L16)-N(M16) -> 10000 | O16: =IF(J16="","",IF(N16<=0,"Clear",IF(N(M16)>0,"Partial","Due"))) -> Due
A17: 2 | B17: =IF(Students!B6="","",Students!B6) | C17: ='Mar 2027'!F17 -> 0 | D17: =IF(B17="",0,N(Students!D6)) -> 0 | F17: =N(C17)+N(D17)-N(E17) -> 0 | G17: =IF(B17="","",IF(F17<=0,"Clear",IF(N(E17)>0,"Partial","Due"))) | I17: 2 | J17: =IF(Students!G6="","",Students!G6) | K17: ='Mar 2027'!N17 -> 0 | L17: =IF(J17="",0,N(Students!I6)) -> 0 | N17: =N(K17)+N(L17)-N(M17) -> 0 | O17: =IF(J17="","",IF(N17<=0,"Clear",IF(N(M17)>0,"Partial","Due")))
A18: 3 | B18: =IF(Students!B7="","",Students!B7) | C18: ='Mar 2027'!F18 -> 0 | D18: =IF(B18="",0,N(Students!D7)) -> 0 | F18: =N(C18)+N(D18)-N(E18) -> 0 | G18: =IF(B18="","",IF(F18<=0,"Clear",IF(N(E18)>0,"Partial","Due"))) | I18: 3 | J18: =IF(Students!G7="","",Students!G7) | K18: ='Mar 2027'!N18 -> 0 | L18: =IF(J18="",0,N(Students!I7)) -> 0 | N18: =N(K18)+N(L18)-N(M18) -> 0 | O18: =IF(J18="","",IF(N18<=0,"Clear",IF(N(M18)>0,"Partial","Due")))
A19: 4 | B19: =IF(Students!B8="","",Students!B8) | C19: ='Mar 2027'!F19 -> 0 | D19: =IF(B19="",0,N(Students!D8)) -> 0 | F19: =N(C19)+N(D19)-N(E19) -> 0 | G19: =IF(B19="","",IF(F19<=0,"Clear",IF(N(E19)>0,"Partial","Due"))) | I19: 4 | J19: =IF(Students!G8="","",Students!G8) | K19: ='Mar 2027'!N19 -> 0 | L19: =IF(J19="",0,N(Students!I8)) -> 0 | N19: =N(K19)+N(L19)-N(M19) -> 0 | O19: =IF(J19="","",IF(N19<=0,"Clear",IF(N(M19)>0,"Partial","Due")))
A20: 5 | B20: =IF(Students!B9="","",Students!B9) | C20: ='Mar 2027'!F20 -> 0 | D20: =IF(B20="",0,N(Students!D9)) -> 0 | F20: =N(C20)+N(D20)-N(E20) -> 0 | G20: =IF(B20="","",IF(F20<=0,"Clear",IF(N(E20)>0,"Partial","Due"))) | I20: 5 | J20: =IF(Students!G9="","",Students!G9) | K20: ='Mar 2027'!N20 -> 0 | L20: =IF(J20="",0,N(Students!I9)) -> 0 | N20: =N(K20)+N(L20)-N(M20) -> 0 | O20: =IF(J20="","",IF(N20<=0,"Clear",IF(N(M20)>0,"Partial","Due")))
A21: 6 | B21: =IF(Students!B10="","",Students!B10) | C21: ='Mar 2027'!F21 -> 0 | D21: =IF(B21="",0,N(Students!D10)) -> 0 | F21: =N(C21)+N(D21)-N(E21) -> 0 | G21: =IF(B21="","",IF(F21<=0,"Clear",IF(N(E21)>0,"Partial","Due"))) | I21: 6 | J21: =IF(Students!G10="","",Students!G10) | K21: ='Mar 2027'!N21 -> 0 | L21: =IF(J21="",0,N(Students!I10)) -> 0 | N21: =N(K21)+N(L21)-N(M21) -> 0 | O21: =IF(J21="","",IF(N21<=0,"Clear",IF(N(M21)>0,"Partial","Due")))
A22: 7 | B22: =IF(Students!B11="","",Students!B11) | C22: ='Mar 2027'!F22 -> 0 | D22: =IF(B22="",0,N(Students!D11)) -> 0 | F22: =N(C22)+N(D22)-N(E22) -> 0 | G22: =IF(B22="","",IF(F22<=0,"Clear",IF(N(E22)>0,"Partial","Due"))) | I22: 7 | J22: =IF(Students!G11="","",Students!G11) | K22: ='Mar 2027'!N22 -> 0 | L22: =IF(J22="",0,N(Students!I11)) -> 0 | N22: =N(K22)+N(L22)-N(M22) -> 0 | O22: =IF(J22="","",IF(N22<=0,"Clear",IF(N(M22)>0,"Partial","Due")))
A23: 8 | B23: =IF(Students!B12="","",Students!B12) | C23: ='Mar 2027'!F23 -> 0 | D23: =IF(B23="",0,N(Students!D12)) -> 0 | F23: =N(C23)+N(D23)-N(E23) -> 0 | G23: =IF(B23="","",IF(F23<=0,"Clear",IF(N(E23)>0,"Partial","Due"))) | I23: 8 | J23: =IF(Students!G12="","",Students!G12) | K23: ='Mar 2027'!N23 -> 0 | L23: =IF(J23="",0,N(Students!I12)) -> 0 | N23: =N(K23)+N(L23)-N(M23) -> 0 | O23: =IF(J23="","",IF(N23<=0,"Clear",IF(N(M23)>0,"Partial","Due")))
A24: 9 | B24: =IF(Students!B13="","",Students!B13) | C24: ='Mar 2027'!F24 -> 0 | D24: =IF(B24="",0,N(Students!D13)) -> 0 | F24: =N(C24)+N(D24)-N(E24) -> 0 | G24: =IF(B24="","",IF(F24<=0,"Clear",IF(N(E24)>0,"Partial","Due"))) | I24: 9 | J24: =IF(Students!G13="","",Students!G13) | K24: ='Mar 2027'!N24 -> 0 | L24: =IF(J24="",0,N(Students!I13)) -> 0 | N24: =N(K24)+N(L24)-N(M24) -> 0 | O24: =IF(J24="","",IF(N24<=0,"Clear",IF(N(M24)>0,"Partial","Due")))
A25: 10 | B25: =IF(Students!B14="","",Students!B14) | C25: ='Mar 2027'!F25 -> 0 | D25: =IF(B25="",0,N(Students!D14)) -> 0 | F25: =N(C25)+N(D25)-N(E25) -> 0 | G25: =IF(B25="","",IF(F25<=0,"Clear",IF(N(E25)>0,"Partial","Due"))) | I25: 10 | J25: =IF(Students!G14="","",Students!G14) | K25: ='Mar 2027'!N25 -> 0 | L25: =IF(J25="",0,N(Students!I14)) -> 0 | N25: =N(K25)+N(L25)-N(M25) -> 0 | O25: =IF(J25="","",IF(N25<=0,"Clear",IF(N(M25)>0,"Partial","Due")))
A26: 11 | B26: =IF(Students!B15="","",Students!B15) | C26: ='Mar 2027'!F26 -> 0 | D26: =IF(B26="",0,N(Students!D15)) -> 0 | F26: =N(C26)+N(D26)-N(E26) -> 0 | G26: =IF(B26="","",IF(F26<=0,"Clear",IF(N(E26)>0,"Partial","Due"))) | I26: 11 | J26: =IF(Students!G15="","",Students!G15) | K26: ='Mar 2027'!N26 -> 0 | L26: =IF(J26="",0,N(Students!I15)) -> 0 | N26: =N(K26)+N(L26)-N(M26) -> 0 | O26: =IF(J26="","",IF(N26<=0,"Clear",IF(N(M26)>0,"Partial","Due")))
A27: 12 | B27: =IF(Students!B16="","",Students!B16) | C27: ='Mar 2027'!F27 -> 0 | D27: =IF(B27="",0,N(Students!D16)) -> 0 | F27: =N(C27)+N(D27)-N(E27) -> 0 | G27: =IF(B27="","",IF(F27<=0,"Clear",IF(N(E27)>0,"Partial","Due"))) | I27: 12 | J27: =IF(Students!G16="","",Students!G16) | K27: ='Mar 2027'!N27 -> 0 | L27: =IF(J27="",0,N(Students!I16)) -> 0 | N27: =N(K27)+N(L27)-N(M27) -> 0 | O27: =IF(J27="","",IF(N27<=0,"Clear",IF(N(M27)>0,"Partial","Due")))
... A65: 50 | B65: =IF(Students!B54="","",Students!B54) | C65: ='Mar 2027'!F65 -> 0 | D65: =IF(B65="",0,N(Students!D54)) -> 0 | F65: =N(C65)+N(D65)-N(E65) -> 0 | G65: =IF(B65="","",IF(F65<=0,"Clear",IF(N(E65)>0,"Partial","Due"))) | I65: 50 | J65: =IF(Students!G54="","",Students!G54) | K65: ='Mar 2027'!N65 -> 0 | L65: =IF(J65="",0,N(Students!I54)) -> 0 | N65: =N(K65)+N(L65)-N(M65) -> 0 | O65: =IF(J65="","",IF(N65<=0,"Clear",IF(N(M65)>0,"Partial","Due")))
A66: TOTAL | C66: =SUM(C16:C65) -> 5000 | D66: =SUM(D16:D65) -> 1000 | E66: =SUM(E16:E65) -> 0 | F66: =SUM(F16:F65) -> 6000 | G66: =(COUNTIF(G16:G65,"Due")+COUNTIF(G16:G65,"Partial"))&" with dues" -> 1 with dues | I66: TOTAL | K66: =SUM(K16:K65) -> 8500 | L66: =SUM(L16:L65) -> 1500 | M66: =SUM(M16:M65) -> 0 | N66: =SUM(N16:N65) -> 10000 | O66: =(COUNTIF(O16:O65,"Due")+COUNTIF(O16:O65,"Partial"))&" with dues" -> 1 with dues

Sheet May 2027
A1: Future Talent Academy Jamshoro — Kids Coaching Fees: May 2027
A2: Yellow cells: type the amount each child paid. Previous dues come from last month automatically.
A4: =UPPER(Setup!B6) -> KIDS CLASS 1 | I4: =UPPER(Setup!B9) -> KIDS CLASS 2
A5: TEACHER SECTION | I5: TEACHER SECTION
A6: Teacher Name | D6: =Setup!B7 -> Miss Farzana | I6: Teacher Name | L6: =Setup!B10 -> Miss Fozia
A7: Fee Collected | D7: =E66 -> 0 | I7: Fee Collected | L7: =M66 -> 0
A8: Teacher Share | D8: =E66*Setup!$B$12 -> 0 | I8: Teacher Share | L8: =M66*Setup!$B$12 -> 0
A9: Academy Share | D9: =E66*Setup!$B$13 -> 0 | I9: Academy Share | L9: =M66*Setup!$B$13 -> 0
A10: Pending Fees | D10: =F66 -> 7000 | I10: Pending Fees | L10: =N66 -> 11500
A12: ACADEMY SECTION (both classes)
A13: Total Collected | C13: =E66+M66 -> 0 | E13: Teachers' Share | G13: =D8+L8 -> 0 | I13: Academy Share | K13: =D9+L9 -> 0 | M13: Pending (both) | O13: =F66+N66 -> 18500
A15: Serial No | B15: Student Name | C15: Previous Due | D15: Monthly Fee | E15: Paid | F15: Balance | G15: Status | I15: Serial No | J15: Student Name | K15: Previous Due | L15: Monthly Fee | M15: Paid | N15: Balance | O15: Status
A16: 1 | B16: =IF(Students!B5="","",Students!B5) -> Sara (example) | C16: ='Apr 2027'!F16 -> 6000 | D16: =IF(B16="",0,N(Students!D5)) -> 1000 | F16: =N(C16)+N(D16)-N(E16) -> 7000 | G16: =IF(B16="","",IF(F16<=0,"Clear",IF(N(E16)>0,"Partial","Due"))) -> Due | I16: 1 | J16: =IF(Students!G5="","",Students!G5) -> Hamza (example) | K16: ='Apr 2027'!N16 -> 10000 | L16: =IF(J16="",0,N(Students!I5)) -> 1500 | N16: =N(K16)+N(L16)-N(M16) -> 11500 | O16: =IF(J16="","",IF(N16<=0,"Clear",IF(N(M16)>0,"Partial","Due"))) -> Due
A17: 2 | B17: =IF(Students!B6="","",Students!B6) | C17: ='Apr 2027'!F17 -> 0 | D17: =IF(B17="",0,N(Students!D6)) -> 0 | F17: =N(C17)+N(D17)-N(E17) -> 0 | G17: =IF(B17="","",IF(F17<=0,"Clear",IF(N(E17)>0,"Partial","Due"))) | I17: 2 | J17: =IF(Students!G6="","",Students!G6) | K17: ='Apr 2027'!N17 -> 0 | L17: =IF(J17="",0,N(Students!I6)) -> 0 | N17: =N(K17)+N(L17)-N(M17) -> 0 | O17: =IF(J17="","",IF(N17<=0,"Clear",IF(N(M17)>0,"Partial","Due")))
A18: 3 | B18: =IF(Students!B7="","",Students!B7) | C18: ='Apr 2027'!F18 -> 0 | D18: =IF(B18="",0,N(Students!D7)) -> 0 | F18: =N(C18)+N(D18)-N(E18) -> 0 | G18: =IF(B18="","",IF(F18<=0,"Clear",IF(N(E18)>0,"Partial","Due"))) | I18: 3 | J18: =IF(Students!G7="","",Students!G7) | K18: ='Apr 2027'!N18 -> 0 | L18: =IF(J18="",0,N(Students!I7)) -> 0 | N18: =N(K18)+N(L18)-N(M18) -> 0 | O18: =IF(J18="","",IF(N18<=0,"Clear",IF(N(M18)>0,"Partial","Due")))
A19: 4 | B19: =IF(Students!B8="","",Students!B8) | C19: ='Apr 2027'!F19 -> 0 | D19: =IF(B19="",0,N(Students!D8)) -> 0 | F19: =N(C19)+N(D19)-N(E19) -> 0 | G19: =IF(B19="","",IF(F19<=0,"Clear",IF(N(E19)>0,"Partial","Due"))) | I19: 4 | J19: =IF(Students!G8="","",Students!G8) | K19: ='Apr 2027'!N19 -> 0 | L19: =IF(J19="",0,N(Students!I8)) -> 0 | N19: =N(K19)+N(L19)-N(M19) -> 0 | O19: =IF(J19="","",IF(N19<=0,"Clear",IF(N(M19)>0,"Partial","Due")))
A20: 5 | B20: =IF(Students!B9="","",Students!B9) | C20: ='Apr 2027'!F20 -> 0 | D20: =IF(B20="",0,N(Students!D9)) -> 0 | F20: =N(C20)+N(D20)-N(E20) -> 0 | G20: =IF(B20="","",IF(F20<=0,"Clear",IF(N(E20)>0,"Partial","Due"))) | I20: 5 | J20: =IF(Students!G9="","",Students!G9) | K20: ='Apr 2027'!N20 -> 0 | L20: =IF(J20="",0,N(Students!I9)) -> 0 | N20: =N(K20)+N(L20)-N(M20) -> 0 | O20: =IF(J20="","",IF(N20<=0,"Clear",IF(N(M20)>0,"Partial","Due")))
A21: 6 | B21: =IF(Students!B10="","",Students!B10) | C21: ='Apr 2027'!F21 -> 0 | D21: =IF(B21="",0,N(Students!D10)) -> 0 | F21: =N(C21)+N(D21)-N(E21) -> 0 | G21: =IF(B21="","",IF(F21<=0,"Clear",IF(N(E21)>0,"Partial","Due"))) | I21: 6 | J21: =IF(Students!G10="","",Students!G10) | K21: ='Apr 2027'!N21 -> 0 | L21: =IF(J21="",0,N(Students!I10)) -> 0 | N21: =N(K21)+N(L21)-N(M21) -> 0 | O21: =IF(J21="","",IF(N21<=0,"Clear",IF(N(M21)>0,"Partial","Due")))
A22: 7 | B22: =IF(Students!B11="","",Students!B11) | C22: ='Apr 2027'!F22 -> 0 | D22: =IF(B22="",0,N(Students!D11)) -> 0 | F22: =N(C22)+N(D22)-N(E22) -> 0 | G22: =IF(B22="","",IF(F22<=0,"Clear",IF(N(E22)>0,"Partial","Due"))) | I22: 7 | J22: =IF(Students!G11="","",Students!G11) | K22: ='Apr 2027'!N22 -> 0 | L22: =IF(J22="",0,N(Students!I11)) -> 0 | N22: =N(K22)+N(L22)-N(M22) -> 0 | O22: =IF(J22="","",IF(N22<=0,"Clear",IF(N(M22)>0,"Partial","Due")))
A23: 8 | B23: =IF(Students!B12="","",Students!B12) | C23: ='Apr 2027'!F23 -> 0 | D23: =IF(B23="",0,N(Students!D12)) -> 0 | F23: =N(C23)+N(D23)-N(E23) -> 0 | G23: =IF(B23="","",IF(F23<=0,"Clear",IF(N(E23)>0,"Partial","Due"))) | I23: 8 | J23: =IF(Students!G12="","",Students!G12) | K23: ='Apr 2027'!N23 -> 0 | L23: =IF(J23="",0,N(Students!I12)) -> 0 | N23: =N(K23)+N(L23)-N(M23) -> 0 | O23: =IF(J23="","",IF(N23<=0,"Clear",IF(N(M23)>0,"Partial","Due")))
A24: 9 | B24: =IF(Students!B13="","",Students!B13) | C24: ='Apr 2027'!F24 -> 0 | D24: =IF(B24="",0,N(Students!D13)) -> 0 | F24: =N(C24)+N(D24)-N(E24) -> 0 | G24: =IF(B24="","",IF(F24<=0,"Clear",IF(N(E24)>0,"Partial","Due"))) | I24: 9 | J24: =IF(Students!G13="","",Students!G13) | K24: ='Apr 2027'!N24 -> 0 | L24: =IF(J24="",0,N(Students!I13)) -> 0 | N24: =N(K24)+N(L24)-N(M24) -> 0 | O24: =IF(J24="","",IF(N24<=0,"Clear",IF(N(M24)>0,"Partial","Due")))
A25: 10 | B25: =IF(Students!B14="","",Students!B14) | C25: ='Apr 2027'!F25 -> 0 | D25: =IF(B25="",0,N(Students!D14)) -> 0 | F25: =N(C25)+N(D25)-N(E25) -> 0 | G25: =IF(B25="","",IF(F25<=0,"Clear",IF(N(E25)>0,"Partial","Due"))) | I25: 10 | J25: =IF(Students!G14="","",Students!G14) | K25: ='Apr 2027'!N25 -> 0 | L25: =IF(J25="",0,N(Students!I14)) -> 0 | N25: =N(K25)+N(L25)-N(M25) -> 0 | O25: =IF(J25="","",IF(N25<=0,"Clear",IF(N(M25)>0,"Partial","Due")))
